Workbook

Sheet LUC-2013-01-08-Run1
B1: 1961 | C1: 1962 | D1: 1963 | E1: 1964 | F1: 1965 | G1: 1966 | H1: 1967 | I1: 1968 | J1: 1969 | K1: 1970 | L1: 1971 | M1: 1972 | N1: 1973 | O1: 1974 | P1: 1975 | Q1: 1976 | R1: 1977 | S1: 1978 | T1: 1979 | U1: 1980 | V1: 1981 | W1: 1982 | X1: 1983 | Y1: 1984 | Z1: 1985 | AA1: 1986 | AB1: 1987 | AC1: 1988 | AD1: 1989 | AE1: 1990 | AF1: 1991 | AG1: 1992 | AH1: 1993 | AI1: 1994 | AJ1: 1995 | AK1: 1996 | AL1: 1997 | AM1: 1998 | AN1: 1999 | AO1: 2000 | AP1: 2001 | AQ1: 2002 | AR1: 2003 | AS1: 2004 | AT1: 2005 | AU1: 2006 | AV1: 2007 | AW1: 2008 | AX1: 2009 | AY1: 2010 | AZ1: 2011 | BA1: 2012 | BB1: 2013 | BC1: 2014 | BD1: 2015 | BE1: 2016 | BF1: 2017 | BG1: 2018 | BH1: 2019 | BI1: 2020 | BJ1: 2021 | BK1: 2022 | BL1: 2023 | BM1: 2024 | BN1: 2025 | BO1: 2026 | BP1: 2027 | BQ1: 2028 | BR1: 2029 | BS1: 2030 | BT1: 2031 | BU1: 2032 | BV1: 2033 | BW1: 2034 | BX1: 2035 | BY1: 2036 | BZ1: 2037 | CA1: 2038 | CB1: 2039 | CC1: 2040 | CD1: 2041 | CE1: 2042 | CF1: 2043 | CG1: 2044 | CH1: 2045 | CI1: 2046 | CJ1: 2047 | CK1: 2048 | CL1: 2049 | CM1: 2050
A2: USA.per_capita_animal_product_demand_scenario | B2: 0 | C2: 0 | D2: 0 | E2: 0 | F2: 0 | G2: 0 | H2: 0 | I2: 0 | J2: 0 | K2: 0 | L2: 0 | M2: 0 | N2: 0 | O2: 0 | P2: 0 | Q2: 0 | R2: 0 | S2: 0 | T2: 0 | U2: 0 | V2: 0 | W2: 0 | X2: 0 | Y2: 0 | Z2: 0 | AA2: 0 | AB2: 0 | AC2: 0 | AD2: 0 | AE2: 0 | AF2: 2.6047124e-05 | AG2: 2.5931821e-05 | AH2: 2.5817027e-05 | AI2: 2.5702742e-05 | AJ2: 2.5588963e-05 | AK2: 2.5475688e-05 | AL2: 2.5362914e-05 | AM2: 2.5250639e-05 | AN2: 2.5138861e-05 | AO2: 2.5027578e-05 | AP2: 2.4916788e-05 | AQ2: 2.4806488e-05 | AR2: 2.4696676e-05 | AS2: 2.458735e-05 | AT2: 2.4478509e-05 | AU2: 2.4370149e-05 | AV2: 2.4378852e-05 | AW2: 2.4387559e-05 | AX2: 2.4396268e-05 | AY2: 2.4404981e-05 | AZ2: 2.4413697e-05 | BA2: 2.4422416e-05 | BB2: 2.4431138e-05 | BC2: 2.4439863e-05 | BD2: 2.4448591e-05 | BE2: 2.4457323e-05 | BF2: 2.4466057e-05 | BG2: 2.4474795e-05 | BH2: 2.4483535e-05 | BI2: 2.4492279e-05 | BJ2: 2.4501026e-05 | BK2: 2.4509776e-05 | BL2: 2.451853e-05 | BM2: 2.4527286e-05 | BN2: 2.4536045e-05 | BO2: 2.4544808e-05 | BP2: 2.4553574e-05 | BQ2: 2.4562343e-05 | BR2: 2.4571115e-05 | BS2: 2.457989e-05 | BT2: 2.4588668e-05 | BU2: 2.4597449e-05 | BV2: 2.4606234e-05 | BW2: 2.4615022e-05 | BX2: 2.4623812e-05 | BY2: 2.4632606e-05 | BZ2: 2.4641404e-05 | CA2: 2.4650204e-05 | CB2: 2.4659007e-05 | CC2: 2.4667814e-05 | CD2: 2.4676623e-05 | CE2: 2.4685436e-05 | CF2: 2.4694252e-05 | CG2: 2.4703071e-05 | CH2: 2.4711893e-05 | CI2: 2.4720719e-05 | CJ2: 2.4729547e-05 | CK2: 2.4738379e-05 | CL2: 2.4747214e-05 | CM2: 2.4756052e-05
A3: … | B3: 0 | C3: 0 | D3: 0 | E3: 0 | F3: 0 | G3: 0 | H3: 0 | I3: 0 | J3: 0 | K3: 0 | L3: 0 | M3: 0 | N3: 0 | O3: 0 | P3: 0 | Q3: 0 | R3: 0 | S3: 0 | T3: 0 | U3: 0 | V3: 0 | W3: 0 | X3: 0 | Y3: 0 | Z3: 0 | AA3: 0 | AB3: 0 | AC3: 0 | AD3: 0 | AE3: 0 | AF3: 0.000201 | AG3: 0.00020106667 | AH3: 0.00020113333 | AI3: 0.0002012 | AJ3: 0.00020126667 | AK3: 0.00020133333 | AL3: 0.0002014 | AM3: 0.00020146667 | AN3: 0.00020153333 | AO3: 0.0002016 | AP3: 0.00020166667 | AQ3: 0.00020173333 | AR3: 0.0002018 | AS3: 0.00020186667 | AT3: 0.00020193333 | AU3: 0.000202 | AV3: 0.00020254167 | AW3: 0.00020308333 | AX3: 0.000203625 | AY3: 0.00020416667 | AZ3: 0.00020470833 | BA3: 0.00020525 | BB3: 0.00020579167 | BC3: 0.00020633333 | BD3: 0.000206875 | BE3: 0.00020741667 | BF3: 0.00020795833 | BG3: 0.0002085 | BH3: 0.00020904167 | BI3: 0.00020958333 | BJ3: 0.000210125 | BK3: 0.00021066667 | BL3: 0.00021120833 | BM3: 0.00021175 | BN3: 0.00021229167 | BO3: 0.00021283333 | BP3: 0.000213375 | BQ3: 0.00021391667 | BR3: 0.00021445833 | BS3: 0.000215 | BT3: 0.00021535 | BU3: 0.0002157 | BV3: 0.00021605 | BW3: 0.0002164 | BX3: 0.00021675 | BY3: 0.0002171 | BZ3: 0.00021745 | CA3: 0.0002178 | CB3: 0.00021815 | CC3: 0.0002185 | CD3: 0.00021885 | CE3: 0.0002192 | CF3: 0.00021955 | CG3: 0.0002199 | CH3: 0.00022025 | CI3: 0.0002206 | CJ3: 0.00022095 | CK3: 0.0002213 | CL3: 0.00022165 | CM3: 0.000222
A4: ... | B4: 0 | C4: 0 | D4: 0 | E4: 0 | F4: 0 | G4: 0 | H4: 0 | I4: 0 | J4: 0 | K4: 0 | L4: 0 | M4: 0 | N4: 0 | O4: 0 | P4: 0 | Q4: 0 | R4: 0 | S4: 0 | T4: 0 | U4: 0 | V4: 0 | W4: 0 | X4: 0 | Y4: 0 | Z4: 0 | AA4: 0 | AB4: 0 | AC4: 0 | AD4: 0 | AE4: 0 | AF4: 3.1090008e-05 | AG4: 3.1214867e-05 | AH4: 3.1340228e-05 | AI4: 3.1466092e-05 | AJ4: 3.1592462e-05 | AK4: 3.1719339e-05 | AL4: 3.1846726e-05 | AM4: 3.1974625e-05 | AN4: 3.2103037e-05 | AO4: 3.2231965e-05 | AP4: 3.2361411e-05 | AQ4: 3.2491376e-05 | AR4: 3.2621863e-05 | AS4: 3.2752875e-05 | AT4: 3.2884413e-05 | AU4: 3.3016479e-05 | AV4: 3.3049495e-05 | AW4: 3.3082545e-05 | AX4: 3.3115627e-05 | AY4: 3.3148743e-05 | AZ4: 3.3181891e-05 | BA4: 3.3215073e-05 | BB4: 3.3248288e-05 | BC4: 3.3281537e-05 | BD4: 3.3314818e-05 | BE4: 3.3348133e-05 | BF4: 3.3381481e-05 | BG4: 3.3414863e-05 | BH4: 3.3448278e-05 | BI4: 3.3481726e-05 | BJ4: 3.3515208e-05 | BK4: 3.3548723e-05 | BL4: 3.3582271e-05 | BM4: 3.3615854e-05 | BN4: 3.364947e-05 | BO4: 3.3683119e-05 | BP4: 3.3716802e-05 | BQ4: 3.3750519e-05 | BR4: 3.3784269e-05 | BS4: 3.3818054e-05 | BT4: 3.3851872e-05 | BU4: 3.3885724e-05 | BV4: 3.3919609e-05 | BW4: 3.3953529e-05 | BX4: 3.3987483e-05 | BY4: 3.402147e-05 | BZ4: 3.4055491e-05 | CA4: 3.4089547e-05 | CB4: 3.4123637e-05 | CC4: 3.415776e-05 | CD4: 3.4191918e-05 | CE4: 3.422611e-05 | CF4: 3.4260336e-05 | CG4: 3.4294596e-05 | CH4: 3.4328891e-05 | CI4: 3.436322e-05 | CJ4: 3.4397583e-05 | CK4: 3.4431981e-05 | CL4: 3.4466413e-05 | CM4: 3.4500879e-05
A5: ... | B5: 0 | C5: 0 | D5: 0 | E5: 0 | F5: 0 | G5: 0 | H5: 0 | I5: 0 | J5: 0 | K5: 0 | L5: 0 | M5: 0 | N5: 0 | O5: 0 | P5: 0 | Q5: 0 | R5: 0 | S5: 0 | T5: 0 | U5: 0 | V5: 0 | W5: 0 | X5: 0 | Y5: 0 | Z5: 0 | AA5: 0 | AB5: 0 | AC5: 0 | AD5: 0 | AE5: 0 | AF5: 1.9058063e-05 | AG5: 1.936795e-05 | AH5: 1.9682876e-05 | AI5: 2.0002922e-05 | AJ5: 2.0328173e-05 | AK5: 2.0658713e-05 | AL5: 2.0994627e-05 | AM5: 2.1336003e-05 | AN5: 2.168293e-05 | AO5: 2.2035498e-05 | AP5: 2.2393798e-05 | AQ5: 2.2757925e-05 | AR5: 2.3127973e-05 | AS5: 2.3504037e-05 | AT5: 2.3886217e-05 | AU5: 2.4274611e-05 | AV5: 2.4444533e-05 | AW5: 2.4615645e-05 | AX5: 2.4787954e-05 | AY5: 2.496147e-05 | AZ5: 2.51362e-05 | BA5: 2.5312153e-05 | BB5: 2.5489338e-05 | BC5: 2.5667764e-05 | BD5: 2.5847438e-05 | BE5: 2.602837e-05 | BF5: 2.6210569e-05 | BG5: 2.6394043e-05 | BH5: 2.6578801e-05 | BI5: 2.6764853e-05 | BJ5: 2.6952207e-05 | BK5: 2.7140872e-05 | BL5: 2.7330858e-05 | BM5: 2.7522174e-05 | BN5: 2.7714829e-05 | BO5: 2.7908833e-05 | BP5: 2.8104195e-05 | BQ5: 2.8300924e-05 | BR5: 2.8499031e-05 | BS5: 2.8698524e-05 | BT5: 2.8899414e-05 | BU5: 2.910171e-05 | BV5: 2.9305422e-05 | BW5: 2.951056e-05 | BX5: 2.9717134e-05 | BY5: 2.9925154e-05 | BZ5: 3.013463e-05 | CA5: 3.0345572e-05 | CB5: 3.0557991e-05 | CC5: 3.0771897e-05 | CD5: 3.09873e-05 | CE5: 3.1204211e-05 | CF5: 3.1422641e-05 | CG5: 3.1642599e-05 | CH5: 3.1864097e-05 | CI5: 3.2087146e-05 | CJ5: 3.2311756e-05 | CK5: 3.2537938e-05 | CL5: 3.2765704e-05 | CM5: 3.2995064e-05
A7: USA.per_capita_commodity_crop_demand_scenario | B7: 0 | C7: 0 | D7: 0 | E7: 0 | F7: 0 | G7: 0 | H7: 0 | I7: 0 | J7: 0 | K7: 0 | L7: 0 | M7: 0 | N7: 0 | O7: 0 | P7: 0 | Q7: 0 | R7: 0 | S7: 0 | T7: 0 | U7: 0 | V7: 0 | W7: 0 | X7: 0 | Y7: 0 | Z7: 0 | AA7: 0 | AB7: 0 | AC7: 0 | AD7: 0 | AE7: 0 | AF7: 3.731055e-05 | AG7: 3.738732e-05 | AH7: 3.7464091e-05 | AI7: 3.7540862e-05 | AJ7: 3.7617632e-05 | AK7: 3.7694403e-05 | AL7: 3.7771174e-05 | AM7: 3.7847945e-05 | AN7: 3.7924715e-05 | AO7: 3.8001486e-05 | AP7: 3.8078257e-05 | AQ7: 3.8155027e-05 | AR7: 3.8231798e-05 | AS7: 3.8308569e-05 | AT7: 3.8385339e-05 | AU7: 3.846211e-05 | AV7: 3.8690127e-05 | AW7: 3.8918144e-05 | AX7: 3.9146161e-05 | AY7: 3.9374178e-05 | AZ7: 3.9602194e-05 | BA7: 3.9830211e-05 | BB7: 4.0058228e-05 | BC7: 4.0286245e-05 | BD7: 4.0514262e-05 | BE7: 4.0742279e-05 | BF7: 4.0970296e-05 | BG7: 4.1198313e-05 | BH7: 4.142633e-05 | BI7: 4.1654347e-05 | BJ7: 4.1882364e-05 | BK7: 4.211038e-05 | BL7: 4.2338397e-05 | BM7: 4.2566414e-05 | BN7: 4.2794431e-05 | BO7: 4.3022448e-05 | BP7: 4.3250465e-05 | BQ7: 4.3478482e-05 | BR7: 4.3706499e-05 | BS7: 4.3934516e-05 | BT7: 4.3934516e-05 | BU7: 4.3934516e-05 | BV7: 4.3934516e-05 | BW7: 4.3934516e-05 | BX7: 4.3934516e-05 | BY7: 4.3934516e-05 | BZ7: 4.3934516e-05 | CA7: 4.3934516e-05 | CB7: 4.3934516e-05 | CC7: 4.3934516e-05 | CD7: 4.3934516e-05 | CE7: 4.3934516e-05 | CF7: 4.3934516e-05 | CG7: 4.3934516e-05 | CH7: 4.3934516e-05 | CI7: 4.3934516e-05 | CJ7: 4.3934516e-05 | CK7: 4.3934516e-05 | CL7: 4.3934516e-05 | CM7: 4.3934516e-05
A8: … | B8: 0 | C8: 0 | D8: 0 | E8: 0 | F8: 0 | G8: 0 | H8: 0 | I8: 0 | J8: 0 | K8: 0 | L8: 0 | M8: 0 | N8: 0 | O8: 0 | P8: 0 | Q8: 0 | R8: 0 | S8: 0 | T8: 0 | U8: 0 | V8: 0 | W8: 0 | X8: 0 | Y8: 0 | Z8: 0 | AA8: 0 | AB8: 0 | AC8: 0 | AD8: 0 | AE8: 0 | AF8: 5.3438336e-05 | AG8: 5.3548291e-05 | AH8: 5.3658247e-05 | AI8: 5.3768202e-05 | AJ8: 5.3878158e-05 | AK8: 5.3988113e-05 | AL8: 5.4098068e-05 | AM8: 5.4208024e-05 | AN8: 5.4317979e-05 | AO8: 5.4427935e-05 | AP8: 5.453789e-05 | AQ8: 5.4647845e-05 | AR8: 5.4757801e-05 | AS8: 5.4867756e-05 | AT8: 5.4977712e-05 | AU8: 5.5087667e-05 | AV8: 5.4915472e-05 | AW8: 5.4743277e-05 | AX8: 5.4571081e-05 | AY8: 5.4398886e-05 | AZ8: 5.4226691e-05 | BA8: 5.4054495e-05 | BB8: 5.38823e-05 | BC8: 5.3710105e-05 | BD8: 5.3537909e-05 | BE8: 5.3365714e-05 | BF8: 5.3193519e-05 | BG8: 5.3021323e-05 | BH8: 5.2849128e-05 | BI8: 5.2676933e-05 | BJ8: 5.2504737e-05 | BK8: 5.2332542e-05 | BL8: 5.2160347e-05 | BM8: 5.1988151e-05 | BN8: 5.1815956e-05 | BO8: 5.1643761e-05 | BP8: 5.1471565e-05 | BQ8: 5.129937e-05 | BR8: 5.1127175e-05 | BS8: 5.095498e-05 | BT8: 5.095498e-05 | BU8: 5.095498e-05 | BV8: 5.095498e-05 | BW8: 5.095498e-05 | BX8: 5.095498e-05 | BY8: 5.095498e-05 | BZ8: 5.095498e-05 | CA8: 5.095498e-05 | CB8: 5.095498e-05 | CC8: 5.095498e-05 | CD8: 5.095498e-05 | CE8: 5.095498e-05 | CF8: 5.095498e-05 | CG8: 5.095498e-05 | CH8: 5.095498e-05 | CI8: 5.095498e-05 | CJ8: 5.095498e-05 | CK8: 5.095498e-05 | CL8: 5.095498e-05 | CM8: 5.095498e-05
A9: … | B9: 0 | C9: 0 | D9: 0 | E9: 0 | F9: 0 | G9: 0 | H9: 0 | I9: 0 | J9: 0 | K9: 0 | L9: 0 | M9: 0 | N9: 0 | O9: 0 | P9: 0 | Q9: 0 | R9: 0 | S9: 0 | T9: 0 | U9: 0 | V9: 0 | W9: 0 | X9: 0 | Y9: 0 | Z9: 0 | AA9: 0 | AB9: 0 | AC9: 0 | AD9: 0 | AE9: 0 | AF9: 3.8032689e-05 | AG9: 3.8110946e-05 | AH9: 3.8189203e-05 | AI9: 3.8267459e-05 | AJ9: 3.8345716e-05 | AK9: 3.8423972e-05 | AL9: 3.8502229e-05 | AM9: 3.8580485e-05 | AN9: 3.8658742e-05 | AO9: 3.8736999e-05 | AP9: 3.8815255e-05 | AQ9: 3.8893512e-05 | AR9: 3.8971768e-05 | AS9: 3.9050025e-05 | AT9: 3.9128281e-05 | AU9: 3.9206538e-05 | AV9: 3.9035529e-05 | AW9: 3.886452e-05 | AX9: 3.8693511e-05 | AY9: 3.8522501e-05 | AZ9: 3.8351492e-05 | BA9: 3.8180483e-05 | BB9: 3.8009474e-05 | BC9: 3.7838465e-05 | BD9: 3.7667456e-05 | BE9: 3.7496447e-05 | BF9: 3.7325438e-05 | BG9: 3.7154429e-05 | BH9: 3.6983419e-05 | BI9: 3.681241e-05 | BJ9: 3.6641401e-05 | BK9: 3.6470392e-05 | BL9: 3.6299383e-05 | BM9: 3.6128374e-05 | BN9: 3.5957365e-05 | BO9: 3.5786356e-05 | BP9: 3.5615347e-05 | BQ9: 3.5444337e-05 | BR9: 3.5273328e-05 | BS9: 3.5102319e-05 | BT9: 3.5102319e-05 | BU9: 3.5102319e-05 | BV9: 3.5102319e-05 | BW9: 3.5102319e-05 | BX9: 3.5102319e-05 | BY9: 3.5102319e-05 | BZ9: 3.5102319e-05 | CA9: 3.5102319e-05 | CB9: 3.5102319e-05 | CC9: 3.5102319e-05 | CD9: 3.5102319e-05 | CE9: 3.5102319e-05 | CF9: 3.5102319e-05 | CG9: 3.5102319e-05 | CH9: 3.5102319e-05 | CI9: 3.5102319e-05 | CJ9: 3.5102319e-05 | CK9: 3.5102319e-05 | CL9: 3.5102319e-05 | CM9: 3.5102319e-05
A10: … | B10: 0 | C10: 0 | D10: 0 | E10: 0 | F10: 0 | G10: 0 | H10: 0 | I10: 0 | J10: 0 | K10: 0 | L10: 0 | M10: 0 | N10: 0 | O10: 0 | P10: 0 | Q10: 0 | R10: 0 | S10: 0 | T10: 0 | U10: 0 | V10: 0 | W10: 0 | X10: 0 | Y10: 0 | Z10: 0 | AA10: 0 | AB10: 0 | AC10: 0 | AD10: 0 | AE10: 0 | AF10: 3.3218425e-05 | AG10: 3.3286776e-05 | AH10: 3.3355126e-05 | AI10: 3.3423477e-05 | AJ10: 3.3491828e-05 | AK10: 3.3560178e-05 | AL10: 3.3628529e-05 | AM10: 3.369688e-05 | AN10: 3.376523e-05 | AO10: 3.3833581e-05 | AP10: 3.3901932e-05 | AQ10: 3.3970282e-05 | AR10: 3.4038633e-05 | AS10: 3.4106984e-05 | AT10: 3.4175334e-05 | AU10: 3.4243685e-05 | AV10: 3.4317206e-05 | AW10: 3.4390727e-05 | AX10: 3.4464248e-05 | AY10: 3.4537768e-05 | AZ10: 3.4611289e-05 | BA10: 3.468481e-05 | BB10: 3.4758331e-05 | BC10: 3.4831852e-05 | BD10: 3.4905373e-05 | BE10: 3.4978894e-05 | BF10: 3.5052414e-05 | BG10: 3.5125935e-05 | BH10: 3.5199456e-05 | BI10: 3.5272977e-05 | BJ10: 3.5346498e-05 | BK10: 3.5420019e-05 | BL10: 3.549354e-05 | BM10: 3.556706e-05 | BN10: 3.5640581e-05 | BO10: 3.5714102e-05 | BP10: 3.5787623e-05 | BQ10: 3.5861144e-05 | BR10: 3.5934665e-05 | BS10: 3.6008186e-05 | BT10: 3.6008186e-05 | BU10: 3.6008186e-05 | BV10: 3.6008186e-05 | BW10: 3.6008186e-05 | BX10: 3.6008186e-05 | BY10: 3.6008186e-05 | BZ10: 3.6008186e-05 | CA10: 3.6008186e-05 | CB10: 3.6008186e-05 | CC10: 3.6008186e-05 | CD10: 3.6008186e-05 | CE10: 3.6008186e-05 | CF10: 3.6008186e-05 | CG10: 3.6008186e-05 | CH10: 3.6008186e-05 | CI10: 3.6008186e-05 | CJ10: 3.6008186e-05 | CK10: 3.6008186e-05 | CL10: 3.6008186e-05 | CM10: 3.6008186e-05
A11: … | B11: 0 | C11: 0 | D11: 0 | E11: 0 | F11: 0 | G11: 0 | H11: 0 | I11: 0 | J11: 0 | K11: 0 | L11: 0 | M11: 0 | N11: 0 | O11: 0 | P11: 0 | Q11: 0 | R11: 0 | S11: 0 | T11: 0 | U11: 0 | V11: 0 | W11: 0 | X11: 0 | Y11: 0 | Z11: 0 | AA11: 0 | AB11: 0 | AC11: 0 | AD11: 0 | AE11: 0 | AF11: 1.6e-05 | AG11: 1.62e-05 | AH11: 1.64e-05 | AI11: 1.66e-05 | AJ11: 1.68e-05 | AK11: 1.7e-05 | AL11: 1.72e-05 | AM11: 1.74e-05 | AN11: 1.76e-05 | AO11: 1.78e-05 | AP11: 1.8e-05 | AQ11: 1.82e-05 | AR11: 1.84e-05 | AS11: 1.86e-05 | AT11: 1.88e-05 | AU11: 1.9e-05 | AV11: 1.9041667e-05 | AW11: 1.9083333e-05 | AX11: 1.9125e-05 | AY11: 1.9166667e-05 | AZ11: 1.9208333e-05 | BA11: 1.925e-05 | BB11: 1.9291667e-05 | BC11: 1.9333333e-05 | BD11: 1.9375e-05 | BE11: 1.9416667e-05 | BF11: 1.9458333e-05 | BG11: 1.95e-05 | BH11: 1.9541667e-05 | BI11: 1.9583333e-05 | BJ11: 1.9625e-05 | BK11: 1.9666667e-05 | BL11: 1.9708333e-05 | BM11: 1.975e-05 | BN11: 1.9791667e-05 | BO11: 1.9833333e-05 | BP11: 1.9875e-05 | BQ11: 1.9916667e-05 | BR11: 1.9958333e-05 | BS11: 2e-05 | BT11: 2.005e-05 | BU11: 2.01e-05 | BV11: 2.015e-05 | BW11: 2.02e-05 | BX11: 2.025e-05 | BY11: 2.03e-05 | BZ11: 2.035e-05 | CA11: 2.04e-05 | CB11: 2.045e-05 | CC11: 2.05e-05 | CD11: 2.055e-05 | CE11: 2.06e-05 | CF11: 2.065e-05 | CG11: 2.07e-05 | CH11: 2.075e-05 | CI11: 2.08e-05 | CJ11: 2.085e-05 | CK11: 2.09e-05 | CL11: 2.095e-05 | CM11: 2.1e-05
A12: … | B12: 0 | C12: 0 | D12: 0 | E12: 0 | F12: 0 | G12: 0 | H12: 0 | I12: 0 | J12: 0 | K12: 0 | L12: 0 | M12: 0 | N12: 0 | O12: 0 | P12: 0 | Q12: 0 | R12: 0 | S12: 0 | T12: 0 | U12: 0 | V12: 0 | W12: 0 | X12: 0 | Y12: 0 | Z12: 0 | AA12: 0 | AB12: 0 | AC12: 0 | AD12: 0 | AE12: 0 | AF12: 3.6e-05 | AG12: 3.5866667e-05 | AH12: 3.5733333e-05 | AI12: 3.56e-05 | AJ12: 3.5466667e-05 | AK12: 3.5333333e-05 | AL12: 3.52e-05 | AM12: 3.5066667e-05 | AN12: 3.4933333e-05 | AO12: 3.48e-05 | AP12: 3.4666667e-05 | AQ12: 3.4533333e-05 | AR12: 3.44e-05 | AS12: 3.4266667e-05 | AT12: 3.4133333e-05 | AU12: 3.4e-05 | AV12: 3.3958333e-05 | AW12: 3.3916667e-05 | AX12: 3.3875e-05 | AY12: 3.3833333e-05 | AZ12: 3.3791667e-05 | BA12: 3.375e-05 | BB12: 3.3708333e-05 | BC12: 3.3666667e-05 | BD12: 3.3625e-05 | BE12: 3.3583333e-05 | BF12: 3.3541667e-05 | BG12: 3.35e-05 | BH12: 3.3458333e-05 | BI12: 3.3416667e-05 | BJ12: 3.3375e-05 | BK12: 3.3333333e-05 | BL12: 3.3291667e-05 | BM12: 3.325e-05 | BN12: 3.3208333e-05 | BO12: 3.3166667e-05 | BP12: 3.3125e-05 | BQ12: 3.3083333e-05 | BR12: 3.3041667e-05 | BS12: 3.3e-05 | BT12: 3.3e-05 | BU12: 3.3e-05 | BV12: 3.3e-05 | BW12: 3.3e-05 | BX12: 3.3e-05 | BY12: 3.3e-05 | BZ12: 3.3e-05 | CA12: 3.3e-05 | CB12: 3.3e-05 | CC12: 3.3e-05 | CD12: 3.3e-05 | CE12: 3.3e-05 | CF12: 3.3e-05 | CG12: 3.3e-05 | CH12: 3.3e-05 | CI12: 3.3e-05 | CJ12: 3.3e-05 | CK12: 3.3e-05 | CL12: 3.3e-05 | CM12: 3.3e-05
A14: USA.Per_capita_VFN_demand_Scenario | B14: 0 | C14: 0 | D14: 0 | E14: 0 | F14: 0 | G14: 0 | H14: 0 | I14: 0 | J14: 0 | K14: 0 | L14: 0 | M14: 0 | N14: 0 | O14: 0 | P14: 0 | Q14: 0 | R14: 0 | S14: 0 | T14: 0 | U14: 0 | V14: 0 | W14: 0 | X14: 0 | Y14: 0 | Z14: 0 | AA14: 0 | AB14: 0 | AC14: 0 | AD14: 0 | AE14: 0 | AF14: 8.09e-05 | AG14: 8.0833333e-05 | AH14: 8.0766667e-05 | AI14: 8.07e-05 | AJ14: 8.0633333e-05 | AK14: 8.0566667e-05 | AL14: 8.05e-05 | AM14: 8.0433333e-05 | AN14: 8.0366667e-05 | AO14: 8.03e-05 | AP14: 8.0233333e-05 | AQ14: 8.0166667e-05 | AR14: 8.01e-05 | AS14: 8.0033333e-05 | AT14: 7.9966667e-05 | AU14: 7.99e-05 | AV14: 7.9790909e-05 | AW14: 7.9681818e-05 | AX14: 7.9572727e-05 | AY14: 7.9463636e-05 | AZ14: 7.9354545e-05 | BA14: 7.9245455e-05 | BB14: 7.9136364e-05 | BC14: 7.9027273e-05 | BD14: 7.8918182e-05 | BE14: 7.8809091e-05 | BF14: 7.87e-05 | BG14: 7.8590909e-05 | BH14: 7.8481818e-05 | BI14: 7.8372727e-05 | BJ14: 7.8263636e-05 | BK14: 7.8154545e-05 | BL14: 7.8045455e-05 | BM14: 7.7936364e-05 | BN14: 7.7827273e-05 | BO14: 7.7718182e-05 | BP14: 7.7609091e-05 | BQ14: 7.75e-05 | BR14: 7.7390909e-05 | BS14: 7.6e-05 | BT14: 7.5955e-05 | BU14: 7.591e-05 | BV14: 7.5865e-05 | BW14: 7.582e-05 | BX14: 7.5775e-05 | BY14: 7.573e-05 | BZ14: 7.5685e-05 | CA14: 7.564e-05 | CB14: 7.5595e-05 | CC14: 7.555e-05 | CD14: 7.5505e-05 | CE14: 7.546e-05 | CF14: 7.5415e-05 | CG14: 7.537e-05 | CH14: 7.5325e-05 | CI14: 7.528e-05 | CJ14: 7.5235e-05 | CK14: 7.519e-05 | CL14: 7.5145e-05 | CM14: 7.51e-05
A16: EU27.per_capita_animal_product_demand_scenario | B16: 0 | C16: 0 | D16: 0 | E16: 0 | F16: 0 | G16: 0 | H16: 0 | I16: 0 | J16: 0 | K16: 0 | L16: 0 | M16: 0 | N16: 0 | O16: 0 | P16: 0 | Q16: 0 | R16: 0 | S16: 0 | T16: 0 | U16: 0 | V16: 0 | W16: 0 | X16: 0 | Y16: 0 | Z16: 0 | AA16: 0 | AB16: 0 | AC16: 0 | AD16: 0 | AE16: 0 | AF16: 2.6047124e-05 | AG16: 2.5931821e-05 | AH16: 2.5817027e-05 | AI16: 2.5702742e-05 | AJ16: 2.5588963e-05 | AK16: 2.5475688e-05 | AL16: 2.5362914e-05 | AM16: 2.5250639e-05 | AN16: 2.5138861e-05 | AO16: 2.5027578e-05 | AP16: 2.4916788e-05 | AQ16: 2.4806488e-05 | AR16: 2.4696676e-05 | AS16: 2.458735e-05 | AT16: 2.4478509e-05 | AU16: 2.4370149e-05 | AV16: 2.4378852e-05 | AW16: 2.4387559e-05 | AX16: 2.4396268e-05 | AY16: 2.4404981e-05 | AZ16: 2.4413697e-05 | BA16: 2.4422416e-05 | BB16: 2.4431138e-05 | BC16: 2.4439863e-05 | BD16: 2.4448591e-05 | BE16: 2.4457323e-05 | BF16: 2.4466057e-05 | BG16: 2.4474795e-05 | BH16: 2.4483535e-05 | BI16: 2.4492279e-05 | BJ16: 2.4501026e-05 | BK16: 2.4509776e-05 | BL16: 2.451853e-05 | BM16: 2.4527286e-05 | BN16: 2.4536045e-05 | BO16: 2.4544808e-05 | BP16: 2.4553574e-05 | BQ16: 2.4562343e-05 | BR16: 2.4571115e-05 | BS16: 2.457989e-05 | BT16: 2.4588668e-05 | BU16: 2.4597449e-05 | BV16: 2.4606234e-05 | BW16: 2.4615022e-05 | BX16: 2.4623812e-05 | BY16: 2.4632606e-05 | BZ16: 2.4641404e-05 | CA16: 2.4650204e-05 | CB16: 2.4659007e-05 | CC16: 2.4667814e-05 | CD16: 2.4676623e-05 | CE16: 2.4685436e-05 | CF16: 2.4694252e-05 | CG16: 2.4703071e-05 | CH16: 2.4711893e-05 | CI16: 2.4720719e-05 | CJ16: 2.4729547e-05 | CK16: 2.4738379e-05 | CL16: 2.4747214e-05 | CM16: 2.4756052e-05
... A551: Oceania.potential forage crop yield | B551: 0 | C551: 0 | D551: 0 | E551: 0 | F551: 0 | G551: 0 | H551: 0 | I551: 0 | J551: 0 | K551: 0 | L551: 0 | M551: 0 | N551: 0 | O551: 0 | P551: 0 | Q551: 0 | R551: 0 | S551: 0 | T551: 0 | U551: 0 | V551: 0 | W551: 0 | X551: 0 | Y551: 0 | Z551: 0 | AA551: 0 | AB551: 0 | AC551: 0 | AD551: 0 | AE551: 0 | AF551: 0.00086618671 | AG551: 0.00087332066 | AH551: 0.0008804546 | AI551: 0.00088758854 | AJ551: 0.00089472249 | AK551: 0.00090185643 | AL551: 0.00090899038 | AM551: 0.00091612432 | AN551: 0.00092325827 | AO551: 0.00093039221 | AP551: 0.00093752615 | AQ551: 0.0009446601 | AR551: 0.00095179404 | AS551: 0.00095892799 | AT551: 0.00096606193 | AU551: 0.00097319588 | AV551: 0.00099072165 | AW551: 0.0010082474 | AX551: 0.0010257732 | AY551: 0.001043299 | AZ551: 0.0010608247 | BA551: 0.0010783505 | BB551: 0.0010958763 | BC551: 0.0011134021 | BD551: 0.0011309278 | BE551: 0.0011484536 | BF551: 0.0011659794 | BG551: 0.0011835052 | BH551: 0.0012010309 | BI551: 0.0012185567 | BJ551: 0.0012360825 | BK551: 0.0012536082 | BL551: 0.001271134 | BM551: 0.0012886598 | BN551: 0.0013061856 | BO551: 0.0013237113 | BP551: 0.0013412371 | BQ551: 0.0013587629 | BR551: 0.0013762887 | BS551: 0.0013938144 | BT551: 0.0014113402 | BU551: 0.001428866 | BV551: 0.0014463918 | BW551: 0.0014639175 | BX551: 0.0014814433 | BY551: 0.0014989691 | BZ551: 0.0015164948 | CA551: 0.0015340206 | CB551: 0.0015515464 | CC551: 0.0015690722 | CD551: 0.0015865979 | CE551: 0.0016041237 | CF551: 0.0016216495 | CG551: 0.0016391753 | CH551: 0.001656701 | CI551: 0.0016742268 | CJ551: 0.0016917526 | CK551: 0.0017092784 | CL551: 0.0017268041 | CM551: 0.0017443299
A553: USA.Crop Land Alloc to Cellulosic Energy Crop | B553: ='WAO Scenario Ag'!B23 -> 0 | C553: ='WAO Scenario Ag'!C23 -> 0 | D553: ='WAO Scenario Ag'!D23 -> 0 | E553: ='WAO Scenario Ag'!E23 -> 0 | F553: ='WAO Scenario Ag'!F23 -> 0 | G553: ='WAO Scenario Ag'!G23 -> 0 | H553: ='WAO Scenario Ag'!H23 -> 0 | I553: ='WAO Scenario Ag'!I23 -> 0 | ... AE553: ='WAO Scenario Ag'!AE23 -> 0 | AF553: 264298.13 | AG553: 520633.93 | AH553: 769361.87 | AI553: 1010815.7 | AJ553: 1245309.9 | AK553: 1473141.1 | AL553: 1694589.3 | AM553: 1909919.1 | AN553: 2119380.6 | AO553: 2323210.4 | AP553: 2528030.7 | AQ553: 3025243.2 | AR553: 3914439.4 | AS553: 4710896.4 | AT553: 5525197 | AU553: 7231647.8 | AV553: 10062408 | AW553: 13916648 | AX553: 14989750 | AY553: 16052595 | AZ553: 17105346 | BA553: 18148159 | BB553: 19181186 | BC553: 20204578 | BD553: 21218479 | BE553: 22223033 | BF553: 23218379 | BG553: 24204653 | BH553: 25181987 | BI553: 25064613 | BJ553: 24948435 | BK553: 24833433 | BL553: 24719587 | BM553: 24606877 | BN553: 24495283 | BO553: 24384788 | BP553: 24275373 | BQ553: 24167021 | BR553: 24059713 | BS553: 23953434 | BT553: 23848166 | BU553: 23743894 | BV553: 23640602 | BW553: 23538275 | BX553: 23436897 | BY553: 23336455 | BZ553: 23236934 | CA553: 23138319 | CB553: 23040598 | CC553: 22943757 | CD553: 22847784 | CE553: 22752664 | CF553: 22658386 | CG553: 22564938 | CH553: 22472307 | CI553: 22380482 | CJ553: 22289452 | CK553: 22199206 | CL553: 22109732 | CM553: 22021019
A555: ROW.Crop Land Alloc to Cellulosic Energy Crop | B555: ='WAO Scenario Ag'!B24 -> 0 | C555: ='WAO Scenario Ag'!C24 -> 0 | D555: ='WAO Scenario Ag'!D24 -> 0 | E555: ='WAO Scenario Ag'!E24 -> 0 | F555: ='WAO Scenario Ag'!F24 -> 0 | G555: ='WAO Scenario Ag'!G24 -> 0 | H555: ='WAO Scenario Ag'!H24 -> 0 | I555: ='WAO Scenario Ag'!I24 -> 0 | ... AE555: ='WAO Scenario Ag'!AE24 -> 0 | AF555: 777759.75 | AG555: 1533792.2 | AH555: 2269044.3 | AI555: 2984406.7 | AJ555: 3680718.1 | AK555: 4358769 | AL555: 5019305.1 | AM555: 5663030.8 | AN555: 6290611.7 | AO555: 6902677.8 | AP555: 7508541.5 | AQ555: 8605931.5 | AR555: 10082152 | AS555: 10285870 | AT555: 12902611 | AU555: 17390372 | AV555: 22066463 | AW555: 30990902 | AX555: 35552080 | AY555: 40030397 | AZ555: 44428125 | BA555: 48747457 | BB555: 52990502 | BC555: 57159297 | BD555: 61255802 | BE555: 65281912 | BF555: 69239453 | BG555: 73130189 | BH555: 76955815 | BI555: 76318164 | BJ555: 75691156 | BK555: 75074522 | BL555: 74468004 | BM555: 73871353 | BN555: 73284328 | BO555: 72706695 | BP555: 72138229 | BQ555: 71578710 | BR555: 71027928 | BS555: 70485676 | BT555: 69951757 | BU555: 69425978 | BV555: 68908153 | BW555: 68398100 | BX555: 67895645 | BY555: 67400618 | BZ555: 66912853 | CA555: 66432191 | CB555: 65958476 | CC555: 65491558 | CD555: 65031289 | CE555: 64577528 | CF555: 64130137 | CG555: 63688981 | CH555: 63253930 | CI555: 62824857 | CJ555: 62401638 | CK555: 61984154 | CL555: 61572288 | CM555: 61165926
A557: USA.population_scenario | B557: 0 | C557: 0 | D557: 0 | E557: 0 | F557: 0 | G557: 0 | H557: 0 | I557: 0 | J557: 0 | K557: 0 | L557: 0 | M557: 0 | N557: 0 | O557: 0 | P557: 0 | Q557: 0 | R557: 0 | S557: 0 | T557: 0 | U557: 0 | V557: 0 | W557: 0 | X557: 0 | Y557: 0 | Z557: 0 | AA557: 0 | AB557: 0 | AC557: 0 | AD557: 0 | AE557: 0 | AF557: 2.2899816e+08 | AG557: 2.3305863e+08 | AH557: 2.3706164e+08 | AI557: 2.4101808e+08 | AJ557: 2.4493668e+08 | AK557: 2.4881632e+08 | AL557: 2.5265408e+08 | AM557: 2.5646195e+08 | AN557: 2.6025608e+08 | AO557: 2.6404815e+08 | AP557: 2.6784313e+08 | AQ557: 2.7164009e+08 | AR557: 2.7543902e+08 | AS557: 2.7923853e+08 | AT557: 2.8303633e+08 | AU557: 2.8683147e+08 | AV557: 2.906253e+08 | AW557: 2.9441962e+08 | AX557: 2.9821625e+08 | AY557: 3.0201472e+08 | AZ557: 3.0581502e+08 | BA557: 3.0961117e+08 | BB557: 3.1339488e+08 | BC557: 3.1715458e+08 | BD557: 3.2088055e+08 | BE557: 3.2456898e+08 | BF557: 3.2821563e+08 | BG557: 3.3181346e+08 | BH557: 3.353545e+08 | BI557: 3.3883073e+08 | BJ557: 3.4224016e+08 | BK557: 3.4557987e+08 | BL557: 3.4884784e+08 | BM557: 3.5204531e+08 | BN557: 3.5517122e+08 | BO557: 3.5822451e+08 | BP557: 3.6120502e+08 | BQ557: 3.641145e+08 | BR557: 3.6695562e+08 | BS557: 3.6973059e+08 | BT557: 3.724393e+08 | BU557: 3.7508354e+08 | BV557: 3.7766506e+08 | BW557: 3.8018938e+08 | BX557: 3.8265878e+08 | BY557: 3.8507504e+08 | BZ557: 3.8743532e+08 | CA557: 3.8973813e+08 | CB557: 3.9197967e+08 | CC557: 3.9415705e+08 | CD557: 3.9626647e+08 | CE557: 3.9830831e+08 | CF557: 4.0027921e+08 | CG557: 4.0217911e+08 | CH557: 4.0400604e+08 | CI557: 4.0575619e+08 | CJ557: 4.0742571e+08 | CK557: 4.0900981e+08 | CL557: 4.1050277e+08 | CM557: 4.1189649e+08
A559: EU27.population_scenario | B559: 0 | C559: 0 | D559: 0 | E559: 0 | F559: 0 | G559: 0 | H559: 0 | I559: 0 | J559: 0 | K559: 0 | L559: 0 | M559: 0 | N559: 0 | O559: 0 | P559: 0 | Q559: 0 | R559: 0 | S559: 0 | T559: 0 | U559: 0 | V559: 0 | W559: 0 | X559: 0 | Y559: 0 | Z559: 0 | AA559: 0 | AB559: 0 | AC559: 0 | AD559: 0 | AE559: 0 | AF559: 4.3451721e+08 | AG559: 4.376781e+08 | AH559: 4.4071066e+08 | AI559: 4.4363905e+08 | AJ559: 4.4648247e+08 | AK559: 4.4924154e+08 | AL559: 4.5191361e+08 | AM559: 4.5452249e+08 | AN559: 4.5709835e+08 | AO559: 4.5966258e+08 | AP559: 4.6222412e+08 | AQ559: 4.6478158e+08 | AR559: 4.6733514e+08 | AS559: 4.6988265e+08 | AT559: 4.7242053e+08 | AU559: 4.7494753e+08 | AV559: 4.7746621e+08 | AW559: 4.7997978e+08 | AX559: 4.8249138e+08 | AY559: 4.8500036e+08 | AZ559: 4.8750685e+08 | BA559: 4.9000151e+08 | BB559: 4.9247161e+08 | BC559: 4.9489971e+08 | BD559: 4.9727164e+08 | BE559: 4.9958276e+08 | BF559: 5.0182781e+08 | BG559: 5.0399745e+08 | BH559: 5.060811e+08 | BI559: 5.0806842e+08 | BJ559: 5.0995823e+08 | BK559: 5.1174798e+08 | BL559: 5.134365e+08 | BM559: 5.1502739e+08 | BN559: 5.1652076e+08 | BO559: 5.1791669e+08 | BP559: 5.1921659e+08 | BQ559: 5.2042445e+08 | BR559: 5.2154551e+08 | BS559: 5.2258421e+08 | BT559: 5.2354162e+08 | BU559: 5.2442139e+08 | BV559: 5.2522705e+08 | BW559: 5.2596727e+08 | BX559: 5.2664599e+08 | BY559: 5.2726647e+08 | BZ559: 5.2782552e+08 | CA559: 5.2832188e+08 | CB559: 5.2875116e+08 | CC559: 5.2911029e+08 | CD559: 5.2939499e+08 | CE559: 5.2960665e+08 | CF559: 5.2974166e+08 | CG559: 5.2980078e+08 | CH559: 5.2978229e+08 | CI559: 5.2968203e+08 | CJ559: 5.294959e+08 | CK559: 5.2921862e+08 | CL559: 5.2884378e+08 | CM559: 5.2836203e+08
A561: BRAZIL.population_scenario | B561: 0 | C561: 0 | D561: 0 | E561: 0 | F561: 0 | G561: 0 | H561: 0 | I561: 0 | J561: 0 | K561: 0 | L561: 0 | M561: 0 | N561: 0 | O561: 0 | P561: 0 | Q561: 0 | R561: 0 | S561: 0 | T561: 0 | U561: 0 | V561: 0 | W561: 0 | X561: 0 | Y561: 0 | Z561: 0 | AA561: 0 | AB561: 0 | AC561: 0 | AD561: 0 | AE561: 0 | AF561: 1.3801566e+08 | AG561: 1.4097145e+08 | AH561: 1.4389476e+08 | AI561: 1.4679178e+08 | AJ561: 1.4966746e+08 | AK561: 1.5252082e+08 | AL561: 1.5534979e+08 | AM561: 1.5816148e+08 | AN561: 1.6096565e+08 | AO561: 1.6376945e+08 | AP561: 1.6657593e+08 | AQ561: 1.6938447e+08 | AR561: 1.7219505e+08 | AS561: 1.7500679e+08 | AT561: 1.7781821e+08 | AU561: 1.8062868e+08 | AV561: 1.8343901e+08 | AW561: 1.8625031e+08 | AX561: 1.8906372e+08 | AY561: 1.9187892e+08 | AZ561: 1.9469589e+08 | BA561: 1.975108e+08 | BB561: 2.0031832e+08 | BC561: 2.0311098e+08 | BD561: 2.0588242e+08 | BE561: 2.0863008e+08 | BF561: 2.1135108e+08 | BG561: 2.1404072e+08 | BH561: 2.166937e+08 | BI561: 2.1930464e+08 | BJ561: 2.2187205e+08 | BK561: 2.2439383e+08 | BL561: 2.2686846e+08 | BM561: 2.2929657e+08 | BN561: 2.3167726e+08 | BO561: 2.3400966e+08 | BP561: 2.3629349e+08 | BQ561: 2.3852973e+08 | BR561: 2.4071997e+08 | BS561: 2.4286551e+08 | BT561: 2.4496614e+08 | BU561: 2.4702291e+08 | BV561: 2.4903686e+08 | BW561: 2.5101151e+08 | BX561: 2.5294828e+08 | BY561: 2.5484826e+08 | BZ561: 2.5670947e+08 | CA561: 2.5853087e+08 | CB561: 2.6030984e+08 | CC561: 2.6204436e+08 | CD561: 2.6373182e+08 | CE561: 2.6537237e+08 | CF561: 2.6696369e+08 | CG561: 2.6850562e+08 | CH561: 2.6999677e+08 | CI561: 2.7143449e+08 | CJ561: 2.7281609e+08 | CK561: 2.7413829e+08 | CL561: 2.7539711e+08 | CM561: 2.7658701e+08
A563: CAN.population_scenario | B563: 0 | C563: 0 | D563: 0 | E563: 0 | F563: 0 | G563: 0 | H563: 0 | I563: 0 | J563: 0 | K563: 0 | L563: 0 | M563: 0 | N563: 0 | O563: 0 | P563: 0 | Q563: 0 | R563: 0 | S563: 0 | T563: 0 | U563: 0 | V563: 0 | W563: 0 | X563: 0 | Y563: 0 | Z563: 0 | AA563: 0 | AB563: 0 | AC563: 0 | AD563: 0 | AE563: 0 | AF563: 26993343 | AG563: 27312827 | AH563: 27624862 | AI563: 27930854 | AJ563: 28231924 | AK563: 28528036 | AL563: 28818948 | AM563: 29106110 | AN563: 29391409 | AO563: 29676194 | AP563: 29961036 | AQ563: 30245836 | AR563: 30530600 | AS563: 30815183 | AT563: 31099340 | AU563: 31382979 | AV563: 31666260 | AW563: 31949387 | AX563: 32232563 | AY563: 32515743 | AZ563: 32798930 | BA563: 33081488 | BB563: 33362546 | BC563: 33640900 | BD563: 33915551 | BE563: 34186143 | BF563: 34452273 | BG563: 34713250 | BH563: 34968296 | BI563: 35216636 | BJ563: 35458126 | BK563: 35692526 | BL563: 35919693 | BM563: 36139815 | BN563: 36352842 | BO563: 36558722 | BP563: 36757497 | BQ563: 36949396 | BR563: 37134740 | BS563: 37313798 | BT563: 37486602 | BU563: 37653371 | BV563: 37814321 | BW563: 37970037 | BX563: 38120776 | BY563: 38266742 | BZ563: 38407678 | CA563: 38543464 | CB563: 38673750 | CC563: 38798281 | CD563: 38916709 | CE563: 39029105 | CF563: 39135169 | CG563: 39234924 | CH563: 39328210 | CI563: 39414683 | CJ563: 39494003 | CK563: 39565739 | CL563: 39629372 | CM563: 39684157
A565: JAPAN.population_scenario | B565: 0 | C565: 0 | D565: 0 | E565: 0 | F565: 0 | G565: 0 | H565: 0 | I565: 0 | J565: 0 | K565: 0 | L565: 0 | M565: 0 | N565: 0 | O565: 0 | P565: 0 | Q565: 0 | R565: 0 | S565: 0 | T565: 0 | U565: 0 | V565: 0 | W565: 0 | X565: 0 | Y565: 0 | Z565: 0 | AA565: 0 | AB565: 0 | AC565: 0 | AD565: 0 | AE565: 0 | AF565: 1.1822141e+08 | AG565: 1.1866798e+08 | AH565: 1.1907788e+08 | AI565: 1.1945799e+08 | AJ565: 1.1981379e+08 | AK565: 1.201457e+08 | AL565: 1.2045325e+08 | AM565: 1.2074301e+08 | AN565: 1.2102317e+08 | AO565: 1.2129945e+08 | AP565: 1.2157425e+08 | AQ565: 1.2184723e+08 | AR565: 1.2211846e+08 | AS565: 1.2238739e+08 | AT565: 1.2265311e+08 | AU565: 1.2291535e+08 | AV565: 1.2317479e+08 | AW565: 1.234323e+08 | AX565: 1.2368868e+08 | AY565: 1.239438e+08 | AZ565: 1.241977e+08 | BA565: 1.2444802e+08 | BB565: 1.2469157e+08 | BC565: 1.2492402e+08 | BD565: 1.251419e+08 | BE565: 1.2534418e+08 | BF565: 1.2552969e+08 | BG565: 1.2569624e+08 | BH565: 1.2584139e+08 | BI565: 1.2596274e+08 | BJ565: 1.2606023e+08 | BK565: 1.2613343e+08 | BL565: 1.2618226e+08 | BM565: 1.2620782e+08 | BN565: 1.2621032e+08 | BO565: 1.2618999e+08 | BP565: 1.2614735e+08 | BQ565: 1.2608356e+08 | BR565: 1.2600006e+08 | BS565: 1.2589808e+08 | BT565: 1.2577803e+08 | BU565: 1.2564091e+08 | BV565: 1.2548773e+08 | BW565: 1.2532065e+08 | BX565: 1.2514073e+08 | BY565: 1.2494884e+08 | BZ565: 1.2474431e+08 | CA565: 1.2452694e+08 | CB565: 1.242958e+08 | CC565: 1.2405026e+08 | CD565: 1.2378944e+08 | CE565: 1.2351376e+08 | CF565: 1.2322251e+08 | CG565: 1.2291596e+08 | CH565: 1.2259383e+08 | CI565: 1.2225526e+08 | CJ565: 1.2189945e+08 | CK565: 1.2152528e+08 | CL565: 1.2113143e+08 | CM565: 1.207159e+08
A567: CHIHKG.population_scenario | B567: 0 | C567: 0 | D567: 0 | E567: 0 | F567: 0 | G567: 0 | H567: 0 | I567: 0 | J567: 0 | K567: 0 | L567: 0 | M567: 0 | N567: 0 | O567: 0 | P567: 0 | Q567: 0 | R567: 0 | S567: 0 | T567: 0 | U567: 0 | V567: 0 | W567: 0 | X567: 0 | Y567: 0 | Z567: 0 | AA567: 0 | AB567: 0 | AC567: 0 | AD567: 0 | AE567: 0 | AF567: 1.1397091e+09 | AG567: 1.1493517e+09 | AH567: 1.1586634e+09 | AI567: 1.1677066e+09 | AJ567: 1.1765309e+09 | AK567: 1.185137e+09 | AL567: 1.1935172e+09 | AM567: 1.2017335e+09 | AN567: 1.2098653e+09 | AO567: 1.2179689e+09 | AP567: 1.2260679e+09 | AQ567: 1.2341585e+09 | AR567: 1.2422411e+09 | AS567: 1.2503101e+09 | AT567: 1.2583556e+09 | AU567: 1.2663744e+09 | AV567: 1.274373e+09 | AW567: 1.2823601e+09 | AX567: 1.2903439e+09 | AY567: 1.2983226e+09 | AZ567: 1.3062966e+09 | BA567: 1.3142407e+09 | BB567: 1.3221206e+09 | BC567: 1.3298894e+09 | BD567: 1.3375085e+09 | BE567: 1.344965e+09 | BF567: 1.3522443e+09 | BG567: 1.3593206e+09 | BH567: 1.366165e+09 | BI567: 1.3727487e+09 | BJ567: 1.379068e+09 | BK567: 1.3851152e+09 | BL567: 1.3908866e+09 | BM567: 1.3963911e+09 | BN567: 1.4016284e+09 | BO567: 1.4065982e+09 | BP567: 1.4113035e+09 | BQ567: 1.4157547e+09 | BR567: 1.4199655e+09 | BS567: 1.4239474e+09 | BT567: 1.4277029e+09 | BU567: 1.4312415e+09 | BV567: 1.4345723e+09 | BW567: 1.4377186e+09 | BX567: 1.4406909e+09 | BY567: 1.4434978e+09 | BZ567: 1.4461302e+09 | CA567: 1.4485845e+09 | CB567: 1.4508481e+09 | CC567: 1.4529124e+09 | CD567: 1.4547652e+09 | CE567: 1.4564101e+09 | CF567: 1.4578366e+09 | CG567: 1.4590466e+09 | CH567: 1.4600349e+09 | CI567: 1.4607898e+09 | CJ567: 1.4612994e+09 | CK567: 1.4615489e+09 | CL567: 1.46152e+09 | CM567: 1.4611865e+09
A569: INDIA.population_scenario | B569: 0 | C569: 0 | D569: 0 | E569: 0 | F569: 0 | G569: 0 | H569: 0 | I569: 0 | J569: 0 | K569: 0 | L569: 0 | M569: 0 | N569: 0 | O569: 0 | P569: 0 | Q569: 0 | R569: 0 | S569: 0 | T569: 0 | U569: 0 | V569: 0 | W569: 0 | X569: 0 | Y569: 0 | Z569: 0 | AA569: 0 | AB569: 0 | AC569: 0 | AD569: 0 | AE569: 0 | AF569: 8.4726203e+08 | AG569: 8.6258212e+08 | AH569: 8.7769085e+08 | AI569: 8.926283e+08 | AJ569: 9.0742661e+08 | AK569: 9.2208145e+08 | AL569: 9.3658185e+08 | AM569: 9.5097209e+08 | AN569: 9.6531191e+08 | AO569: 9.7964465e+08 | AP569: 9.9398867e+08 | AQ569: 1.0083405e+09 | AR569: 1.0227002e+09 | AS569: 1.0370625e+09 | AT569: 1.0514188e+09 | AU569: 1.0657657e+09 | AV569: 1.0801081e+09 | AW569: 1.0944528e+09 | AX569: 1.1088064e+09 | AY569: 1.1231672e+09 | AZ569: 1.1375352e+09 | BA569: 1.151888e+09 | BB569: 1.1661949e+09 | BC569: 1.1804128e+09 | BD569: 1.1945053e+09 | BE569: 1.2084583e+09 | BF569: 1.2222558e+09 | BG569: 1.2358716e+09 | BH569: 1.2492758e+09 | BI569: 1.2624385e+09 | BJ569: 1.2753521e+09 | BK569: 1.2880057e+09 | BL569: 1.3003915e+09 | BM569: 1.3125142e+09 | BN569: 1.3243696e+09 | BO569: 1.3359537e+09 | BP569: 1.3472658e+09 | BQ569: 1.3583122e+09 | BR569: 1.369103e+09 | BS569: 1.3796461e+09 | BT569: 1.3899413e+09 | BU569: 1.3999949e+09 | BV569: 1.4098136e+09 | BW569: 1.4194178e+09 | BX569: 1.4288161e+09 | BY569: 1.4380149e+09 | BZ569: 1.4470037e+09 | CA569: 1.4557769e+09 | CB569: 1.4643201e+09 | CC569: 1.4726226e+09 | CD569: 1.4806701e+09 | CE569: 1.4884639e+09 | CF569: 1.4959915e+09 | CG569: 1.5032525e+09 | CH569: 1.5102397e+09 | CI569: 1.5169385e+09 | CJ569: 1.5233346e+09 | CK569: 1.5294101e+09 | CL569: 1.5351434e+09 | CM569: 1.5405042e+09
A571: C_C_Amer.population_scenario | B571: 0 | C571: 0 | D571: 0 | E571: 0 | F571: 0 | G571: 0 | H571: 0 | I571: 0 | J571: 0 | K571: 0 | L571: 0 | M571: 0 | N571: 0 | O571: 0 | P571: 0 | Q571: 0 | R571: 0 | S571: 0 | T571: 0 | U571: 0 | V571: 0 | W571: 0 | X571: 0 | Y571: 0 | Z571: 0 | AA571: 0 | AB571: 0 | AC571: 0 | AD571: 0 | AE571: 0 | AF571: 1.5312211e+08 | AG571: 1.5485071e+08 | AH571: 1.565367e+08 | AI571: 1.5818812e+08 | AJ571: 1.5981137e+08 | AK571: 1.6140631e+08 | AL571: 1.6297162e+08 | AM571: 1.6451553e+08 | AN571: 1.6604874e+08 | AO571: 1.675789e+08 | AP571: 1.6910922e+08 | AQ571: 1.7063917e+08 | AR571: 1.7216877e+08 | AS571: 1.7369721e+08 | AT571: 1.7522312e+08 | AU571: 1.7674599e+08 | AV571: 1.7826671e+08 | AW571: 1.7978645e+08 | AX571: 1.8130635e+08 | AY571: 1.8282616e+08 | AZ571: 1.843459e+08 | BA571: 1.85862e+08 | BB571: 1.8736958e+08 | BC571: 1.8886188e+08 | BD571: 1.9033332e+08 | BE571: 1.9178192e+08 | BF571: 1.9320546e+08 | BG571: 1.9460008e+08 | BH571: 1.9596146e+08 | BI571: 1.9728529e+08 | BJ571: 1.9857081e+08 | BK571: 1.998167e+08 | BL571: 2.010222e+08 | BM571: 2.021884e+08 | BN571: 2.0331506e+08 | BO571: 2.0440192e+08 | BP571: 2.0544926e+08 | BQ571: 2.0645837e+08 | BR571: 2.0743109e+08 | BS571: 2.0836896e+08 | BT571: 2.0927216e+08 | BU571: 2.1014195e+08 | BV571: 2.1097956e+08 | BW571: 2.1178828e+08 | BX571: 2.1256954e+08 | BY571: 2.1332452e+08 | BZ571: 2.1405179e+08 | CA571: 2.147507e+08 | CB571: 2.1541932e+08 | CC571: 2.1605623e+08 | CD571: 2.1665954e+08 | CE571: 2.1722965e+08 | CF571: 2.177649e+08 | CG571: 2.1826545e+08 | CH571: 2.1873042e+08 | CI571: 2.1915793e+08 | CJ571: 2.1954609e+08 | CK571: 2.1989254e+08 | CL571: 2.2019441e+08 | CM571: 2.204476e+08
A573: S_o_Amer.population_scenario | B573: 0 | C573: 0 | D573: 0 | E573: 0 | F573: 0 | G573: 0 | H573: 0 | I573: 0 | J573: 0 | K573: 0 | L573: 0 | M573: 0 | N573: 0 | O573: 0 | P573: 0 | Q573: 0 | R573: 0 | S573: 0 | T573: 0 | U573: 0 | V573: 0 | W573: 0 | X573: 0 | Y573: 0 | Z573: 0 | AA573: 0 | AB573: 0 | AC573: 0 | AD573: 0 | AE573: 0 | AF573: 1.524707e+08 | AG573: 1.5448275e+08 | AH573: 1.564536e+08 | AI573: 1.5839104e+08 | AJ573: 1.6030128e+08 | AK573: 1.62184e+08 | AL573: 1.6403768e+08 | AM573: 1.6587047e+08 | AN573: 1.6769306e+08 | AO573: 1.6951311e+08 | AP573: 1.7133384e+08 | AQ573: 1.731547e+08 | AR573: 1.749757e+08 | AS573: 1.76796e+08 | AT573: 1.786142e+08 | AU573: 1.8042973e+08 | AV573: 1.8224351e+08 | AW573: 1.8405669e+08 | AX573: 1.8587044e+08 | AY573: 1.8768449e+08 | AZ573: 1.8949885e+08 | BA573: 1.9130985e+08 | BB573: 1.9311241e+08 | BC573: 1.9489953e+08 | BD573: 1.9666539e+08 | BE573: 1.9840783e+08 | BF573: 2.0012447e+08 | BG573: 2.0181123e+08 | BH573: 2.0346348e+08 | BI573: 2.0507664e+08 | BJ573: 2.0664977e+08 | BK573: 2.0818139e+08 | BL573: 2.0967055e+08 | BM573: 2.1111827e+08 | BN573: 2.1252417e+08 | BO573: 2.1388786e+08 | BP573: 2.1520949e+08 | BQ573: 2.1649034e+08 | BR573: 2.1773219e+08 | BS573: 2.1893657e+08 | BT573: 2.2010361e+08 | BU573: 2.2123451e+08 | BV573: 2.2233048e+08 | BW573: 2.2339494e+08 | BX573: 2.2442932e+08 | BY573: 2.2543481e+08 | BZ573: 2.2640983e+08 | CA573: 2.2735365e+08 | CB573: 2.2826416e+08 | CC573: 2.291398e+08 | CD573: 2.2997849e+08 | CE573: 2.3078058e+08 | CF573: 2.3154426e+08 | CG573: 2.3226961e+08 | CH573: 2.3295565e+08 | CI573: 2.3360029e+08 | CJ573: 2.3420146e+08 | CK573: 2.3475656e+08 | CL573: 2.3526244e+08 | CM573: 2.3571463e+08
A575: E_Asia.population_scenario | B575: 0 | C575: 0 | D575: 0 | E575: 0 | F575: 0 | G575: 0 | H575: 0 | I575: 0 | J575: 0 | K575: 0 | L575: 0 | M575: 0 | N575: 0 | O575: 0 | P575: 0 | Q575: 0 | R575: 0 | S575: 0 | T575: 0 | U575: 0 | V575: 0 | W575: 0 | X575: 0 | Y575: 0 | Z575: 0 | AA575: 0 | AB575: 0 | AC575: 0 | AD575: 0 | AE575: 0 | AF575: 86151221 | AG575: 86772924 | AH575: 87369161 | AI575: 87944726 | AJ575: 88503430 | AK575: 89045400 | AL575: 89570111 | AM575: 90082286 | AN575: 90587908 | AO575: 91091214 | AP575: 91593979 | AQ575: 92095926 | AR575: 92597090 | AS575: 93097048 | AT575: 93595089 | AU575: 94090967 | AV575: 94585189 | AW575: 95078391 | AX575: 95571195 | AY575: 96063474 | AZ575: 96555252 | BA575: 97044679 | BB575: 97529236 | BC575: 98005471 | BD575: 98470577 | BE575: 98923638 | BF575: 99363614 | BG575: 99788656 | BH575: 1.0019667e+08 | BI575: 1.0058562e+08 | BJ575: 1.0095527e+08 | BK575: 1.0130511e+08 | BL575: 1.0163493e+08 | BM575: 1.0194542e+08 | BN575: 1.0223662e+08 | BO575: 1.0250855e+08 | BP575: 1.0276148e+08 | BQ575: 1.0299621e+08 | BR575: 1.0321378e+08 | BS575: 1.0341507e+08 | BT575: 1.0360029e+08 | BU575: 1.0377016e+08 | BV575: 1.0392539e+08 | BW575: 1.0406769e+08 | BX575: 1.0419785e+08 | BY575: 1.0431651e+08 | BZ575: 1.0442303e+08 | CA575: 1.0451718e+08 | CB575: 1.0459808e+08 | CC575: 1.0466513e+08 | CD575: 1.0471748e+08 | CE575: 1.0475541e+08 | CF575: 1.0477821e+08 | CG575: 1.0478603e+08 | CH575: 1.0477852e+08 | CI575: 1.0475488e+08 | CJ575: 1.0471428e+08 | CK575: 1.0465569e+08 | CL575: 1.0457784e+08 | CM575: 1.0447888e+08
A577: Mala_Indo.population_scenario | B577: 0 | C577: 0 | D577: 0 | E577: 0 | F577: 0 | G577: 0 | H577: 0 | I577: 0 | J577: 0 | K577: 0 | L577: 0 | M577: 0 | N577: 0 | O577: 0 | P577: 0 | Q577: 0 | R577: 0 | S577: 0 | T577: 0 | U577: 0 | V577: 0 | W577: 0 | X577: 0 | Y577: 0 | Z577: 0 | AA577: 0 | AB577: 0 | AC577: 0 | AD577: 0 | AE577: 0 | AF577: 2.0450704e+08 | AG577: 2.0695507e+08 | AH577: 2.0934676e+08 | AI577: 2.1169277e+08 | AJ577: 2.1400157e+08 | AK577: 2.1627287e+08 | AL577: 2.1850482e+08 | AM577: 2.207084e+08 | AN577: 2.2289791e+08 | AO577: 2.2508357e+08 | AP577: 2.272697e+08 | AQ577: 2.2945557e+08 | AR577: 2.3164122e+08 | AS577: 2.3382553e+08 | AT577: 2.3600666e+08 | AU577: 2.381839e+08 | AV577: 2.4035846e+08 | AW577: 2.4253189e+08 | AX577: 2.4470573e+08 | AY577: 2.4687964e+08 | AZ577: 2.4905363e+08 | BA577: 2.5122289e+08 | BB577: 2.5338079e+08 | BC577: 2.5551818e+08 | BD577: 2.5762747e+08 | BE577: 2.5970594e+08 | BF577: 2.6175052e+08 | BG577: 2.6375597e+08 | BH577: 2.6571634e+08 | BI577: 2.6762575e+08 | BJ577: 2.6948308e+08 | BK577: 2.7128651e+08 | BL577: 2.7303492e+08 | BM577: 2.7472974e+08 | BN577: 2.7637058e+08 | BO577: 2.7795702e+08 | BP577: 2.7948938e+08 | BQ577: 2.8096938e+08 | BR577: 2.8239946e+08 | BS577: 2.8378166e+08 | BT577: 2.8511621e+08 | BU577: 2.8640477e+08 | BV577: 2.8764896e+08 | BW577: 2.8885325e+08 | BX577: 2.9001956e+08 | BY577: 2.9114946e+08 | BZ577: 2.9224098e+08 | CA577: 2.9329319e+08 | CB577: 2.9430344e+08 | CC577: 2.9526978e+08 | CD577: 2.9618955e+08 | CE577: 2.9706329e+08 | CF577: 2.978887e+08 | CG577: 2.9866596e+08 | CH577: 2.9939383e+08 | CI577: 3.0006971e+08 | CJ577: 3.0069098e+08 | CK577: 3.0125436e+08 | CL577: 3.017559e+08 | CM577: 3.0218991e+08
A579: R_SE_Asia.population_scenario | B579: 0 | C579: 0 | D579: 0 | E579: 0 | F579: 0 | G579: 0 | H579: 0 | I579: 0 | J579: 0 | K579: 0 | L579: 0 | M579: 0 | N579: 0 | O579: 0 | P579: 0 | Q579: 0 | R579: 0 | S579: 0 | T579: 0 | U579: 0 | V579: 0 | W579: 0 | X579: 0 | Y579: 0 | Z579: 0 | AA579: 0 | AB579: 0 | AC579: 0 | AD579: 0 | AE579: 0 | AF579: 2.4342282e+08 | AG579: 2.4741339e+08 | AH579: 2.5134149e+08 | AI579: 2.5521896e+08 | AJ579: 2.5905525e+08 | AK579: 2.6284938e+08 | AL579: 2.6659846e+08 | AM579: 2.703153e+08 | AN579: 2.7401703e+08 | AO579: 2.7771603e+08 | AP579: 2.8141753e+08 | AQ579: 2.8512057e+08 | AR579: 2.8882515e+08 | AS579: 2.9252984e+08 | AT579: 2.9623226e+08 | AU579: 2.9993143e+08 | AV579: 3.0362879e+08 | AW579: 3.0732623e+08 | AX579: 3.1102568e+08 | AY579: 3.1472665e+08 | AZ579: 3.1842913e+08 | BA579: 3.2212692e+08 | BB579: 3.2581141e+08 | BC579: 3.2947064e+08 | BD579: 3.3309457e+08 | BE579: 3.3667936e+08 | BF579: 3.4022067e+08 | BG579: 3.4371132e+08 | BH579: 3.4714316e+08 | BI579: 3.5050803e+08 | BJ579: 3.5380398e+08 | BK579: 3.5702812e+08 | BL579: 3.6017851e+08 | BM579: 3.6325656e+08 | BN579: 3.6626128e+08 | BO579: 3.6919168e+08 | BP579: 3.7204775e+08 | BQ579: 3.7483138e+08 | BR579: 3.7754541e+08 | BS579: 3.8019221e+08 | BT579: 3.8277178e+08 | BU579: 3.8528601e+08 | BV579: 3.8773679e+08 | BW579: 3.9012986e+08 | BX579: 3.9246761e+08 | BY579: 3.9475193e+08 | BZ579: 3.9697994e+08 | CA579: 3.9915019e+08 | CB579: 4.0125884e+08 | CC579: 4.0330299e+08 | CD579: 4.0527879e+08 | CE579: 4.0718672e+08 | CF579: 4.090234e+08 | CG579: 4.1078881e+08 | CH579: 4.1248104e+08 | CI579: 4.1409621e+08 | CJ579: 4.1563049e+08 | CK579: 4.1707906e+08 | CL579: 4.1843614e+08 | CM579: 4.1969357e+08
... A593: Oceania.population_scenario | B593: 0 | C593: 0 | D593: 0 | E593: 0 | F593: 0 | G593: 0 | H593: 0 | I593: 0 | J593: 0 | K593: 0 | L593: 0 | M593: 0 | N593: 0 | O593: 0 | P593: 0 | Q593: 0 | R593: 0 | S593: 0 | T593: 0 | U593: 0 | V593: 0 | W593: 0 | X593: 0 | Y593: 0 | Z593: 0 | AA593: 0 | AB593: 0 | AC593: 0 | AD593: 0 | AE593: 0 | AF593: 25121192 | AG593: 25654416 | AH593: 26181708 | AI593: 26704196 | AJ593: 27222787 | AK593: 27737306 | AL593: 28247377 | AM593: 28754294 | AN593: 29259837 | AO593: 29765304 | AP593: 30271249 | AQ593: 30777562 | AR593: 31284239 | AS593: 31791118 | AT593: 32297932 | AU593: 32804568 | AV593: 33311172 | AW593: 33817947 | AX593: 34325098 | AY593: 34832569 | AZ593: 35340356 | BA593: 35847764 | BB593: 36353825 | BC593: 36857185 | BD593: 37356692 | BE593: 37851881 | BF593: 38342231 | BG593: 38826892 | BH593: 39304902 | BI593: 39775289 | BJ593: 40237784 | BK593: 40692005 | BL593: 41137683 | BM593: 41574930 | BN593: 42003587 | BO593: 42423497 | BP593: 42834612 | BQ593: 43237108 | BR593: 43631276 | BS593: 44017353 | BT593: 44395304 | BU593: 44765318 | BV593: 45127584 | BW593: 45482744 | BX593: 45831053 | BY593: 46172711 | BZ593: 46507360 | CA593: 46834811 | CB593: 47154589 | CC593: 47466334 | CD593: 47769568 | CE593: 48064323 | CF593: 48350177 | CG593: 48627104 | CH593: 48894853 | CI593: 49152942 | CJ593: 49400889 | CK593: 49638096 | CL593: 49863848 | CM593: 50077141
A595: USA.commodity area crop harvested data | B595: 0 | C595: 0 | D595: 0 | E595: 0 | F595: 0 | G595: 0 | H595: 0 | I595: 0 | J595: 0 | K595: 0 | L595: 0 | M595: 0 | N595: 0 | O595: 0 | P595: 0 | Q595: 0 | R595: 0 | S595: 0 | T595: 0 | U595: 0 | V595: 0 | W595: 0 | X595: 0 | Y595: 0 | Z595: 0 | AA595: 0 | AB595: 0 | AC595: 0 | AD595: 0 | AE595: 0 | AF595: 28315.197 | AG595: 28952.722 | AH595: 29590.248 | AI595: 30227.773 | AJ595: 30865.298 | AK595: 31502.823 | AL595: 32140.348 | AM595: 32777.873 | AN595: 33415.399 | AO595: 34052.924 | AP595: 34690.449 | AQ595: 35327.974 | AR595: 35965.499 | AS595: 36603.024 | AT595: 37240.55 | AU595: 37878.075 | AV595: 38515.6 | AW595: 39153.125 | AX595: 39790.65 | AY595: 40428.175 | AZ595: 41065.701 | BA595: 41703.226 | BB595: 42340.751 | BC595: 42978.276 | BD595: 43615.801 | BE595: 44253.326 | BF595: 44890.852 | BG595: 45528.377 | BH595: 46165.902 | BI595: 46803.427 | BJ595: 47440.952 | BK595: 48078.477 | BL595: 48716.003 | BM595: 49353.528 | BN595: 49991.053 | BO595: 50628.578 | BP595: 51266.103 | BQ595: 51903.628 | BR595: 52541.154 | BS595: 53178.679 | BT595: 53816.204 | BU595: 54453.729 | BV595: 55091.254 | BW595: 55728.779 | BX595: 56366.305 | BY595: 57003.83 | BZ595: 57641.355 | CA595: 58278.88 | CB595: 58916.405 | CC595: 59553.93 | CD595: 60191.456 | CE595: 60828.981 | CF595: 61466.506 | CG595: 62104.031 | CH595: 62741.556 | CI595: 63379.081 | CJ595: 64016.607 | CK595: 64654.132 | CL595: 65291.657 | CM595: 65929.182 | CN595: 66566.707
A596: … | B596: 0 | C596: 0 | D596: 0 | E596: 0 | F596: 0 | G596: 0 | H596: 0 | I596: 0 | J596: 0 | K596: 0 | L596: 0 | M596: 0 | N596: 0 | O596: 0 | P596: 0 | Q596: 0 | R596: 0 | S596: 0 | T596: 0 | U596: 0 | V596: 0 | W596: 0 | X596: 0 | Y596: 0 | Z596: 0 | AA596: 0 | AB596: 0 | AC596: 0 | AD596: 0 | AE596: 0 | AF596: 25596.981 | AG596: 25278.412 | AH596: 24959.842 | AI596: 24641.272 | AJ596: 24322.703 | AK596: 24004.133 | AL596: 23685.563 | AM596: 23366.994 | AN596: 23048.424 | AO596: 22729.854 | AP596: 22411.285 | AQ596: 22092.715 | AR596: 21774.145 | AS596: 21455.576 | AT596: 21137.006 | AU596: 20818.436 | AV596: 20499.867 | AW596: 20181.297 | AX596: 19862.727 | AY596: 19544.158 | AZ596: 19225.588 | BA596: 18907.018 | BB596: 18588.449 | BC596: 18269.879 | BD596: 17951.309 | BE596: 17632.74 | BF596: 17314.17 | BG596: 16995.6 | BH596: 16677.031 | BI596: 16358.461 | BJ596: 16039.891 | BK596: 15721.322 | BL596: 15402.752 | BM596: 15084.182 | BN596: 14765.613 | BO596: 14447.043 | BP596: 14128.473 | BQ596: 13809.904 | BR596: 13491.334 | BS596: 13172.764 | BT596: 12854.195 | BU596: 12535.625 | BV596: 12217.055 | BW596: 11898.486 | BX596: 11579.916 | BY596: 11261.346 | BZ596: 10942.777 | CA596: 10624.207 | CB596: 10305.637 | CC596: 9987.0677 | CD596: 9668.498 | CE596: 9349.9283 | CF596: 9031.3587 | CG596: 8712.789 | CH596: 8394.2193 | CI596: 8075.6497 | CJ596: 7757.08 | CK596: 7438.5103 | CL596: 7119.9407 | CM596: 6801.371 | CN596: 6482.8013
A597: … | B597: 0 | C597: 0 | D597: 0 | E597: 0 | F597: 0 | G597: 0 | H597: 0 | I597: 0 | J597: 0 | K597: 0 | L597: 0 | M597: 0 | N597: 0 | O597: 0 | P597: 0 | Q597: 0 | R597: 0 | S597: 0 | T597: 0 | U597: 0 | V597: 0 | W597: 0 | X597: 0 | Y597: 0 | Z597: 0 | AA597: 0 | AB597: 0 | AC597: 0 | AD597: 0 | AE597: 0 | AF597: 1777.992 | AG597: 1741.2383 | AH597: 1704.4847 | AI597: 1667.731 | AJ597: 1630.9773 | AK597: 1594.2237 | AL597: 1557.47 | AM597: 1520.7163 | AN597: 1483.9627 | AO597: 1447.209 | AP597: 1410.4553 | AQ597: 1373.7017 | AR597: 1336.948 | AS597: 1300.1943 | AT597: 1263.4407 | AU597: 1226.687 | AV597: 1189.9333 | AW597: 1153.1797 | AX597: 1116.426 | AY597: 1079.6723 | AZ597: 1042.9187 | BA597: 1006.165 | BB597: 969.41133 | BC597: 932.65767 | BD597: 895.904 | BE597: 859.15033 | BF597: 822.39667 | BG597: 785.643 | BH597: 748.88933 | BI597: 712.13567 | BJ597: 675.382 | BK597: 638.62833 | BL597: 601.87467 | BM597: 565.121 | BN597: 528.36733 | BO597: 491.61367 | BP597: 454.86 | BQ597: 418.10633 | BR597: 381.35267 | BS597: 344.599 | BT597: 307.84533 | BU597: 271.09167 | BV597: 234.338 | BW597: 197.58433 | BX597: 160.83067 | BY597: 124.077 | BZ597: 87.323333 | CA597: 50.569667 | CB597: 13.816 | CC597: -22.937667 | CD597: -59.691333 | CE597: -96.445 | CF597: -133.19867 | CG597: -169.95233 | CH597: -206.706 | CI597: -243.45967 | CJ597: -280.21333 | CK597: -316.967 | CL597: -353.72067 | CM597: -390.47433 | CN597: -427.228
A598: … | B598: 0 | C598: 0 | D598: 0 | E598: 0 | F598: 0 | G598: 0 | H598: 0 | I598: 0 | J598: 0 | K598: 0 | L598: 0 | M598: 0 | N598: 0 | O598: 0 | P598: 0 | Q598: 0 | R598: 0 | S598: 0 | T598: 0 | U598: 0 | V598: 0 | W598: 0 | X598: 0 | Y598: 0 | Z598: 0 | AA598: 0 | AB598: 0 | AC598: 0 | AD598: 0 | AE598: 0 | AF598: 0 | AG598: 0 | AH598: 0 | AI598: 0 | AJ598: 0 | AK598: 0 | AL598: 0 | AM598: 0 | AN598: 0 | AO598: 0 | AP598: 0 | AQ598: 0 | AR598: 0 | AS598: 0 | AT598: 0 | AU598: 0 | AV598: 0 | AW598: 0 | AX598: 0 | AY598: 0 | AZ598: 0 | BA598: 0 | BB598: 0 | BC598: 0 | BD598: 0 | BE598: 0 | BF598: 0 | BG598: 0 | BH598: 0 | BI598: 0 | BJ598: 0 | BK598: 0 | BL598: 0 | BM598: 0 | BN598: 0 | BO598: 0 | BP598: 0 | BQ598: 0 | BR598: 0 | BS598: 0 | BT598: 0 | BU598: 0 | BV598: 0 | BW598: 0 | BX598: 0 | BY598: 0 | BZ598: 0 | CA598: 0 | CB598: 0 | CC598: 0 | CD598: 0 | CE598: 0 | CF598: 0 | CG598: 0 | CH598: 0 | CI598: 0 | CJ598: 0 | CK598: 0 | CL598: 0 | CM598: 0 | CN598: 0
A599: … | B599: 0 | C599: 0 | D599: 0 | E599: 0 | F599: 0 | G599: 0 | H599: 0 | I599: 0 | J599: 0 | K599: 0 | L599: 0 | M599: 0 | N599: 0 | O599: 0 | P599: 0 | Q599: 0 | R599: 0 | S599: 0 | T599: 0 | U599: 0 | V599: 0 | W599: 0 | X599: 0 | Y599: 0 | Z599: 0 | AA599: 0 | AB599: 0 | AC599: 0 | AD599: 0 | AE599: 0 | AF599: 41489.211 | AG599: 40724.86 | AH599: 39960.509 | AI599: 39196.159 | AJ599: 38431.808 | AK599: 37667.457 | AL599: 36903.107 | AM599: 36138.756 | AN599: 35374.405 | AO599: 34610.055 | AP599: 33845.704 | AQ599: 33081.353 | AR599: 32317.003 | AS599: 31552.652 | AT599: 30788.301 | AU599: 30023.951 | AV599: 29259.6 | AW599: 28495.249 | AX599: 27730.899 | AY599: 26966.548 | AZ599: 26202.197 | BA599: 25437.847 | BB599: 24673.496 | BC599: 23909.145 | BD599: 23144.795 | BE599: 22380.444 | BF599: 21616.093 | BG599: 20851.743 | BH599: 20087.392 | BI599: 19323.041 | BJ599: 18558.691 | BK599: 17794.34 | BL599: 17029.989 | BM599: 16265.639 | BN599: 15501.288 | BO599: 14736.937 | BP599: 13972.587 | BQ599: 13208.236 | BR599: 12443.885 | BS599: 11679.535 | BT599: 10915.184 | BU599: 10150.833 | BV599: 9386.4827 | BW599: 8622.132 | BX599: 7857.7813 | BY599: 7093.4307 | BZ599: 6329.08 | CA599: 5564.7293 | CB599: 4800.3787 | CC599: 4036.028 | CD599: 3271.6773 | CE599: 2507.3267 | CF599: 1742.976 | CG599: 978.62533 | CH599: 978.62533 | CI599: 1233.4089 | CJ599: 1063.5532 | CK599: 1091.8625 | CL599: 1129.6082 | CM599: 1095.0079 | CN599: 1105.4929
A600: … | B600: 0 | C600: 0 | D600: 0 | E600: 0 | F600: 0 | G600: 0 | H600: 0 | I600: 0 | J600: 0 | K600: 0 | L600: 0 | M600: 0 | N600: 0 | O600: 0 | P600: 0 | Q600: 0 | R600: 0 | S600: 0 | T600: 0 | U600: 0 | V600: 0 | W600: 0 | X600: 0 | Y600: 0 | Z600: 0 | AA600: 0 | AB600: 0 | AC600: 0 | AD600: 0 | AE600: 0 | AF600: 1281.7293 | AG600: 1256.4025 | AH600: 1231.0757 | AI600: 1205.7488 | AJ600: 1180.422 | AK600: 1155.0952 | AL600: 1129.7683 | AM600: 1104.4415 | AN600: 1079.1147 | AO600: 1053.7878 | AP600: 1028.461 | AQ600: 1003.1342 | AR600: 977.80733 | AS600: 952.4805 | AT600: 927.15367 | AU600: 901.82683 | AV600: 876.5 | AW600: 851.17317 | AX600: 825.84633 | AY600: 800.5195 | AZ600: 775.19267 | BA600: 749.86583 | BB600: 724.539 | BC600: 699.21217 | BD600: 673.88533 | BE600: 648.5585 | BF600: 623.23167 | BG600: 597.90483 | BH600: 572.578 | BI600: 547.25117 | BJ600: 521.92433 | BK600: 496.5975 | BL600: 471.27067 | BM600: 445.94383 | BN600: 420.617 | BO600: 395.29017 | BP600: 369.96333 | BQ600: 344.6365 | BR600: 319.30967 | BS600: 293.98283 | BT600: 268.656 | BU600: 243.32917 | BV600: 218.00233 | BW600: 192.6755 | BX600: 167.34867 | BY600: 142.02183 | BZ600: 116.695 | CA600: 91.368167 | CB600: 66.041333 | CC600: 40.7145 | CD600: 15.387667 | CE600: 78.70475 | CF600: 53.377917 | CG600: 50.212063 | CH600: 47.046208 | CI600: 49.420599 | CJ600: 57.335234 | CK600: 50.014197 | CL600: 51.003526 | CM600: 50.95406 | CN600: 51.943389
A602: USA.fiber area harvested data | B602: 0 | C602: 0 | D602: 0 | E602: 0 | F602: 0 | G602: 0 | H602: 0 | I602: 0 | J602: 0 | K602: 0 | L602: 0 | M602: 0 | N602: 0 | O602: 0 | P602: 0 | Q602: 0 | R602: 0 | S602: 0 | T602: 0 | U602: 0 | V602: 0 | W602: 0 | X602: 0 | Y602: 0 | Z602: 0 | AA602: 0 | AB602: 0 | AC602: 0 | AD602: 0 | AE602: 0 | AF602: 7245.7067 | AG602: 7079.8 | AH602: 6913.8933 | AI602: 6747.9867 | AJ602: 6582.08 | AK602: 6416.1733 | AL602: 6250.2667 | AM602: 6084.36 | AN602: 5918.4533 | AO602: 5752.5467 | AP602: 5586.64 | AQ602: 5420.7333 | AR602: 5254.8267 | AS602: 5088.92 | AT602: 4923.0133 | AU602: 4757.1067 | AV602: 4591.2 | AW602: 4425.2933 | AX602: 4259.3867 | AY602: 4093.48 | AZ602: 3927.5733 | BA602: 3761.6667 | BB602: 3595.76 | BC602: 3429.8533 | BD602: 3263.9467 | BE602: 3098.04 | BF602: 2932.1333 | BG602: 2766.2267 | BH602: 2600.32 | BI602: 2434.4133 | BJ602: 2268.5067 | BK602: 2102.6 | BL602: 1936.6933 | BM602: 1770.7867 | BN602: 1604.88 | BO602: 1438.9733 | BP602: 1273.0667 | BQ602: 1107.16 | BR602: 941.25333 | BS602: 775.34667 | BT602: 609.44 | BU602: 443.53333 | BV602: 277.62667 | BW602: 111.72 | BX602: 526.48667 | BY602: 360.58 | BZ602: 339.84167 | CA602: 319.10333 | CB602: 334.65708 | CC602: 386.50292 | CD602: 338.54552 | CE602: 345.02625 | CF602: 344.70221 | CG602: 351.18294 | CH602: 353.69423 | CI602: 344.86423 | CJ602: 348.65141 | CK602: 348.6109 | CL602: 349.5982 | CM602: 348.95519 | CN602: 347.93119
A604: USA.other area harvested data | B604: 0 | C604: 0 | D604: 0 | E604: 0 | F604: 0 | G604: 0 | H604: 0 | I604: 0 | J604: 0 | K604: 0 | L604: 0 | M604: 0 | N604: 0 | O604: 0 | P604: 0 | Q604: 0 | R604: 0 | S604: 0 | T604: 0 | U604: 0 | V604: 0 | W604: 0 | X604: 0 | Y604: 0 | Z604: 0 | AA604: 0 | AB604: 0 | AC604: 0 | AD604: 0 | AE604: 0 | AF604: 242.16311 | AG604: 242.04619 | AH604: 241.92927 | AI604: 241.81235 | AJ604: 241.69542 | AK604: 241.5785 | AL604: 241.46158 | AM604: 241.34466 | AN604: 241.22774 | AO604: 241.11081 | AP604: 240.99389 | AQ604: 240.87697 | AR604: 240.76005 | AS604: 240.64313 | AT604: 240.5262 | AU604: 240.40928 | AV604: 240.29236 | AW604: 240.17544 | AX604: 240.05852 | AY604: 239.94159 | AZ604: 239.82467 | BA604: 239.70775 | BB604: 239.59083 | BC604: 239.47391 | BD604: 239.35698 | BE604: 239.24006 | BF604: 239.12314 | BG604: 239.00622 | BH604: 238.8893 | BI604: 238.77237 | BJ604: 238.65545 | BK604: 238.53853 | BL604: 238.42161 | BM604: 238.30469 | BN604: 238.18776 | BO604: 238.07084 | BP604: 237.95392 | BQ604: 237.837 | BR604: 237.72008 | BS604: 237.60315 | BT604: 237.48623 | BU604: 237.36931 | BV604: 237.25239 | BW604: 237.13547 | BX604: 237.01854 | BY604: 236.90162 | BZ604: 236.7847 | CA604: 236.66778 | CB604: 236.55086 | CC604: 236.43393 | CD604: 236.31701 | CE604: 236.20009 | CF604: 236.08317 | CG604: 235.96625 | CH604: 235.84932 | CI604: 235.7324 | CJ604: 235.61548 | CK604: 235.49856 | CL604: 235.38164 | CM604: 235.26471 | CN604: 235.14779
A606: USA.VFN area harvested data | B606: 0 | C606: 0 | D606: 0 | E606: 0 | F606: 0 | G606: 0 | H606: 0 | I606: 0 | J606: 0 | K606: 0 | L606: 0 | M606: 0 | N606: 0 | O606: 0 | P606: 0 | Q606: 0 | R606: 0 | S606: 0 | T606: 0 | U606: 0 | V606: 0 | W606: 0 | X606: 0 | Y606: 0 | Z606: 0 | AA606: 0 | AB606: 0 | AC606: 0 | AD606: 0 | AE606: 0 | AF606: 3647.2467 | AG606: 3682.8167 | AH606: 3718.3867 | AI606: 3753.9567 | AJ606: 3789.5267 | AK606: 3825.0967 | AL606: 3860.6667 | AM606: 3896.2367 | AN606: 3931.8067 | AO606: 3967.3767 | AP606: 4002.9467 | AQ606: 4038.5167 | AR606: 4074.0867 | AS606: 4109.6567 | AT606: 4145.2267 | AU606: 4180.7967 | AV606: 4216.3667 | AW606: 4251.9367 | AX606: 4287.5067 | AY606: 4323.0767 | AZ606: 4358.6467 | BA606: 4394.2167 | BB606: 4429.7867 | BC606: 4465.3567 | BD606: 4500.9267 | BE606: 4536.4967 | BF606: 4572.0667 | BG606: 4607.6367 | BH606: 4643.2067 | BI606: 4678.7767 | BJ606: 4714.3467 | BK606: 4749.9167 | BL606: 4785.4867 | BM606: 4821.0567 | BN606: 4856.6267 | BO606: 4892.1967 | BP606: 4927.7667 | BQ606: 4963.3367 | BR606: 4998.9067 | BS606: 5034.4767 | BT606: 5070.0467 | BU606: 5105.6167 | BV606: 5141.1867 | BW606: 5176.7567 | BX606: 5212.3267 | BY606: 5247.8967 | BZ606: 5283.4667 | CA606: 5319.0367 | CB606: 5354.6067 | CC606: 5390.1767 | CD606: 5425.7467 | CE606: 5461.3167 | CF606: 5496.8867 | CG606: 5532.4567 | CH606: 5568.0267 | CI606: 5603.5967 | CJ606: 5639.1667 | CK606: 5674.7367 | CL606: 5710.3067 | CM606: 5745.8767 | CN606: 5781.4467
A608: USA.forage area harvested data | B608: 0 | C608: 0 | D608: 0 | E608: 0 | F608: 0 | G608: 0 | H608: 0 | I608: 0 | J608: 0 | K608: 0 | L608: 0 | M608: 0 | N608: 0 | O608: 0 | P608: 0 | Q608: 0 | R608: 0 | S608: 0 | T608: 0 | U608: 0 | V608: 0 | W608: 0 | X608: 0 | Y608: 0 | Z608: 0 | AA608: 0 | AB608: 0 | AC608: 0 | AD608: 0 | AE608: 0 | AF608: 28874.77 | AG608: 28860.829 | AH608: 28846.887 | AI608: 28832.946 | AJ608: 28819.005 | AK608: 28805.063 | AL608: 28791.122 | AM608: 28777.18 | AN608: 28763.239 | AO608: 28749.298 | AP608: 28735.356 | AQ608: 28721.415 | AR608: 28707.473 | AS608: 28693.532 | AT608: 28679.59 | AU608: 28665.649 | AV608: 28651.708 | AW608: 28637.766 | AX608: 28623.825 | AY608: 28609.883 | AZ608: 28595.942 | BA608: 28582.001 | BB608: 28568.059 | BC608: 28554.118 | BD608: 28540.176 | BE608: 28526.235 | BF608: 28512.294 | BG608: 28498.352 | BH608: 28484.411 | BI608: 28470.469 | BJ608: 28456.528 | BK608: 28442.586 | BL608: 28428.645 | BM608: 28414.704 | BN608: 28400.762 | BO608: 28386.821 | BP608: 28372.879 | BQ608: 28358.938 | BR608: 28344.997 | BS608: 28331.055 | BT608: 28317.114 | BU608: 28303.172 | BV608: 28289.231 | BW608: 28275.29 | BX608: 28261.348 | BY608: 28247.407 | BZ608: 28233.465 | CA608: 28219.524 | CB608: 28205.582 | CC608: 28191.641 | CD608: 28177.7 | CE608: 28163.758 | CF608: 28149.817 | CG608: 28135.875 | CH608: 28121.934 | CI608: 28107.993 | CJ608: 28094.051 | CK608: 28080.11 | CL608: 28066.168 | CM608: 28052.227 | CN608: 28038.286
