Workbook

Sheet LUC-2012-08-10-Run1
B1: 1961 | C1: 1962 | D1: 1963 | E1: 1964 | F1: 1965 | G1: 1966 | H1: 1967 | I1: 1968 | J1: 1969 | K1: 1970 | L1: 1971 | M1: 1972 | N1: 1973 | O1: 1974 | P1: 1975 | Q1: 1976 | R1: 1977 | S1: 1978 | T1: 1979 | U1: 1980 | V1: 1981 | W1: 1982 | X1: 1983 | Y1: 1984 | Z1: 1985 | AA1: 1986 | AB1: 1987 | AC1: 1988 | AD1: 1989 | AE1: 1990 | AF1: 1991 | AG1: 1992 | AH1: 1993 | AI1: 1994 | AJ1: 1995 | AK1: 1996 | AL1: 1997 | AM1: 1998 | AN1: 1999 | AO1: 2000 | AP1: 2001 | AQ1: 2002 | AR1: 2003 | AS1: 2004 | AT1: 2005 | AU1: 2006 | AV1: 2007 | AW1: 2008 | AX1: 2009 | AY1: 2010 | AZ1: 2011 | BA1: 2012 | BB1: 2013 | BC1: 2014 | BD1: 2015 | BE1: 2016 | BF1: 2017 | BG1: 2018 | BH1: 2019 | BI1: 2020 | BJ1: 2021 | BK1: 2022 | BL1: 2023 | BM1: 2024 | BN1: 2025 | BO1: 2026 | BP1: 2027 | BQ1: 2028 | BR1: 2029 | BS1: 2030 | BT1: 2031 | BU1: 2032 | BV1: 2033 | BW1: 2034 | BX1: 2035 | BY1: 2036 | BZ1: 2037 | CA1: 2038 | CB1: 2039 | CC1: 2040 | CD1: 2041 | CE1: 2042 | CF1: 2043 | CG1: 2044 | CH1: 2045 | CI1: 2046 | CJ1: 2047 | CK1: 2048 | CL1: 2049 | CM1: 2050
A2: ROW.per_capita_animal_product_demand_scenario | B2: 0 | C2: 0 | D2: 0 | E2: 0 | F2: 0 | G2: 0 | H2: 0 | I2: 0 | J2: 0 | K2: 0 | L2: 0 | M2: 0 | N2: 0 | O2: 0 | P2: 0 | Q2: 0 | R2: 0 | S2: 0 | T2: 0 | U2: 0 | V2: 0 | W2: 0 | X2: 0 | Y2: 0 | Z2: 0 | AA2: 0 | AB2: 0 | AC2: 0 | AD2: 0 | AE2: 0 | AF2: 1.0508416e-05 | AG2: 1.0527619e-05 | AH2: 1.0524145e-05 | AI2: 1.0522463e-05 | AJ2: 1.0522681e-05 | AK2: 1.0524798e-05 | AL2: 1.0528849e-05 | AM2: 1.0535258e-05 | AN2: 1.0544408e-05 | AO2: 1.0556611e-05 | AP2: 1.0571845e-05 | AQ2: 1.058998e-05 | AR2: 1.0610719e-05 | AS2: 1.0633798e-05 | AT2: 1.0658935e-05 | AU2: 1.0686103e-05 | AV2: 1.0706788e-05 | AW2: 1.0728456e-05 | AX2: 1.0751066e-05 | AY2: 1.0774564e-05 | AZ2: 1.079896e-05 | BA2: 1.0824296e-05 | BB2: 1.0850593e-05 | BC2: 1.0877941e-05 | BD2: 1.0906366e-05 | BE2: 1.0935893e-05 | BF2: 1.0966503e-05 | BG2: 1.0998166e-05 | BH2: 1.1030891e-05 | BI2: 1.1064614e-05 | BJ2: 1.1099353e-05 | BK2: 1.1135071e-05 | BL2: 1.1171769e-05 | BM2: 1.1209436e-05 | BN2: 1.1248082e-05 | BO2: 1.1287651e-05 | BP2: 1.1328155e-05 | BQ2: 1.1369577e-05 | BR2: 1.141197e-05 | BS2: 1.1455315e-05 | BT2: 1.1499618e-05 | BU2: 1.1544883e-05 | BV2: 1.1591015e-05 | BW2: 1.1637937e-05 | BX2: 1.1685595e-05 | BY2: 1.1733977e-05 | BZ2: 1.1783073e-05 | CA2: 1.1832927e-05 | CB2: 1.1883595e-05 | CC2: 1.1935118e-05 | CD2: 1.1987489e-05 | CE2: 1.2040728e-05 | CF2: 1.2094807e-05 | CG2: 1.2149717e-05 | CH2: 1.2205477e-05 | CI2: 1.2262068e-05 | CJ2: 1.2319521e-05 | CK2: 1.2377868e-05 | CL2: 1.2437151e-05 | CM2: 1.2497423e-05
A3: … | B3: 0 | C3: 0 | D3: 0 | E3: 0 | F3: 0 | G3: 0 | H3: 0 | I3: 0 | J3: 0 | K3: 0 | L3: 0 | M3: 0 | N3: 0 | O3: 0 | P3: 0 | Q3: 0 | R3: 0 | S3: 0 | T3: 0 | U3: 0 | V3: 0 | W3: 0 | X3: 0 | Y3: 0 | Z3: 0 | AA3: 0 | AB3: 0 | AC3: 0 | AD3: 0 | AE3: 0 | AF3: 7.000043e-05 | AG3: 7.0630961e-05 | AH3: 7.1066274e-05 | AI3: 7.150778e-05 | AJ3: 7.1952945e-05 | AK3: 7.2400862e-05 | AL3: 7.2852846e-05 | AM3: 7.3313274e-05 | AN3: 7.3787111e-05 | AO3: 7.4277958e-05 | AP3: 7.4785862e-05 | AQ3: 7.5308758e-05 | AR3: 7.584261e-05 | AS3: 7.638308e-05 | AT3: 7.6926134e-05 | AU3: 7.747081e-05 | AV3: 7.7835708e-05 | AW3: 7.8201471e-05 | AX3: 7.8567369e-05 | AY3: 7.8932911e-05 | AZ3: 7.9297852e-05 | BA3: 7.9662258e-05 | BB3: 8.0026719e-05 | BC3: 8.0392479e-05 | BD3: 8.0760241e-05 | BE3: 8.1130207e-05 | BF3: 8.150222e-05 | BG3: 8.1876587e-05 | BH3: 8.2253774e-05 | BI3: 8.2633806e-05 | BJ3: 8.3016912e-05 | BK3: 8.3402934e-05 | BL3: 8.3791548e-05 | BM3: 8.4182323e-05 | BN3: 8.457512e-05 | BO3: 8.4969478e-05 | BP3: 8.5365604e-05 | BQ3: 8.5763088e-05 | BR3: 8.6162015e-05 | BS3: 8.6562047e-05 | BT3: 8.6909832e-05 | BU3: 8.7260258e-05 | BV3: 8.761298e-05 | BW3: 8.796821e-05 | BX3: 8.8325924e-05 | BY3: 8.8686259e-05 | BZ3: 8.9048882e-05 | CA3: 8.9414054e-05 | CB3: 8.9781752e-05 | CC3: 9.0152e-05 | CD3: 9.0524661e-05 | CE3: 9.0899781e-05 | CF3: 9.1277331e-05 | CG3: 9.1657233e-05 | CH3: 9.2039603e-05 | CI3: 9.2424321e-05 | CJ3: 9.2811363e-05 | CK3: 9.3200498e-05 | CL3: 9.359191e-05 | CM3: 9.3985309e-05
A4: ... | B4: 0 | C4: 0 | D4: 0 | E4: 0 | F4: 0 | G4: 0 | H4: 0 | I4: 0 | J4: 0 | K4: 0 | L4: 0 | M4: 0 | N4: 0 | O4: 0 | P4: 0 | Q4: 0 | R4: 0 | S4: 0 | T4: 0 | U4: 0 | V4: 0 | W4: 0 | X4: 0 | Y4: 0 | Z4: 0 | AA4: 0 | AB4: 0 | AC4: 0 | AD4: 0 | AE4: 0 | AF4: 1.3228987e-05 | AG4: 1.3351004e-05 | AH4: 1.3448211e-05 | AI4: 1.3548882e-05 | AJ4: 1.365327e-05 | AK4: 1.3761501e-05 | AL4: 1.3873701e-05 | AM4: 1.3990475e-05 | AN4: 1.4112379e-05 | AO4: 1.4239928e-05 | AP4: 1.4373259e-05 | AQ4: 1.4512397e-05 | AR4: 1.4657165e-05 | AS4: 1.4807427e-05 | AT4: 1.4962997e-05 | AU4: 1.512402e-05 | AV4: 1.5129679e-05 | AW4: 1.5136668e-05 | AX4: 1.5144948e-05 | AY4: 1.5154462e-05 | AZ4: 1.5165243e-05 | BA4: 1.5177363e-05 | BB4: 1.5190865e-05 | BC4: 1.5205886e-05 | BD4: 1.5222476e-05 | BE4: 1.524069e-05 | BF4: 1.5260525e-05 | BG4: 1.528197e-05 | BH4: 1.5305073e-05 | BI4: 1.532978e-05 | BJ4: 1.5356154e-05 | BK4: 1.5384179e-05 | BL4: 1.541389e-05 | BM4: 1.5445307e-05 | BN4: 1.5478483e-05 | BO4: 1.5513378e-05 | BP4: 1.5550048e-05 | BQ4: 1.55885e-05 | BR4: 1.562883e-05 | BS4: 1.5671044e-05 | BT4: 1.5715176e-05 | BU4: 1.5761274e-05 | BV4: 1.5809239e-05 | BW4: 1.5859003e-05 | BX4: 1.5910525e-05 | BY4: 1.5963826e-05 | BZ4: 1.6018932e-05 | CA4: 1.6075946e-05 | CB4: 1.6134996e-05 | CC4: 1.6196177e-05 | CD4: 1.6259531e-05 | CE4: 1.6325138e-05 | CF4: 1.6393003e-05 | CG4: 1.6463171e-05 | CH4: 1.6535713e-05 | CI4: 1.6610676e-05 | CJ4: 1.6688154e-05 | CK4: 1.6768272e-05 | CL4: 1.6851146e-05 | CM4: 1.6936941e-05
A5: ... | B5: 0 | C5: 0 | D5: 0 | E5: 0 | F5: 0 | G5: 0 | H5: 0 | I5: 0 | J5: 0 | K5: 0 | L5: 0 | M5: 0 | N5: 0 | O5: 0 | P5: 0 | Q5: 0 | R5: 0 | S5: 0 | T5: 0 | U5: 0 | V5: 0 | W5: 0 | X5: 0 | Y5: 0 | Z5: 0 | AA5: 0 | AB5: 0 | AC5: 0 | AD5: 0 | AE5: 0 | AF5: 7.0121002e-06 | AG5: 7.2210894e-06 | AH5: 7.4202146e-06 | AI5: 7.6288203e-06 | AJ5: 7.8474397e-06 | AK5: 8.0765895e-06 | AL5: 8.3168765e-06 | AM5: 8.5692634e-06 | AN5: 8.8347261e-06 | AO5: 9.1142143e-06 | AP5: 9.4084017e-06 | AQ5: 9.7178946e-06 | AR5: 1.0043174e-05 | AS5: 1.0384788e-05 | AT5: 1.0743309e-05 | AU5: 1.1119589e-05 | AV5: 1.1213797e-05 | AW5: 1.1310063e-05 | AX5: 1.1408395e-05 | AY5: 1.1508781e-05 | AZ5: 1.161128e-05 | BA5: 1.1715979e-05 | BB5: 1.1822948e-05 | BC5: 1.1932326e-05 | BD5: 1.2044192e-05 | BE5: 1.2158625e-05 | BF5: 1.2275664e-05 | BG5: 1.2395333e-05 | BH5: 1.2517707e-05 | BI5: 1.2642778e-05 | BJ5: 1.2770631e-05 | BK5: 1.2901294e-05 | BL5: 1.3034831e-05 | BM5: 1.31713e-05 | BN5: 1.3310783e-05 | BO5: 1.3453288e-05 | BP5: 1.3598903e-05 | BQ5: 1.374768e-05 | BR5: 1.3899751e-05 | BS5: 1.405517e-05 | BT5: 1.4214019e-05 | BU5: 1.4376384e-05 | BV5: 1.4542238e-05 | BW5: 1.4711574e-05 | BX5: 1.488441e-05 | BY5: 1.5060818e-05 | BZ5: 1.5240875e-05 | CA5: 1.5424723e-05 | CB5: 1.5612527e-05 | CC5: 1.5804431e-05 | CD5: 1.6000528e-05 | CE5: 1.6200948e-05 | CF5: 1.6405763e-05 | CG5: 1.6615072e-05 | CH5: 1.6829008e-05 | CI5: 1.704767e-05 | CJ5: 1.7271214e-05 | CK5: 1.749981e-05 | CL5: 1.7733636e-05 | CM5: 1.7972898e-05
A7: ROW.per_capita_commodity_crop_demand_scenario | B7: 0 | C7: 0 | D7: 0 | E7: 0 | F7: 0 | G7: 0 | H7: 0 | I7: 0 | J7: 0 | K7: 0 | L7: 0 | M7: 0 | N7: 0 | O7: 0 | P7: 0 | Q7: 0 | R7: 0 | S7: 0 | T7: 0 | U7: 0 | V7: 0 | W7: 0 | X7: 0 | Y7: 0 | Z7: 0 | AA7: 0 | AB7: 0 | AC7: 0 | AD7: 0 | AE7: 0 | AF7: 3.6843337e-05 | AG7: 3.6790336e-05 | AH7: 3.6735361e-05 | AI7: 3.6679542e-05 | AJ7: 3.6623172e-05 | AK7: 3.6566333e-05 | AL7: 3.6509049e-05 | AM7: 3.6451466e-05 | AN7: 3.6393772e-05 | AO7: 3.6336058e-05 | AP7: 3.6278481e-05 | AQ7: 3.6221086e-05 | AR7: 3.6163908e-05 | AS7: 3.6106967e-05 | AT7: 3.6050252e-05 | AU7: 3.5993816e-05 | AV7: 3.6240761e-05 | AW7: 3.6488319e-05 | AX7: 3.6736402e-05 | AY7: 3.6984942e-05 | AZ7: 3.7233916e-05 | BA7: 3.7483341e-05 | BB7: 3.7733265e-05 | BC7: 3.7983772e-05 | BD7: 3.8234915e-05 | BE7: 3.8486709e-05 | BF7: 3.8739113e-05 | BG7: 3.8992096e-05 | BH7: 3.9245624e-05 | BI7: 3.9499679e-05 | BJ7: 3.975424e-05 | BK7: 4.0009324e-05 | BL7: 4.0264903e-05 | BM7: 4.052098e-05 | BN7: 4.0777533e-05 | BO7: 4.103456e-05 | BP7: 4.1292071e-05 | BQ7: 4.1550085e-05 | BR7: 4.1808652e-05 | BS7: 4.2067778e-05 | BT7: 4.2057327e-05 | BU7: 4.204757e-05 | BV7: 4.2038516e-05 | BW7: 4.2030165e-05 | BX7: 4.2022518e-05 | BY7: 4.2015579e-05 | BZ7: 4.200935e-05 | CA7: 4.2003839e-05 | CB7: 4.1999036e-05 | CC7: 4.1994954e-05 | CD7: 4.1991584e-05 | CE7: 4.1988923e-05 | CF7: 4.1986974e-05 | CG7: 4.1985725e-05 | CH7: 4.1985181e-05 | CI7: 4.1985334e-05 | CJ7: 4.198618e-05 | CK7: 4.1987716e-05 | CL7: 4.1989957e-05 | CM7: 4.1992888e-05
A8: … | B8: 0 | C8: 0 | D8: 0 | E8: 0 | F8: 0 | G8: 0 | H8: 0 | I8: 0 | J8: 0 | K8: 0 | L8: 0 | M8: 0 | N8: 0 | O8: 0 | P8: 0 | Q8: 0 | R8: 0 | S8: 0 | T8: 0 | U8: 0 | V8: 0 | W8: 0 | X8: 0 | Y8: 0 | Z8: 0 | AA8: 0 | AB8: 0 | AC8: 0 | AD8: 0 | AE8: 0 | AF8: 5.2769166e-05 | AG8: 5.2693256e-05 | AH8: 5.2614517e-05 | AI8: 5.253457e-05 | AJ8: 5.2453834e-05 | AK8: 5.2372426e-05 | AL8: 5.229038e-05 | AM8: 5.2207906e-05 | AN8: 5.2125274e-05 | AO8: 5.2042613e-05 | AP8: 5.1960147e-05 | AQ8: 5.1877943e-05 | AR8: 5.1796049e-05 | AS8: 5.1714495e-05 | AT8: 5.1633265e-05 | AU8: 5.1552433e-05 | AV8: 5.1426673e-05 | AW8: 5.130194e-05 | AX8: 5.1178111e-05 | AY8: 5.1055095e-05 | AZ8: 5.0932864e-05 | BA8: 5.0811445e-05 | BB8: 5.069091e-05 | BC8: 5.0571373e-05 | BD8: 5.0452905e-05 | BE8: 5.0335522e-05 | BF8: 5.0219168e-05 | BG8: 5.0103801e-05 | BH8: 4.9989378e-05 | BI8: 4.9875874e-05 | BJ8: 4.9763265e-05 | BK8: 4.9651571e-05 | BL8: 4.9540761e-05 | BM8: 4.9430839e-05 | BN8: 4.9321783e-05 | BO8: 4.9213588e-05 | BP8: 4.9106274e-05 | BQ8: 4.8999864e-05 | BR8: 4.8894421e-05 | BS8: 4.8789948e-05 | BT8: 4.8777827e-05 | BU8: 4.8766511e-05 | BV8: 4.8756011e-05 | BW8: 4.8746326e-05 | BX8: 4.8737456e-05 | BY8: 4.8729408e-05 | BZ8: 4.8722184e-05 | CA8: 4.8715793e-05 | CB8: 4.8710222e-05 | CC8: 4.8705488e-05 | CD8: 4.8701579e-05 | CE8: 4.8698493e-05 | CF8: 4.8696233e-05 | CG8: 4.8694784e-05 | CH8: 4.8694153e-05 | CI8: 4.8694331e-05 | CJ8: 4.8695312e-05 | CK8: 4.8697093e-05 | CL8: 4.8699693e-05 | CM8: 4.8703092e-05
A9: … | B9: 0 | C9: 0 | D9: 0 | E9: 0 | F9: 0 | G9: 0 | H9: 0 | I9: 0 | J9: 0 | K9: 0 | L9: 0 | M9: 0 | N9: 0 | O9: 0 | P9: 0 | Q9: 0 | R9: 0 | S9: 0 | T9: 0 | U9: 0 | V9: 0 | W9: 0 | X9: 0 | Y9: 0 | Z9: 0 | AA9: 0 | AB9: 0 | AC9: 0 | AD9: 0 | AE9: 0 | AF9: 3.7556434e-05 | AG9: 3.7502407e-05 | AH9: 3.7446368e-05 | AI9: 3.7389469e-05 | AJ9: 3.7332008e-05 | AK9: 3.7274069e-05 | AL9: 3.7215676e-05 | AM9: 3.7156978e-05 | AN9: 3.7098168e-05 | AO9: 3.7039337e-05 | AP9: 3.6980645e-05 | AQ9: 3.6922139e-05 | AR9: 3.6863855e-05 | AS9: 3.6805812e-05 | AT9: 3.6747999e-05 | AU9: 3.669047e-05 | AV9: 3.6554387e-05 | AW9: 3.641905e-05 | AX9: 3.628437e-05 | AY9: 3.6150285e-05 | AZ9: 3.6016773e-05 | BA9: 3.5883857e-05 | BB9: 3.5751585e-05 | BC9: 3.562004e-05 | BD9: 3.5489271e-05 | BE9: 3.5359289e-05 | BF9: 3.5230055e-05 | BG9: 3.5101538e-05 | BH9: 3.4973709e-05 | BI9: 3.484655e-05 | BJ9: 3.4720044e-05 | BK9: 3.4594207e-05 | BL9: 3.4469014e-05 | BM9: 3.4344472e-05 | BN9: 3.4220562e-05 | BO9: 3.4097284e-05 | BP9: 3.3974651e-05 | BQ9: 3.385268e-05 | BR9: 3.3731412e-05 | BS9: 3.3610853e-05 | BT9: 3.3602503e-05 | BU9: 3.3594708e-05 | BV9: 3.3587474e-05 | BW9: 3.3580802e-05 | BX9: 3.3574692e-05 | BY9: 3.3569148e-05 | BZ9: 3.3564171e-05 | CA9: 3.3559769e-05 | CB9: 3.3555931e-05 | CC9: 3.355267e-05 | CD9: 3.3549977e-05 | CE9: 3.3547851e-05 | CF9: 3.3546294e-05 | CG9: 3.3545296e-05 | CH9: 3.3544861e-05 | CI9: 3.3544983e-05 | CJ9: 3.3545659e-05 | CK9: 3.3546886e-05 | CL9: 3.3548677e-05 | CM9: 3.3551019e-05
A10: … | B10: 0 | C10: 0 | D10: 0 | E10: 0 | F10: 0 | G10: 0 | H10: 0 | I10: 0 | J10: 0 | K10: 0 | L10: 0 | M10: 0 | N10: 0 | O10: 0 | P10: 0 | Q10: 0 | R10: 0 | S10: 0 | T10: 0 | U10: 0 | V10: 0 | W10: 0 | X10: 0 | Y10: 0 | Z10: 0 | AA10: 0 | AB10: 0 | AC10: 0 | AD10: 0 | AE10: 0 | AF10: 3.2802455e-05 | AG10: 3.2755267e-05 | AH10: 3.2706321e-05 | AI10: 3.2656625e-05 | AJ10: 3.2606437e-05 | AK10: 3.2555832e-05 | AL10: 3.2504831e-05 | AM10: 3.2453563e-05 | AN10: 3.2402197e-05 | AO10: 3.2350813e-05 | AP10: 3.2299551e-05 | AQ10: 3.2248451e-05 | AR10: 3.2197544e-05 | AS10: 3.2146848e-05 | AT10: 3.2096354e-05 | AU10: 3.2046107e-05 | AV10: 3.2141497e-05 | AW10: 3.2237472e-05 | AX10: 3.2333953e-05 | AY10: 3.2430883e-05 | AZ10: 3.2528241e-05 | BA10: 3.2626044e-05 | BB10: 3.2724335e-05 | BC10: 3.2823187e-05 | BD10: 3.2922647e-05 | BE10: 3.3022726e-05 | BF10: 3.3123389e-05 | BG10: 3.3224607e-05 | BH10: 3.3326354e-05 | BI10: 3.3428612e-05 | BJ10: 3.3531365e-05 | BK10: 3.3634627e-05 | BL10: 3.3738375e-05 | BM10: 3.3842612e-05 | BN10: 3.394732e-05 | BO10: 3.4052497e-05 | BP10: 3.4158155e-05 | BQ10: 3.4264307e-05 | BR10: 3.4370998e-05 | BS10: 3.447823e-05 | BT10: 3.4469665e-05 | BU10: 3.4461668e-05 | BV10: 3.4454248e-05 | BW10: 3.4447403e-05 | BX10: 3.4441136e-05 | BY10: 3.4435448e-05 | BZ10: 3.4430343e-05 | CA10: 3.4425827e-05 | CB10: 3.442189e-05 | CC10: 3.4418545e-05 | CD10: 3.4415782e-05 | CE10: 3.4413602e-05 | CF10: 3.4412005e-05 | CG10: 3.4410981e-05 | CH10: 3.4410535e-05 | CI10: 3.441066e-05 | CJ10: 3.4411354e-05 | CK10: 3.4412612e-05 | CL10: 3.441445e-05 | CM10: 3.4416852e-05
A11: … | B11: 0 | C11: 0 | D11: 0 | E11: 0 | F11: 0 | G11: 0 | H11: 0 | I11: 0 | J11: 0 | K11: 0 | L11: 0 | M11: 0 | N11: 0 | O11: 0 | P11: 0 | Q11: 0 | R11: 0 | S11: 0 | T11: 0 | U11: 0 | V11: 0 | W11: 0 | X11: 0 | Y11: 0 | Z11: 0 | AA11: 0 | AB11: 0 | AC11: 0 | AD11: 0 | AE11: 0 | AF11: 9.8542367e-06 | AG11: 9.9823314e-06 | AH11: 1.0100377e-05 | AI11: 1.0217954e-05 | AJ11: 1.0335036e-05 | AK11: 1.045161e-05 | AL11: 1.0567721e-05 | AM11: 1.0683585e-05 | AN11: 1.0799445e-05 | AO11: 1.0915504e-05 | AP11: 1.1031807e-05 | AQ11: 1.114831e-05 | AR11: 1.126487e-05 | AS11: 1.1381328e-05 | AT11: 1.1497512e-05 | AU11: 1.1613397e-05 | AV11: 1.1713799e-05 | AW11: 1.181447e-05 | AX11: 1.1915346e-05 | AY11: 1.2016381e-05 | AZ11: 1.2117558e-05 | BA11: 1.2218891e-05 | BB11: 1.2320406e-05 | BC11: 1.2422163e-05 | BD11: 1.2524187e-05 | BE11: 1.2626484e-05 | BF11: 1.2729031e-05 | BG11: 1.2831825e-05 | BH11: 1.2934868e-05 | BI11: 1.3038142e-05 | BJ11: 1.3141646e-05 | BK11: 1.3245362e-05 | BL11: 1.3349273e-05 | BM11: 1.3453362e-05 | BN11: 1.3557618e-05 | BO11: 1.3662013e-05 | BP11: 1.3766548e-05 | BQ11: 1.3871201e-05 | BR11: 1.3975979e-05 | BS11: 1.4080865e-05 | BT11: 1.4176706e-05 | BU11: 1.4272898e-05 | BV11: 1.4369405e-05 | BW11: 1.4466221e-05 | BX11: 1.4563333e-05 | BY11: 1.4660743e-05 | BZ11: 1.475844e-05 | CA11: 1.4856433e-05 | CB11: 1.4954724e-05 | CC11: 1.5053311e-05 | CD11: 1.5152187e-05 | CE11: 1.5251348e-05 | CF11: 1.5350789e-05 | CG11: 1.5450503e-05 | CH11: 1.5550494e-05 | CI11: 1.5650749e-05 | CJ11: 1.5751267e-05 | CK11: 1.5852033e-05 | CL11: 1.5953047e-05 | CM11: 1.605429e-05
A12: … | B12: 0 | C12: 0 | D12: 0 | E12: 0 | F12: 0 | G12: 0 | H12: 0 | I12: 0 | J12: 0 | K12: 0 | L12: 0 | M12: 0 | N12: 0 | O12: 0 | P12: 0 | Q12: 0 | R12: 0 | S12: 0 | T12: 0 | U12: 0 | V12: 0 | W12: 0 | X12: 0 | Y12: 0 | Z12: 0 | AA12: 0 | AB12: 0 | AC12: 0 | AD12: 0 | AE12: 0 | AF12: 2.1546611e-05 | AG12: 2.1548776e-05 | AH12: 2.1529814e-05 | AI12: 2.1511796e-05 | AJ12: 2.1494295e-05 | AK12: 2.1477259e-05 | AL12: 2.1460781e-05 | AM12: 2.1445238e-05 | AN12: 2.1430974e-05 | AO12: 2.1418246e-05 | AP12: 2.1406989e-05 | AQ12: 2.1396971e-05 | AR12: 2.1387819e-05 | AS12: 2.1379161e-05 | AT12: 2.1370586e-05 | AU12: 2.136208e-05 | AV12: 2.143122e-05 | AW12: 2.1500622e-05 | AX12: 2.1570179e-05 | AY12: 2.1639822e-05 | AZ12: 2.1709568e-05 | BA12: 2.1779463e-05 | BB12: 2.1849627e-05 | BC12: 2.1920278e-05 | BD12: 2.1991551e-05 | BE12: 2.2063476e-05 | BF12: 2.2136023e-05 | BG12: 2.2209233e-05 | BH12: 2.2283197e-05 | BI12: 2.2357891e-05 | BJ12: 2.2433347e-05 | BK12: 2.2509532e-05 | BL12: 2.258636e-05 | BM12: 2.266374e-05 | BN12: 2.2741629e-05 | BO12: 2.2819946e-05 | BP12: 2.2898701e-05 | BQ12: 2.2977839e-05 | BR12: 2.3057374e-05 | BS12: 2.3137229e-05 | BT12: 2.3220885e-05 | BU12: 2.3304857e-05 | BV12: 2.3389124e-05 | BW12: 2.3473653e-05 | BX12: 2.3558451e-05 | BY12: 2.3643525e-05 | BZ12: 2.372884e-05 | CA12: 2.3814449e-05 | CB12: 2.3900369e-05 | CC12: 2.3986619e-05 | CD12: 2.4073167e-05 | CE12: 2.4160049e-05 | CF12: 2.4247234e-05 | CG12: 2.433471e-05 | CH12: 2.4422475e-05 | CI12: 2.4510534e-05 | CJ12: 2.4598869e-05 | CK12: 2.4687475e-05 | CL12: 2.477636e-05 | CM12: 2.4865496e-05
A14: ROW.Per_capita_VFN_demand_Scenario | B14: 0 | C14: 0 | D14: 0 | E14: 0 | F14: 0 | G14: 0 | H14: 0 | I14: 0 | J14: 0 | K14: 0 | L14: 0 | M14: 0 | N14: 0 | O14: 0 | P14: 0 | Q14: 0 | R14: 0 | S14: 0 | T14: 0 | U14: 0 | V14: 0 | W14: 0 | X14: 0 | Y14: 0 | Z14: 0 | AA14: 0 | AB14: 0 | AC14: 0 | AD14: 0 | AE14: 0 | AF14: 7.2579401e-05 | AG14: 7.271075e-05 | AH14: 7.2835631e-05 | AI14: 7.2966845e-05 | AJ14: 7.310436e-05 | AK14: 7.3248247e-05 | AL14: 7.3398755e-05 | AM14: 7.3555626e-05 | AN14: 7.371863e-05 | AO14: 7.388793e-05 | AP14: 7.4063048e-05 | AQ14: 7.4244147e-05 | AR14: 7.4431632e-05 | AS14: 7.4625872e-05 | AT14: 7.4827372e-05 | AU14: 7.5036048e-05 | AV14: 7.519613e-05 | AW14: 7.5362227e-05 | AX14: 7.5533423e-05 | AY14: 7.5709183e-05 | AZ14: 7.5889042e-05 | BA14: 7.6072967e-05 | BB14: 7.626069e-05 | BC14: 7.6451712e-05 | BD14: 7.6645709e-05 | BE14: 7.6842654e-05 | BF14: 7.7042342e-05 | BG14: 7.7245071e-05 | BH14: 7.7450697e-05 | BI14: 7.7659336e-05 | BJ14: 7.7871119e-05 | BK14: 7.8085963e-05 | BL14: 7.8304194e-05 | BM14: 7.85262e-05 | BN14: 7.8752113e-05 | BO14: 7.898214e-05 | BP14: 7.9215968e-05 | BQ14: 7.9453663e-05 | BR14: 7.9694686e-05 | BS14: 8.093914e-05 | BT14: 8.1144581e-05 | BU14: 8.1352255e-05 | BV14: 8.156159e-05 | BW14: 8.1772239e-05 | BX14: 8.1983733e-05 | BY14: 8.2195785e-05 | BZ14: 8.240854e-05 | CA14: 8.262177e-05 | CB14: 8.2835636e-05 | CC14: 8.3049975e-05 | CD14: 8.3264965e-05 | CE14: 8.3480476e-05 | CF14: 8.3696427e-05 | CG14: 8.3912862e-05 | CH14: 8.4129688e-05 | CI14: 8.434705e-05 | CJ14: 8.4565e-05 | CK14: 8.4783853e-05 | CL14: 8.5003601e-05 | CM14: 8.5224739e-05
A16: USA.per_capita_animal_product_demand_scenario | B16: 0 | C16: 0 | D16: 0 | E16: 0 | F16: 0 | G16: 0 | H16: 0 | I16: 0 | J16: 0 | K16: 0 | L16: 0 | M16: 0 | N16: 0 | O16: 0 | P16: 0 | Q16: 0 | R16: 0 | S16: 0 | T16: 0 | U16: 0 | V16: 0 | W16: 0 | X16: 0 | Y16: 0 | Z16: 0 | AA16: 0 | AB16: 0 | AC16: 0 | AD16: 0 | AE16: 0 | AF16: 2.6047124e-05 | AG16: 2.5931821e-05 | AH16: 2.5817027e-05 | AI16: 2.5702742e-05 | AJ16: 2.5588963e-05 | AK16: 2.5475688e-05 | AL16: 2.5362914e-05 | AM16: 2.5250639e-05 | AN16: 2.5138861e-05 | AO16: 2.5027578e-05 | AP16: 2.4916788e-05 | AQ16: 2.4806488e-05 | AR16: 2.4696676e-05 | AS16: 2.458735e-05 | AT16: 2.4478509e-05 | AU16: 2.4370149e-05 | AV16: 2.4378852e-05 | AW16: 2.4387559e-05 | AX16: 2.4396268e-05 | AY16: 2.4404981e-05 | AZ16: 2.4413697e-05 | BA16: 2.4422416e-05 | BB16: 2.4431138e-05 | BC16: 2.4439863e-05 | BD16: 2.4448591e-05 | BE16: 2.4457323e-05 | BF16: 2.4466057e-05 | BG16: 2.4474795e-05 | BH16: 2.4483535e-05 | BI16: 2.4492279e-05 | BJ16: 2.4501026e-05 | BK16: 2.4509776e-05 | BL16: 2.451853e-05 | BM16: 2.4527286e-05 | BN16: 2.4536045e-05 | BO16: 2.4544808e-05 | BP16: 2.4553574e-05 | BQ16: 2.4562343e-05 | BR16: 2.4571115e-05 | BS16: 2.457989e-05 | BT16: 2.4588668e-05 | BU16: 2.4597449e-05 | BV16: 2.4606234e-05 | BW16: 2.4615022e-05 | BX16: 2.4623812e-05 | BY16: 2.4632606e-05 | BZ16: 2.4641404e-05 | CA16: 2.4650204e-05 | CB16: 2.4659007e-05 | CC16: 2.4667814e-05 | CD16: 2.4676623e-05 | CE16: 2.4685436e-05 | CF16: 2.4694252e-05 | CG16: 2.4703071e-05 | CH16: 2.4711893e-05 | CI16: 2.4720719e-05 | CJ16: 2.4729547e-05 | CK16: 2.4738379e-05 | CL16: 2.4747214e-05 | CM16: 2.4756052e-05
... A50: USA.Potential VFN yield | B50: 0 | C50: 0 | D50: 0 | E50: 0 | F50: 0 | G50: 0 | H50: 0 | I50: 0 | J50: 0 | K50: 0 | L50: 0 | M50: 0 | N50: 0 | O50: 0 | P50: 0 | Q50: 0 | R50: 0 | S50: 0 | T50: 0 | U50: 0 | V50: 0 | W50: 0 | X50: 0 | Y50: 0 | Z50: 0 | AA50: 0 | AB50: 0 | AC50: 0 | AD50: 0 | AE50: 0 | AF50: 0.00086618671 | AG50: 0.00087332066 | AH50: 0.0008804546 | AI50: 0.00088758854 | AJ50: 0.00089472249 | AK50: 0.00090185643 | AL50: 0.00090899038 | AM50: 0.00091612432 | AN50: 0.00092325827 | AO50: 0.00093039221 | AP50: 0.00093752615 | AQ50: 0.0009446601 | AR50: 0.00095179404 | AS50: 0.00095892799 | AT50: 0.00096606193 | AU50: 0.00097319588 | AV50: 0.00099072165 | AW50: 0.0010082474 | AX50: 0.0010257732 | AY50: 0.001043299 | AZ50: 0.0010608247 | BA50: 0.0010783505 | BB50: 0.0010958763 | BC50: 0.0011134021 | BD50: 0.0011309278 | BE50: 0.0011484536 | BF50: 0.0011659794 | BG50: 0.0011835052 | BH50: 0.0012010309 | BI50: 0.0012185567 | BJ50: 0.0012360825 | BK50: 0.0012536082 | BL50: 0.001271134 | BM50: 0.0012886598 | BN50: 0.0013061856 | BO50: 0.0013237113 | BP50: 0.0013412371 | BQ50: 0.0013587629 | BR50: 0.0013762887 | BS50: 0.0013938144 | BT50: 0.0014113402 | BU50: 0.001428866 | BV50: 0.0014463918 | BW50: 0.0014639175 | BX50: 0.0014814433 | BY50: 0.0014989691 | BZ50: 0.0015164948 | CA50: 0.0015340206 | CB50: 0.0015515464 | CC50: 0.0015690722 | CD50: 0.0015865979 | CE50: 0.0016041237 | CF50: 0.0016216495 | CG50: 0.0016391753 | CH50: 0.001656701 | CI50: 0.0016742268 | CJ50: 0.0016917526 | CK50: 0.0017092784 | CL50: 0.0017268041 | CM50: 0.0017443299
A52: USA.Crop Land Alloc to Cellulosic Energy Crop | B52: ='WAO Scenario Ag'!B23 -> 0 | C52: ='WAO Scenario Ag'!C23 -> 0 | D52: ='WAO Scenario Ag'!D23 -> 0 | E52: ='WAO Scenario Ag'!E23 -> 0 | F52: ='WAO Scenario Ag'!F23 -> 0 | G52: ='WAO Scenario Ag'!G23 -> 0 | H52: ='WAO Scenario Ag'!H23 -> 0 | I52: ='WAO Scenario Ag'!I23 -> 0 | ... CM52: ='WAO Scenario Ag'!CM23 -> 22021019
A54: ROW.Crop Land Alloc to Cellulosic Energy Crop | B54: ='WAO Scenario Ag'!B24 -> 0 | C54: ='WAO Scenario Ag'!C24 -> 0 | D54: ='WAO Scenario Ag'!D24 -> 0 | E54: ='WAO Scenario Ag'!E24 -> 0 | F54: ='WAO Scenario Ag'!F24 -> 0 | G54: ='WAO Scenario Ag'!G24 -> 0 | H54: ='WAO Scenario Ag'!H24 -> 0 | I54: ='WAO Scenario Ag'!I24 -> 0 | ... CM54: ='WAO Scenario Ag'!CM24 -> 61165926

Sheet LUC-2012-08-10-Run2
B1: 1961 | C1: 1962 | D1: 1963 | E1: 1964 | F1: 1965 | G1: 1966 | H1: 1967 | I1: 1968 | J1: 1969 | K1: 1970 | L1: 1971 | M1: 1972 | N1: 1973 | O1: 1974 | P1: 1975 | Q1: 1976 | R1: 1977 | S1: 1978 | T1: 1979 | U1: 1980 | V1: 1981 | W1: 1982 | X1: 1983 | Y1: 1984 | Z1: 1985 | AA1: 1986 | AB1: 1987 | AC1: 1988 | AD1: 1989 | AE1: 1990 | AF1: 1991 | AG1: 1992 | AH1: 1993 | AI1: 1994 | AJ1: 1995 | AK1: 1996 | AL1: 1997 | AM1: 1998 | AN1: 1999 | AO1: 2000 | AP1: 2001 | AQ1: 2002 | AR1: 2003 | AS1: 2004 | AT1: 2005 | AU1: 2006 | AV1: 2007 | AW1: 2008 | AX1: 2009 | AY1: 2010 | AZ1: 2011 | BA1: 2012 | BB1: 2013 | BC1: 2014 | BD1: 2015 | BE1: 2016 | BF1: 2017 | BG1: 2018 | BH1: 2019 | BI1: 2020 | BJ1: 2021 | BK1: 2022 | BL1: 2023 | BM1: 2024 | BN1: 2025 | BO1: 2026 | BP1: 2027 | BQ1: 2028 | BR1: 2029 | BS1: 2030 | BT1: 2031 | BU1: 2032 | BV1: 2033 | BW1: 2034 | BX1: 2035 | BY1: 2036 | BZ1: 2037 | CA1: 2038 | CB1: 2039 | CC1: 2040 | CD1: 2041 | CE1: 2042 | CF1: 2043 | CG1: 2044 | CH1: 2045 | CI1: 2046 | CJ1: 2047 | CK1: 2048 | CL1: 2049 | CM1: 2050
A2: ROW.per_capita_animal_product_demand_scenario | B2: 0 | C2: 0 | D2: 0 | E2: 0 | F2: 0 | G2: 0 | H2: 0 | I2: 0 | J2: 0 | K2: 0 | L2: 0 | M2: 0 | N2: 0 | O2: 0 | P2: 0 | Q2: 0 | R2: 0 | S2: 0 | T2: 0 | U2: 0 | V2: 0 | W2: 0 | X2: 0 | Y2: 0 | Z2: 0 | AA2: 0 | AB2: 0 | AC2: 0 | AD2: 0 | AE2: 0 | AF2: 1.0508416e-05 | AG2: 1.0527619e-05 | AH2: 1.0524145e-05 | AI2: 1.0522463e-05 | AJ2: 1.0522681e-05 | AK2: 1.0524798e-05 | AL2: 1.0528849e-05 | AM2: 1.0535258e-05 | AN2: 1.0544408e-05 | AO2: 1.0556611e-05 | AP2: 1.0571845e-05 | AQ2: 1.058998e-05 | AR2: 1.0610719e-05 | AS2: 1.0633798e-05 | AT2: 1.0658935e-05 | AU2: 1.0847333e-05 | AV2: 1.0964836e-05 | AW2: 1.1083992e-05 | AX2: 1.120477e-05 | AY2: 1.1327126e-05 | AZ2: 1.1451083e-05 | BA2: 1.1576694e-05 | BB2: 1.170399e-05 | BC2: 1.1833063e-05 | BD2: 1.1963939e-05 | BE2: 1.2096649e-05 | BF2: 1.2231179e-05 | BG2: 1.2367491e-05 | BH2: 1.2505587e-05 | BI2: 1.2645391e-05 | BJ2: 1.2786913e-05 | BK2: 1.2930112e-05 | BL2: 1.3074987e-05 | BM2: 1.3221532e-05 | BN2: 1.3369756e-05 | BO2: 1.35196e-05 | BP2: 1.3671072e-05 | BQ2: 1.3824161e-05 | BR2: 1.3978933e-05 | BS2: 1.4135376e-05 | BT2: 1.429351e-05 | BU2: 1.4453327e-05 | BV2: 1.4614729e-05 | BW2: 1.4777609e-05 | BX2: 1.49419e-05 | BY2: 1.5107582e-05 | BZ2: 1.5274651e-05 | CA2: 1.5443153e-05 | CB2: 1.5613158e-05 | CC2: 1.5784721e-05 | CD2: 1.5957834e-05 | CE2: 1.6132525e-05 | CF2: 1.6308757e-05 | CG2: 1.6486516e-05 | CH2: 1.6665823e-05 | CI2: 1.6846654e-05 | CJ2: 1.7029046e-05 | CK2: 1.7213054e-05 | CL2: 1.7398717e-05 | CM2: 1.7586115e-05
A3: … | B3: 0 | C3: 0 | D3: 0 | E3: 0 | F3: 0 | G3: 0 | H3: 0 | I3: 0 | J3: 0 | K3: 0 | L3: 0 | M3: 0 | N3: 0 | O3: 0 | P3: 0 | Q3: 0 | R3: 0 | S3: 0 | T3: 0 | U3: 0 | V3: 0 | W3: 0 | X3: 0 | Y3: 0 | Z3: 0 | AA3: 0 | AB3: 0 | AC3: 0 | AD3: 0 | AE3: 0 | AF3: 7.000043e-05 | AG3: 7.0630961e-05 | AH3: 7.1066274e-05 | AI3: 7.150778e-05 | AJ3: 7.1952945e-05 | AK3: 7.2400862e-05 | AL3: 7.2852846e-05 | AM3: 7.3313274e-05 | AN3: 7.3787111e-05 | AO3: 7.4277958e-05 | AP3: 7.4785862e-05 | AQ3: 7.5308758e-05 | AR3: 7.584261e-05 | AS3: 7.638308e-05 | AT3: 7.6926134e-05 | AU3: 7.8564814e-05 | AV3: 7.9759633e-05 | AW3: 8.0954262e-05 | AX3: 8.2147892e-05 | AY3: 8.3339977e-05 | AZ3: 8.4530221e-05 | BA3: 8.5718612e-05 | BB3: 8.690567e-05 | BC3: 8.8092573e-05 | BD3: 8.9279967e-05 | BE3: 9.0467983e-05 | BF3: 9.1656452e-05 | BG3: 9.2845627e-05 | BH3: 9.4035979e-05 | BI3: 9.5227511e-05 | BJ3: 9.6420416e-05 | BK3: 9.7614504e-05 | BL3: 9.8809372e-05 | BM3: 0.00010000446 | BN3: 0.00010119957 | BO3: 0.00010239415 | BP3: 0.00010358838 | BQ3: 0.00010478176 | BR3: 0.00010597432 | BS3: 0.00010716565 | BT3: 0.00010822525 | BU3: 0.00010928723 | BV3: 0.00011035132 | BW3: 0.00011141784 | BX3: 0.00011248686 | BY3: 0.00011355858 | BZ3: 0.00011463261 | CA3: 0.0001157092 | CB3: 0.00011678824 | CC3: 0.0001178697 | CD3: 0.00011895337 | CE3: 0.00012003931 | CF3: 0.00012112748 | CG3: 0.00012221779 | CH3: 0.00012331033 | CI3: 0.00012440495 | CJ3: 0.00012550153 | CK3: 0.00012659968 | CL3: 0.00012769947 | CM3: 0.00012880035
A4: ... | B4: 0 | C4: 0 | D4: 0 | E4: 0 | F4: 0 | G4: 0 | H4: 0 | I4: 0 | J4: 0 | K4: 0 | L4: 0 | M4: 0 | N4: 0 | O4: 0 | P4: 0 | Q4: 0 | R4: 0 | S4: 0 | T4: 0 | U4: 0 | V4: 0 | W4: 0 | X4: 0 | Y4: 0 | Z4: 0 | AA4: 0 | AB4: 0 | AC4: 0 | AD4: 0 | AE4: 0 | AF4: 1.3228987e-05 | AG4: 1.3351004e-05 | AH4: 1.3448211e-05 | AI4: 1.3548882e-05 | AJ4: 1.365327e-05 | AK4: 1.3761501e-05 | AL4: 1.3873701e-05 | AM4: 1.3990475e-05 | AN4: 1.4112379e-05 | AO4: 1.4239928e-05 | AP4: 1.4373259e-05 | AQ4: 1.4512397e-05 | AR4: 1.4657165e-05 | AS4: 1.4807427e-05 | AT4: 1.4962997e-05 | AU4: 1.5469466e-05 | AV4: 1.5574976e-05 | AW4: 1.5682744e-05 | AX4: 1.5792765e-05 | AY4: 1.5905015e-05 | AZ4: 1.6019564e-05 | BA4: 1.6136521e-05 | BB4: 1.6255961e-05 | BC4: 1.6378047e-05 | BD4: 1.6502859e-05 | BE4: 1.6630486e-05 | BF4: 1.6760962e-05 | BG4: 1.6894312e-05 | BH4: 1.7030628e-05 | BI4: 1.716989e-05 | BJ4: 1.7312207e-05 | BK4: 1.7457606e-05 | BL4: 1.7606171e-05 | BM4: 1.7757978e-05 | BN4: 1.7913134e-05 | BO4: 1.8071653e-05 | BP4: 1.8233636e-05 | BQ4: 1.8399149e-05 | BR4: 1.8568334e-05 | BS4: 1.8741253e-05 | BT4: 1.8917994e-05 | BU4: 1.9098657e-05 | BV4: 1.9283182e-05 | BW4: 1.9471519e-05 | BX4: 1.9663666e-05 | BY4: 1.9859684e-05 | BZ4: 2.0059663e-05 | CA4: 2.0263768e-05 | CB4: 2.0472218e-05 | CC4: 2.0685178e-05 | CD4: 2.0902763e-05 | CE4: 2.1125138e-05 | CF4: 2.1352359e-05 | CG4: 2.158455e-05 | CH4: 2.182185e-05 | CI4: 2.20644e-05 | CJ4: 2.2312385e-05 | CK4: 2.2566061e-05 | CL4: 2.2825635e-05 | CM4: 2.3091433e-05
A5: ... | B5: 0 | C5: 0 | D5: 0 | E5: 0 | F5: 0 | G5: 0 | H5: 0 | I5: 0 | J5: 0 | K5: 0 | L5: 0 | M5: 0 | N5: 0 | O5: 0 | P5: 0 | Q5: 0 | R5: 0 | S5: 0 | T5: 0 | U5: 0 | V5: 0 | W5: 0 | X5: 0 | Y5: 0 | Z5: 0 | AA5: 0 | AB5: 0 | AC5: 0 | AD5: 0 | AE5: 0 | AF5: 7.0121002e-06 | AG5: 7.2210894e-06 | AH5: 7.4202146e-06 | AI5: 7.6288203e-06 | AJ5: 7.8474397e-06 | AK5: 8.0765895e-06 | AL5: 8.3168765e-06 | AM5: 8.5692634e-06 | AN5: 8.8347261e-06 | AO5: 9.1142143e-06 | AP5: 9.4084017e-06 | AQ5: 9.7178946e-06 | AR5: 1.0043174e-05 | AS5: 1.0384788e-05 | AT5: 1.0743309e-05 | AU5: 1.1732151e-05 | AV5: 1.2029102e-05 | AW5: 1.2330363e-05 | AX5: 1.2636011e-05 | AY5: 1.2946105e-05 | AZ5: 1.3260781e-05 | BA5: 1.3580209e-05 | BB5: 1.3904535e-05 | BC5: 1.4233979e-05 | BD5: 1.45687e-05 | BE5: 1.4908865e-05 | BF5: 1.5254594e-05 | BG5: 1.560599e-05 | BH5: 1.5963211e-05 | BI5: 1.6326322e-05 | BJ5: 1.6695498e-05 | BK5: 1.7070852e-05 | BL5: 1.7452545e-05 | BM5: 1.7840733e-05 | BN5: 1.8235602e-05 | BO5: 1.8637253e-05 | BP5: 1.9045874e-05 | BQ5: 1.9461628e-05 | BR5: 1.9884772e-05 | BS5: 2.0315474e-05 | BT5: 2.0753938e-05 | BU5: 2.1200362e-05 | BV5: 2.165481e-05 | BW5: 2.2117347e-05 | BX5: 2.258809e-05 | BY5: 2.3067222e-05 | BZ5: 2.3554949e-05 | CA5: 2.4051561e-05 | CB5: 2.4557389e-05 | CC5: 2.5072742e-05 | CD5: 2.5597856e-05 | CE5: 2.613303e-05 | CF5: 2.6678466e-05 | CG5: 2.7234421e-05 | CH5: 2.7801191e-05 | CI5: 2.8379046e-05 | CJ5: 2.8968324e-05 | CK5: 2.9569416e-05 | CL5: 3.0182697e-05 | CM5: 3.080862e-05
A7: ROW.per_capita_commodity_crop_demand_scenario | B7: 0 | C7: 0 | D7: 0 | E7: 0 | F7: 0 | G7: 0 | H7: 0 | I7: 0 | J7: 0 | K7: 0 | L7: 0 | M7: 0 | N7: 0 | O7: 0 | P7: 0 | Q7: 0 | R7: 0 | S7: 0 | T7: 0 | U7: 0 | V7: 0 | W7: 0 | X7: 0 | Y7: 0 | Z7: 0 | AA7: 0 | AB7: 0 | AC7: 0 | AD7: 0 | AE7: 0 | AF7: 3.6843337e-05 | AG7: 3.6790336e-05 | AH7: 3.6735361e-05 | AI7: 3.6679542e-05 | AJ7: 3.6623172e-05 | AK7: 3.6566333e-05 | AL7: 3.6509049e-05 | AM7: 3.6451466e-05 | AN7: 3.6393772e-05 | AO7: 3.6336058e-05 | AP7: 3.6278481e-05 | AQ7: 3.6221086e-05 | AR7: 3.6163908e-05 | AS7: 3.6106967e-05 | AT7: 3.6050252e-05 | AU7: 3.6181023e-05 | AV7: 3.6805881e-05 | AW7: 3.7432183e-05 | AX7: 3.805984e-05 | AY7: 3.8688784e-05 | AZ7: 3.9318985e-05 | BA7: 3.9950454e-05 | BB7: 4.0583238e-05 | BC7: 4.1217414e-05 | BD7: 4.1853032e-05 | BE7: 4.2490101e-05 | BF7: 4.3128576e-05 | BG7: 4.3768429e-05 | BH7: 4.4409623e-05 | BI7: 4.5052144e-05 | BJ7: 4.5695973e-05 | BK7: 4.6341127e-05 | BL7: 4.6987579e-05 | BM7: 4.7635341e-05 | BN7: 4.8284392e-05 | BO7: 4.8934736e-05 | BP7: 4.9586382e-05 | BQ7: 5.0239352e-05 | BR7: 5.0893685e-05 | BS7: 5.1549386e-05 | BT7: 5.1636306e-05 | BU7: 5.172455e-05 | BV7: 5.1814122e-05 | BW7: 5.1905017e-05 | BX7: 5.1997227e-05 | BY7: 5.2090743e-05 | BZ7: 5.2185572e-05 | CA7: 5.2281706e-05 | CB7: 5.2379129e-05 | CC7: 5.2477845e-05 | CD7: 5.2577842e-05 | CE7: 5.2679113e-05 | CF7: 5.2781652e-05 | CG7: 5.2885445e-05 | CH7: 5.2990488e-05 | CI7: 5.3096775e-05 | CJ7: 5.3204298e-05 | CK7: 5.3313061e-05 | CL7: 5.3423071e-05 | CM7: 5.3534324e-05
A8: … | B8: 0 | C8: 0 | D8: 0 | E8: 0 | F8: 0 | G8: 0 | H8: 0 | I8: 0 | J8: 0 | K8: 0 | L8: 0 | M8: 0 | N8: 0 | O8: 0 | P8: 0 | Q8: 0 | R8: 0 | S8: 0 | T8: 0 | U8: 0 | V8: 0 | W8: 0 | X8: 0 | Y8: 0 | Z8: 0 | AA8: 0 | AB8: 0 | AC8: 0 | AD8: 0 | AE8: 0 | AF8: 5.2769166e-05 | AG8: 5.2693256e-05 | AH8: 5.2614517e-05 | AI8: 5.253457e-05 | AJ8: 5.2453834e-05 | AK8: 5.2372426e-05 | AL8: 5.229038e-05 | AM8: 5.2207906e-05 | AN8: 5.2125274e-05 | AO8: 5.2042613e-05 | AP8: 5.1960147e-05 | AQ8: 5.1877943e-05 | AR8: 5.1796049e-05 | AS8: 5.1714495e-05 | AT8: 5.1633265e-05 | AU8: 5.1820562e-05 | AV8: 5.1885131e-05 | AW8: 5.1950214e-05 | AX8: 5.20157e-05 | AY8: 5.2081508e-05 | AZ8: 5.2147615e-05 | BA8: 5.2214059e-05 | BB8: 5.2280919e-05 | BC8: 5.2348326e-05 | BD8: 5.2416362e-05 | BE8: 5.2485056e-05 | BF8: 5.2554358e-05 | BG8: 5.2624227e-05 | BH8: 5.2694617e-05 | BI8: 5.2765503e-05 | BJ8: 5.2836861e-05 | BK8: 5.2908715e-05 | BL8: 5.2981037e-05 | BM8: 5.3053844e-05 | BN8: 5.3127113e-05 | BO8: 5.3200846e-05 | BP8: 5.3275066e-05 | BQ8: 5.3349808e-05 | BR8: 5.3425155e-05 | BS8: 5.3501125e-05 | BT8: 5.35859e-05 | BU8: 5.3672283e-05 | BV8: 5.376027e-05 | BW8: 5.3849853e-05 | BX8: 5.3941018e-05 | BY8: 5.4033763e-05 | BZ8: 5.4128092e-05 | CA8: 5.4224009e-05 | CB8: 5.4321497e-05 | CC8: 5.4420573e-05 | CD8: 5.4521219e-05 | CE8: 5.4623426e-05 | CF8: 5.4727189e-05 | CG8: 5.4832486e-05 | CH8: 5.4939322e-05 | CI8: 5.5047676e-05 | CJ8: 5.5157543e-05 | CK8: 5.5268921e-05 | CL8: 5.5381827e-05 | CM8: 5.5496248e-05
A9: … | B9: 0 | C9: 0 | D9: 0 | E9: 0 | F9: 0 | G9: 0 | H9: 0 | I9: 0 | J9: 0 | K9: 0 | L9: 0 | M9: 0 | N9: 0 | O9: 0 | P9: 0 | Q9: 0 | R9: 0 | S9: 0 | T9: 0 | U9: 0 | V9: 0 | W9: 0 | X9: 0 | Y9: 0 | Z9: 0 | AA9: 0 | AB9: 0 | AC9: 0 | AD9: 0 | AE9: 0 | AF9: 3.7556434e-05 | AG9: 3.7502407e-05 | AH9: 3.7446368e-05 | AI9: 3.7389469e-05 | AJ9: 3.7332008e-05 | AK9: 3.7274069e-05 | AL9: 3.7215676e-05 | AM9: 3.7156978e-05 | AN9: 3.7098168e-05 | AO9: 3.7039337e-05 | AP9: 3.6980645e-05 | AQ9: 3.6922139e-05 | AR9: 3.6863855e-05 | AS9: 3.6805812e-05 | AT9: 3.6747999e-05 | AU9: 3.6881301e-05 | AV9: 3.6933063e-05 | AW9: 3.6984803e-05 | AX9: 3.7036437e-05 | AY9: 3.7087902e-05 | AZ9: 3.7139177e-05 | BA9: 3.7190286e-05 | BB9: 3.7241284e-05 | BC9: 3.7292262e-05 | BD9: 3.7343281e-05 | BE9: 3.7394359e-05 | BF9: 3.7445462e-05 | BG9: 3.7496556e-05 | BH9: 3.7547609e-05 | BI9: 3.7598598e-05 | BJ9: 3.7649503e-05 | BK9: 3.7700339e-05 | BL9: 3.775108e-05 | BM9: 3.7801728e-05 | BN9: 3.7852263e-05 | BO9: 3.7902674e-05 | BP9: 3.795298e-05 | BQ9: 3.8003198e-05 | BR9: 3.8053394e-05 | BS9: 3.8103575e-05 | BT9: 3.8156453e-05 | BU9: 3.8210418e-05 | BV9: 3.8265476e-05 | BW9: 3.8321624e-05 | BX9: 3.837886e-05 | BY9: 3.8437188e-05 | BZ9: 3.8496608e-05 | CA9: 3.8557128e-05 | CB9: 3.8618734e-05 | CC9: 3.8681443e-05 | CD9: 3.8745238e-05 | CE9: 3.8810115e-05 | CF9: 3.8876073e-05 | CG9: 3.8943094e-05 | CH9: 3.9011184e-05 | CI9: 3.9080324e-05 | CJ9: 3.9150511e-05 | CK9: 3.9221738e-05 | CL9: 3.9294017e-05 | CM9: 3.936733e-05
A10: … | B10: 0 | C10: 0 | D10: 0 | E10: 0 | F10: 0 | G10: 0 | H10: 0 | I10: 0 | J10: 0 | K10: 0 | L10: 0 | M10: 0 | N10: 0 | O10: 0 | P10: 0 | Q10: 0 | R10: 0 | S10: 0 | T10: 0 | U10: 0 | V10: 0 | W10: 0 | X10: 0 | Y10: 0 | Z10: 0 | AA10: 0 | AB10: 0 | AC10: 0 | AD10: 0 | AE10: 0 | AF10: 3.2802455e-05 | AG10: 3.2755267e-05 | AH10: 3.2706321e-05 | AI10: 3.2656625e-05 | AJ10: 3.2606437e-05 | AK10: 3.2555832e-05 | AL10: 3.2504831e-05 | AM10: 3.2453563e-05 | AN10: 3.2402197e-05 | AO10: 3.2350813e-05 | AP10: 3.2299551e-05 | AQ10: 3.2248451e-05 | AR10: 3.2197544e-05 | AS10: 3.2146848e-05 | AT10: 3.2096354e-05 | AU10: 3.2212782e-05 | AV10: 3.2464153e-05 | AW10: 3.2716906e-05 | AX10: 3.2970962e-05 | AY10: 3.3226264e-05 | AZ10: 3.3482789e-05 | BA10: 3.374055e-05 | BB10: 3.3999588e-05 | BC10: 3.4259969e-05 | BD10: 3.4521734e-05 | BE10: 3.4784889e-05 | BF10: 3.5049395e-05 | BG10: 3.5315228e-05 | BH10: 3.5582358e-05 | BI10: 3.5850774e-05 | BJ10: 3.6120462e-05 | BK10: 3.6391437e-05 | BL10: 3.6663678e-05 | BM10: 3.6937198e-05 | BN10: 3.7211979e-05 | BO10: 3.7488031e-05 | BP10: 3.776536e-05 | BQ10: 3.8043985e-05 | BR10: 3.8323934e-05 | BS10: 3.860521e-05 | BT10: 3.867792e-05 | BU10: 3.8751713e-05 | BV10: 3.8826592e-05 | BW10: 3.8902553e-05 | BX10: 3.8979588e-05 | BY10: 3.9057691e-05 | BZ10: 3.9136866e-05 | CA10: 3.9217106e-05 | CB10: 3.9298399e-05 | CC10: 3.9380745e-05 | CD10: 3.9464137e-05 | CE10: 3.9548569e-05 | CF10: 3.9634035e-05 | CG10: 3.9720527e-05 | CH10: 3.9808039e-05 | CI10: 3.9896568e-05 | CJ10: 3.9986108e-05 | CK10: 4.0076663e-05 | CL10: 4.016824e-05 | CM10: 4.0260837e-05
A11: … | B11: 0 | C11: 0 | D11: 0 | E11: 0 | F11: 0 | G11: 0 | H11: 0 | I11: 0 | J11: 0 | K11: 0 | L11: 0 | M11: 0 | N11: 0 | O11: 0 | P11: 0 | Q11: 0 | R11: 0 | S11: 0 | T11: 0 | U11: 0 | V11: 0 | W11: 0 | X11: 0 | Y11: 0 | Z11: 0 | AA11: 0 | AB11: 0 | AC11: 0 | AD11: 0 | AE11: 0 | AF11: 9.8542367e-06 | AG11: 9.9823314e-06 | AH11: 1.0100377e-05 | AI11: 1.0217954e-05 | AJ11: 1.0335036e-05 | AK11: 1.045161e-05 | AL11: 1.0567721e-05 | AM11: 1.0683585e-05 | AN11: 1.0799445e-05 | AO11: 1.0915504e-05 | AP11: 1.1031807e-05 | AQ11: 1.114831e-05 | AR11: 1.126487e-05 | AS11: 1.1381328e-05 | AT11: 1.1497512e-05 | AU11: 1.1803464e-05 | AV11: 1.2071077e-05 | AW11: 1.2339033e-05 | AX11: 1.2607263e-05 | AY11: 1.2875722e-05 | AZ11: 1.3144398e-05 | BA11: 1.34133e-05 | BB11: 1.3682449e-05 | BC11: 1.3951887e-05 | BD11: 1.4221622e-05 | BE11: 1.4491644e-05 | BF11: 1.4761925e-05 | BG11: 1.5032444e-05 | BH11: 1.5303188e-05 | BI11: 1.5574123e-05 | BJ11: 1.5845232e-05 | BK11: 1.6116482e-05 | BL11: 1.6387847e-05 | BM11: 1.6659294e-05 | BN11: 1.6930805e-05 | BO11: 1.720234e-05 | BP11: 1.747389e-05 | BQ11: 1.7745422e-05 | BR11: 1.8016931e-05 | BS11: 1.8288393e-05 | BT11: 1.8537394e-05 | BU11: 1.8786939e-05 | BV11: 1.9037001e-05 | BW11: 1.9287579e-05 | BX11: 1.9538671e-05 | BY11: 1.9790284e-05 | BZ11: 2.0042405e-05 | CA11: 2.0295034e-05 | CB11: 2.0548157e-05 | CC11: 2.0801759e-05 | CD11: 2.1055828e-05 | CE11: 2.1310347e-05 | CF11: 2.1565315e-05 | CG11: 2.1820724e-05 | CH11: 2.2076568e-05 | CI11: 2.2332827e-05 | CJ11: 2.2589489e-05 | CK11: 2.284651e-05 | CL11: 2.3103865e-05 | CM11: 2.3361499e-05
A12: … | B12: 0 | C12: 0 | D12: 0 | E12: 0 | F12: 0 | G12: 0 | H12: 0 | I12: 0 | J12: 0 | K12: 0 | L12: 0 | M12: 0 | N12: 0 | O12: 0 | P12: 0 | Q12: 0 | R12: 0 | S12: 0 | T12: 0 | U12: 0 | V12: 0 | W12: 0 | X12: 0 | Y12: 0 | Z12: 0 | AA12: 0 | AB12: 0 | AC12: 0 | AD12: 0 | AE12: 0 | AF12: 2.1546611e-05 | AG12: 2.1548776e-05 | AH12: 2.1529814e-05 | AI12: 2.1511796e-05 | AJ12: 2.1494295e-05 | AK12: 2.1477259e-05 | AL12: 2.1460781e-05 | AM12: 2.1445238e-05 | AN12: 2.1430974e-05 | AO12: 2.1418246e-05 | AP12: 2.1406989e-05 | AQ12: 2.1396971e-05 | AR12: 2.1387819e-05 | AS12: 2.1379161e-05 | AT12: 2.1370586e-05 | AU12: 2.1564353e-05 | AV12: 2.1793341e-05 | AW12: 2.20229e-05 | AX12: 2.2252916e-05 | AY12: 2.2483317e-05 | AZ12: 2.2714122e-05 | BA12: 2.294537e-05 | BB12: 2.3177169e-05 | BC12: 2.3409715e-05 | BD12: 2.3643118e-05 | BE12: 2.3877389e-05 | BF12: 2.411249e-05 | BG12: 2.4348441e-05 | BH12: 2.4585313e-05 | BI12: 2.4823071e-05 | BJ12: 2.5061723e-05 | BK12: 2.5301223e-05 | BL12: 2.554147e-05 | BM12: 2.5782357e-05 | BN12: 2.6023827e-05 | BO12: 2.6265788e-05 | BP12: 2.650824e-05 | BQ12: 2.6751113e-05 | BR12: 2.6994399e-05 | BS12: 2.7238016e-05 | BT12: 2.7486278e-05 | BU12: 2.7735067e-05 | BV12: 2.7984373e-05 | BW12: 2.8234186e-05 | BX12: 2.8484527e-05 | BY12: 2.8735408e-05 | BZ12: 2.8986784e-05 | CA12: 2.9238689e-05 | CB12: 2.9491106e-05 | CC12: 2.974403e-05 | CD12: 2.9997419e-05 | CE12: 3.0251286e-05 | CF12: 3.0505605e-05 | CG12: 3.0760362e-05 | CH12: 3.1015538e-05 | CI12: 3.1271124e-05 | CJ12: 3.1527085e-05 | CK12: 3.1783371e-05 | CL12: 3.2039952e-05 | CM12: 3.2296748e-05
A14: ROW.Per_capita_VFN_demand_Scenario | B14: 0 | C14: 0 | D14: 0 | E14: 0 | F14: 0 | G14: 0 | H14: 0 | I14: 0 | J14: 0 | K14: 0 | L14: 0 | M14: 0 | N14: 0 | O14: 0 | P14: 0 | Q14: 0 | R14: 0 | S14: 0 | T14: 0 | U14: 0 | V14: 0 | W14: 0 | X14: 0 | Y14: 0 | Z14: 0 | AA14: 0 | AB14: 0 | AC14: 0 | AD14: 0 | AE14: 0 | AF14: 7.2579401e-05 | AG14: 7.271075e-05 | AH14: 7.2835631e-05 | AI14: 7.2966845e-05 | AJ14: 7.310436e-05 | AK14: 7.3248247e-05 | AL14: 7.3398755e-05 | AM14: 7.3555626e-05 | AN14: 7.371863e-05 | AO14: 7.388793e-05 | AP14: 7.4063048e-05 | AQ14: 7.4244147e-05 | AR14: 7.4431632e-05 | AS14: 7.4625872e-05 | AT14: 7.4827372e-05 | AU14: 7.5272799e-05 | AV14: 7.5653422e-05 | AW14: 7.6040194e-05 | AX14: 7.6432191e-05 | AY14: 7.682888e-05 | AZ14: 7.7229801e-05 | BA14: 7.7634911e-05 | BB14: 7.8043932e-05 | BC14: 7.8456345e-05 | BD14: 7.8871802e-05 | BE14: 7.9290254e-05 | BF14: 7.9711491e-05 | BG14: 8.0135789e-05 | BH14: 8.0562988e-05 | BI14: 8.0993198e-05 | BJ14: 8.1426527e-05 | BK14: 8.1862877e-05 | BL14: 8.2302563e-05 | BM14: 8.2745948e-05 | BN14: 8.3193151e-05 | BO14: 8.3644367e-05 | BP14: 8.4099277e-05 | BQ14: 8.4557926e-05 | BR14: 8.5019751e-05 | BS14: 8.8421504e-05 | BT14: 8.8842394e-05 | BU14: 8.9265304e-05 | BV14: 8.968967e-05 | BW14: 9.0115191e-05 | BX14: 9.0541413e-05 | BY14: 9.0968056e-05 | BZ14: 9.1395259e-05 | CA14: 9.1822764e-05 | CB14: 9.2250697e-05 | CC14: 9.2678861e-05 | CD14: 9.3107438e-05 | CE14: 9.3536263e-05 | CF14: 9.3965275e-05 | CG14: 9.4394519e-05 | CH14: 9.4823893e-05 | CI14: 9.5253529e-05 | CJ14: 9.5683466e-05 | CK14: 9.6113971e-05 | CL14: 9.6545001e-05 | CM14: 9.6977e-05
A16: USA.per_capita_animal_product_demand_scenario | B16: 0 | C16: 0 | D16: 0 | E16: 0 | F16: 0 | G16: 0 | H16: 0 | I16: 0 | J16: 0 | K16: 0 | L16: 0 | M16: 0 | N16: 0 | O16: 0 | P16: 0 | Q16: 0 | R16: 0 | S16: 0 | T16: 0 | U16: 0 | V16: 0 | W16: 0 | X16: 0 | Y16: 0 | Z16: 0 | AA16: 0 | AB16: 0 | AC16: 0 | AD16: 0 | AE16: 0 | AF16: 2.6047124e-05 | AG16: 2.5931821e-05 | AH16: 2.5817027e-05 | AI16: 2.5702742e-05 | AJ16: 2.5588963e-05 | AK16: 2.5475688e-05 | AL16: 2.5362914e-05 | AM16: 2.5250639e-05 | AN16: 2.5138861e-05 | AO16: 2.5027578e-05 | AP16: 2.4916788e-05 | AQ16: 2.4806488e-05 | AR16: 2.4696676e-05 | AS16: 2.458735e-05 | AT16: 2.4478509e-05 | AU16: 2.4527271e-05 | AV16: 2.4548594e-05 | AW16: 2.4569925e-05 | AX16: 2.4591263e-05 | AY16: 2.4612609e-05 | AZ16: 2.4633963e-05 | BA16: 2.4655324e-05 | BB16: 2.4676693e-05 | BC16: 2.469807e-05 | BD16: 2.4719454e-05 | BE16: 2.4740846e-05 | BF16: 2.4762246e-05 | BG16: 2.4783653e-05 | BH16: 2.4805068e-05 | BI16: 2.482649e-05 | BJ16: 2.484792e-05 | BK16: 2.4869358e-05 | BL16: 2.4890803e-05 | BM16: 2.4912256e-05 | BN16: 2.4933717e-05 | BO16: 2.4955185e-05 | BP16: 2.4976662e-05 | BQ16: 2.4998145e-05 | BR16: 2.5019637e-05 | BS16: 2.5041136e-05 | BT16: 2.5062642e-05 | BU16: 2.5084157e-05 | BV16: 2.5105679e-05 | BW16: 2.5127209e-05 | BX16: 2.5148746e-05 | BY16: 2.5170292e-05 | BZ16: 2.5191844e-05 | CA16: 2.5213405e-05 | CB16: 2.5234973e-05 | CC16: 2.5256549e-05 | CD16: 2.5278133e-05 | CE16: 2.5299724e-05 | CF16: 2.5321323e-05 | CG16: 2.534293e-05 | CH16: 2.5364545e-05 | CI16: 2.5386167e-05 | CJ16: 2.5407797e-05 | CK16: 2.5429435e-05 | CL16: 2.545108e-05 | CM16: 2.5472733e-05
... A50: USA.Potential VFN yield | B50: 0 | C50: 0 | D50: 0 | E50: 0 | F50: 0 | G50: 0 | H50: 0 | I50: 0 | J50: 0 | K50: 0 | L50: 0 | M50: 0 | N50: 0 | O50: 0 | P50: 0 | Q50: 0 | R50: 0 | S50: 0 | T50: 0 | U50: 0 | V50: 0 | W50: 0 | X50: 0 | Y50: 0 | Z50: 0 | AA50: 0 | AB50: 0 | AC50: 0 | AD50: 0 | AE50: 0 | AF50: 0.00086618671 | AG50: 0.00087332066 | AH50: 0.0008804546 | AI50: 0.00088758854 | AJ50: 0.00089472249 | AK50: 0.00090185643 | AL50: 0.00090899038 | AM50: 0.00091612432 | AN50: 0.00092325827 | AO50: 0.00093039221 | AP50: 0.00093752615 | AQ50: 0.0009446601 | AR50: 0.00095179404 | AS50: 0.00095892799 | AT50: 0.00096606193 | AU50: 0.00097319588 | AV50: 0.00099072165 | AW50: 0.0010082474 | AX50: 0.0010257732 | AY50: 0.001043299 | AZ50: 0.0010608247 | BA50: 0.0010783505 | BB50: 0.0010958763 | BC50: 0.0011134021 | BD50: 0.0011309278 | BE50: 0.0011484536 | BF50: 0.0011659794 | BG50: 0.0011835052 | BH50: 0.0012010309 | BI50: 0.0012185567 | BJ50: 0.0012360825 | BK50: 0.0012536082 | BL50: 0.001271134 | BM50: 0.0012886598 | BN50: 0.0013061856 | BO50: 0.0013237113 | BP50: 0.0013412371 | BQ50: 0.0013587629 | BR50: 0.0013762887 | BS50: 0.0013938144 | BT50: 0.0014113402 | BU50: 0.001428866 | BV50: 0.0014463918 | BW50: 0.0014639175 | BX50: 0.0014814433 | BY50: 0.0014989691 | BZ50: 0.0015164948 | CA50: 0.0015340206 | CB50: 0.0015515464 | CC50: 0.0015690722 | CD50: 0.0015865979 | CE50: 0.0016041237 | CF50: 0.0016216495 | CG50: 0.0016391753 | CH50: 0.001656701 | CI50: 0.0016742268 | CJ50: 0.0016917526 | CK50: 0.0017092784 | CL50: 0.0017268041 | CM50: 0.0017443299
A52: USA.Crop Land Alloc to Cellulosic Energy Crop | B52: ='WAO Scenario Ag'!B23 -> 0 | C52: ='WAO Scenario Ag'!C23 -> 0 | D52: ='WAO Scenario Ag'!D23 -> 0 | E52: ='WAO Scenario Ag'!E23 -> 0 | F52: ='WAO Scenario Ag'!F23 -> 0 | G52: ='WAO Scenario Ag'!G23 -> 0 | H52: ='WAO Scenario Ag'!H23 -> 0 | I52: ='WAO Scenario Ag'!I23 -> 0 | ... CM52: ='WAO Scenario Ag'!CM23 -> 22021019
A54: ROW.Crop Land Alloc to Cellulosic Energy Crop | B54: ='WAO Scenario Ag'!B24 -> 0 | C54: ='WAO Scenario Ag'!C24 -> 0 | D54: ='WAO Scenario Ag'!D24 -> 0 | E54: ='WAO Scenario Ag'!E24 -> 0 | F54: ='WAO Scenario Ag'!F24 -> 0 | G54: ='WAO Scenario Ag'!G24 -> 0 | H54: ='WAO Scenario Ag'!H24 -> 0 | I54: ='WAO Scenario Ag'!I24 -> 0 | ... CM54: ='WAO Scenario Ag'!CM24 -> 61165926

Sheet LUC-2012-08-10-Run3
B1: 1961 | C1: 1962 | D1: 1963 | E1: 1964 | F1: 1965 | G1: 1966 | H1: 1967 | I1: 1968 | J1: 1969 | K1: 1970 | L1: 1971 | M1: 1972 | N1: 1973 | O1: 1974 | P1: 1975 | Q1: 1976 | R1: 1977 | S1: 1978 | T1: 1979 | U1: 1980 | V1: 1981 | W1: 1982 | X1: 1983 | Y1: 1984 | Z1: 1985 | AA1: 1986 | AB1: 1987 | AC1: 1988 | AD1: 1989 | AE1: 1990 | AF1: 1991 | AG1: 1992 | AH1: 1993 | AI1: 1994 | AJ1: 1995 | AK1: 1996 | AL1: 1997 | AM1: 1998 | AN1: 1999 | AO1: 2000 | AP1: 2001 | AQ1: 2002 | AR1: 2003 | AS1: 2004 | AT1: 2005 | AU1: 2006 | AV1: 2007 | AW1: 2008 | AX1: 2009 | AY1: 2010 | AZ1: 2011 | BA1: 2012 | BB1: 2013 | BC1: 2014 | BD1: 2015 | BE1: 2016 | BF1: 2017 | BG1: 2018 | BH1: 2019 | BI1: 2020 | BJ1: 2021 | BK1: 2022 | BL1: 2023 | BM1: 2024 | BN1: 2025 | BO1: 2026 | BP1: 2027 | BQ1: 2028 | BR1: 2029 | BS1: 2030 | BT1: 2031 | BU1: 2032 | BV1: 2033 | BW1: 2034 | BX1: 2035 | BY1: 2036 | BZ1: 2037 | CA1: 2038 | CB1: 2039 | CC1: 2040 | CD1: 2041 | CE1: 2042 | CF1: 2043 | CG1: 2044 | CH1: 2045 | CI1: 2046 | CJ1: 2047 | CK1: 2048 | CL1: 2049 | CM1: 2050
A2: ROW.per_capita_animal_product_demand_scenario | B2: 0 | C2: 0 | D2: 0 | E2: 0 | F2: 0 | G2: 0 | H2: 0 | I2: 0 | J2: 0 | K2: 0 | L2: 0 | M2: 0 | N2: 0 | O2: 0 | P2: 0 | Q2: 0 | R2: 0 | S2: 0 | T2: 0 | U2: 0 | V2: 0 | W2: 0 | X2: 0 | Y2: 0 | Z2: 0 | AA2: 0 | AB2: 0 | AC2: 0 | AD2: 0 | AE2: 0 | AF2: 1.0508416e-05 | AG2: 1.0527619e-05 | AH2: 1.0524145e-05 | AI2: 1.0522463e-05 | AJ2: 1.0522681e-05 | AK2: 1.0524798e-05 | AL2: 1.0528849e-05 | AM2: 1.0535258e-05 | AN2: 1.0544408e-05 | AO2: 1.0556611e-05 | AP2: 1.0571845e-05 | AQ2: 1.058998e-05 | AR2: 1.0610719e-05 | AS2: 1.0633798e-05 | AT2: 1.0658935e-05 | AU2: 1.0686103e-05 | AV2: 1.0706788e-05 | AW2: 1.0728456e-05 | AX2: 1.0751066e-05 | AY2: 1.0774564e-05 | AZ2: 1.079896e-05 | BA2: 1.0824296e-05 | BB2: 1.0850593e-05 | BC2: 1.0877941e-05 | BD2: 1.0906366e-05 | BE2: 1.0935893e-05 | BF2: 1.0966503e-05 | BG2: 1.0998166e-05 | BH2: 1.1030891e-05 | BI2: 1.1064614e-05 | BJ2: 1.1099353e-05 | BK2: 1.1135071e-05 | BL2: 1.1171769e-05 | BM2: 1.1209436e-05 | BN2: 1.1248082e-05 | BO2: 1.1287651e-05 | BP2: 1.1328155e-05 | BQ2: 1.1369577e-05 | BR2: 1.141197e-05 | BS2: 1.1455315e-05 | BT2: 1.1499618e-05 | BU2: 1.1544883e-05 | BV2: 1.1591015e-05 | BW2: 1.1637937e-05 | BX2: 1.1685595e-05 | BY2: 1.1733977e-05 | BZ2: 1.1783073e-05 | CA2: 1.1832927e-05 | CB2: 1.1883595e-05 | CC2: 1.1935118e-05 | CD2: 1.1987489e-05 | CE2: 1.2040728e-05 | CF2: 1.2094807e-05 | CG2: 1.2149717e-05 | CH2: 1.2205477e-05 | CI2: 1.2262068e-05 | CJ2: 1.2319521e-05 | CK2: 1.2377868e-05 | CL2: 1.2437151e-05 | CM2: 1.2497423e-05
A3: … | B3: 0 | C3: 0 | D3: 0 | E3: 0 | F3: 0 | G3: 0 | H3: 0 | I3: 0 | J3: 0 | K3: 0 | L3: 0 | M3: 0 | N3: 0 | O3: 0 | P3: 0 | Q3: 0 | R3: 0 | S3: 0 | T3: 0 | U3: 0 | V3: 0 | W3: 0 | X3: 0 | Y3: 0 | Z3: 0 | AA3: 0 | AB3: 0 | AC3: 0 | AD3: 0 | AE3: 0 | AF3: 7.000043e-05 | AG3: 7.0630961e-05 | AH3: 7.1066274e-05 | AI3: 7.150778e-05 | AJ3: 7.1952945e-05 | AK3: 7.2400862e-05 | AL3: 7.2852846e-05 | AM3: 7.3313274e-05 | AN3: 7.3787111e-05 | AO3: 7.4277958e-05 | AP3: 7.4785862e-05 | AQ3: 7.5308758e-05 | AR3: 7.584261e-05 | AS3: 7.638308e-05 | AT3: 7.6926134e-05 | AU3: 7.747081e-05 | AV3: 7.7835708e-05 | AW3: 7.8201471e-05 | AX3: 7.8567369e-05 | AY3: 7.8932911e-05 | AZ3: 7.9297852e-05 | BA3: 7.9662258e-05 | BB3: 8.0026719e-05 | BC3: 8.0392479e-05 | BD3: 8.0760241e-05 | BE3: 8.1130207e-05 | BF3: 8.150222e-05 | BG3: 8.1876587e-05 | BH3: 8.2253774e-05 | BI3: 8.2633806e-05 | BJ3: 8.3016912e-05 | BK3: 8.3402934e-05 | BL3: 8.3791548e-05 | BM3: 8.4182323e-05 | BN3: 8.457512e-05 | BO3: 8.4969478e-05 | BP3: 8.5365604e-05 | BQ3: 8.5763088e-05 | BR3: 8.6162015e-05 | BS3: 8.6562047e-05 | BT3: 8.6909832e-05 | BU3: 8.7260258e-05 | BV3: 8.761298e-05 | BW3: 8.796821e-05 | BX3: 8.8325924e-05 | BY3: 8.8686259e-05 | BZ3: 8.9048882e-05 | CA3: 8.9414054e-05 | CB3: 8.9781752e-05 | CC3: 9.0152e-05 | CD3: 9.0524661e-05 | CE3: 9.0899781e-05 | CF3: 9.1277331e-05 | CG3: 9.1657233e-05 | CH3: 9.2039603e-05 | CI3: 9.2424321e-05 | CJ3: 9.2811363e-05 | CK3: 9.3200498e-05 | CL3: 9.359191e-05 | CM3: 9.3985309e-05
A4: ... | B4: 0 | C4: 0 | D4: 0 | E4: 0 | F4: 0 | G4: 0 | H4: 0 | I4: 0 | J4: 0 | K4: 0 | L4: 0 | M4: 0 | N4: 0 | O4: 0 | P4: 0 | Q4: 0 | R4: 0 | S4: 0 | T4: 0 | U4: 0 | V4: 0 | W4: 0 | X4: 0 | Y4: 0 | Z4: 0 | AA4: 0 | AB4: 0 | AC4: 0 | AD4: 0 | AE4: 0 | AF4: 1.3228987e-05 | AG4: 1.3351004e-05 | AH4: 1.3448211e-05 | AI4: 1.3548882e-05 | AJ4: 1.365327e-05 | AK4: 1.3761501e-05 | AL4: 1.3873701e-05 | AM4: 1.3990475e-05 | AN4: 1.4112379e-05 | AO4: 1.4239928e-05 | AP4: 1.4373259e-05 | AQ4: 1.4512397e-05 | AR4: 1.4657165e-05 | AS4: 1.4807427e-05 | AT4: 1.4962997e-05 | AU4: 1.512402e-05 | AV4: 1.5129679e-05 | AW4: 1.5136668e-05 | AX4: 1.5144948e-05 | AY4: 1.5154462e-05 | AZ4: 1.5165243e-05 | BA4: 1.5177363e-05 | BB4: 1.5190865e-05 | BC4: 1.5205886e-05 | BD4: 1.5222476e-05 | BE4: 1.524069e-05 | BF4: 1.5260525e-05 | BG4: 1.528197e-05 | BH4: 1.5305073e-05 | BI4: 1.532978e-05 | BJ4: 1.5356154e-05 | BK4: 1.5384179e-05 | BL4: 1.541389e-05 | BM4: 1.5445307e-05 | BN4: 1.5478483e-05 | BO4: 1.5513378e-05 | BP4: 1.5550048e-05 | BQ4: 1.55885e-05 | BR4: 1.562883e-05 | BS4: 1.5671044e-05 | BT4: 1.5715176e-05 | BU4: 1.5761274e-05 | BV4: 1.5809239e-05 | BW4: 1.5859003e-05 | BX4: 1.5910525e-05 | BY4: 1.5963826e-05 | BZ4: 1.6018932e-05 | CA4: 1.6075946e-05 | CB4: 1.6134996e-05 | CC4: 1.6196177e-05 | CD4: 1.6259531e-05 | CE4: 1.6325138e-05 | CF4: 1.6393003e-05 | CG4: 1.6463171e-05 | CH4: 1.6535713e-05 | CI4: 1.6610676e-05 | CJ4: 1.6688154e-05 | CK4: 1.6768272e-05 | CL4: 1.6851146e-05 | CM4: 1.6936941e-05
A5: ... | B5: 0 | C5: 0 | D5: 0 | E5: 0 | F5: 0 | G5: 0 | H5: 0 | I5: 0 | J5: 0 | K5: 0 | L5: 0 | M5: 0 | N5: 0 | O5: 0 | P5: 0 | Q5: 0 | R5: 0 | S5: 0 | T5: 0 | U5: 0 | V5: 0 | W5: 0 | X5: 0 | Y5: 0 | Z5: 0 | AA5: 0 | AB5: 0 | AC5: 0 | AD5: 0 | AE5: 0 | AF5: 7.0121002e-06 | AG5: 7.2210894e-06 | AH5: 7.4202146e-06 | AI5: 7.6288203e-06 | AJ5: 7.8474397e-06 | AK5: 8.0765895e-06 | AL5: 8.3168765e-06 | AM5: 8.5692634e-06 | AN5: 8.8347261e-06 | AO5: 9.1142143e-06 | AP5: 9.4084017e-06 | AQ5: 9.7178946e-06 | AR5: 1.0043174e-05 | AS5: 1.0384788e-05 | AT5: 1.0743309e-05 | AU5: 1.1119589e-05 | AV5: 1.1213797e-05 | AW5: 1.1310063e-05 | AX5: 1.1408395e-05 | AY5: 1.1508781e-05 | AZ5: 1.161128e-05 | BA5: 1.1715979e-05 | BB5: 1.1822948e-05 | BC5: 1.1932326e-05 | BD5: 1.2044192e-05 | BE5: 1.2158625e-05 | BF5: 1.2275664e-05 | BG5: 1.2395333e-05 | BH5: 1.2517707e-05 | BI5: 1.2642778e-05 | BJ5: 1.2770631e-05 | BK5: 1.2901294e-05 | BL5: 1.3034831e-05 | BM5: 1.31713e-05 | BN5: 1.3310783e-05 | BO5: 1.3453288e-05 | BP5: 1.3598903e-05 | BQ5: 1.374768e-05 | BR5: 1.3899751e-05 | BS5: 1.405517e-05 | BT5: 1.4214019e-05 | BU5: 1.4376384e-05 | BV5: 1.4542238e-05 | BW5: 1.4711574e-05 | BX5: 1.488441e-05 | BY5: 1.5060818e-05 | BZ5: 1.5240875e-05 | CA5: 1.5424723e-05 | CB5: 1.5612527e-05 | CC5: 1.5804431e-05 | CD5: 1.6000528e-05 | CE5: 1.6200948e-05 | CF5: 1.6405763e-05 | CG5: 1.6615072e-05 | CH5: 1.6829008e-05 | CI5: 1.704767e-05 | CJ5: 1.7271214e-05 | CK5: 1.749981e-05 | CL5: 1.7733636e-05 | CM5: 1.7972898e-05
A7: ROW.per_capita_commodity_crop_demand_scenario | B7: 0 | C7: 0 | D7: 0 | E7: 0 | F7: 0 | G7: 0 | H7: 0 | I7: 0 | J7: 0 | K7: 0 | L7: 0 | M7: 0 | N7: 0 | O7: 0 | P7: 0 | Q7: 0 | R7: 0 | S7: 0 | T7: 0 | U7: 0 | V7: 0 | W7: 0 | X7: 0 | Y7: 0 | Z7: 0 | AA7: 0 | AB7: 0 | AC7: 0 | AD7: 0 | AE7: 0 | AF7: 3.6843337e-05 | AG7: 3.6790336e-05 | AH7: 3.6735361e-05 | AI7: 3.6679542e-05 | AJ7: 3.6623172e-05 | AK7: 3.6566333e-05 | AL7: 3.6509049e-05 | AM7: 3.6451466e-05 | AN7: 3.6393772e-05 | AO7: 3.6336058e-05 | AP7: 3.6278481e-05 | AQ7: 3.6221086e-05 | AR7: 3.6163908e-05 | AS7: 3.6106967e-05 | AT7: 3.6050252e-05 | AU7: 3.5993816e-05 | AV7: 3.6240761e-05 | AW7: 3.6488319e-05 | AX7: 3.6736402e-05 | AY7: 3.6984942e-05 | AZ7: 3.7233916e-05 | BA7: 3.7483341e-05 | BB7: 3.7733265e-05 | BC7: 3.7983772e-05 | BD7: 3.8234915e-05 | BE7: 3.8486709e-05 | BF7: 3.8739113e-05 | BG7: 3.8992096e-05 | BH7: 3.9245624e-05 | BI7: 3.9499679e-05 | BJ7: 3.975424e-05 | BK7: 4.0009324e-05 | BL7: 4.0264903e-05 | BM7: 4.052098e-05 | BN7: 4.0777533e-05 | BO7: 4.103456e-05 | BP7: 4.1292071e-05 | BQ7: 4.1550085e-05 | BR7: 4.1808652e-05 | BS7: 4.2067778e-05 | BT7: 4.2057327e-05 | BU7: 4.204757e-05 | BV7: 4.2038516e-05 | BW7: 4.2030165e-05 | BX7: 4.2022518e-05 | BY7: 4.2015579e-05 | BZ7: 4.200935e-05 | CA7: 4.2003839e-05 | CB7: 4.1999036e-05 | CC7: 4.1994954e-05 | CD7: 4.1991584e-05 | CE7: 4.1988923e-05 | CF7: 4.1986974e-05 | CG7: 4.1985725e-05 | CH7: 4.1985181e-05 | CI7: 4.1985334e-05 | CJ7: 4.198618e-05 | CK7: 4.1987716e-05 | CL7: 4.1989957e-05 | CM7: 4.1992888e-05
A8: … | B8: 0 | C8: 0 | D8: 0 | E8: 0 | F8: 0 | G8: 0 | H8: 0 | I8: 0 | J8: 0 | K8: 0 | L8: 0 | M8: 0 | N8: 0 | O8: 0 | P8: 0 | Q8: 0 | R8: 0 | S8: 0 | T8: 0 | U8: 0 | V8: 0 | W8: 0 | X8: 0 | Y8: 0 | Z8: 0 | AA8: 0 | AB8: 0 | AC8: 0 | AD8: 0 | AE8: 0 | AF8: 5.2769166e-05 | AG8: 5.2693256e-05 | AH8: 5.2614517e-05 | AI8: 5.253457e-05 | AJ8: 5.2453834e-05 | AK8: 5.2372426e-05 | AL8: 5.229038e-05 | AM8: 5.2207906e-05 | AN8: 5.2125274e-05 | AO8: 5.2042613e-05 | AP8: 5.1960147e-05 | AQ8: 5.1877943e-05 | AR8: 5.1796049e-05 | AS8: 5.1714495e-05 | AT8: 5.1633265e-05 | AU8: 5.1552433e-05 | AV8: 5.1426673e-05 | AW8: 5.130194e-05 | AX8: 5.1178111e-05 | AY8: 5.1055095e-05 | AZ8: 5.0932864e-05 | BA8: 5.0811445e-05 | BB8: 5.069091e-05 | BC8: 5.0571373e-05 | BD8: 5.0452905e-05 | BE8: 5.0335522e-05 | BF8: 5.0219168e-05 | BG8: 5.0103801e-05 | BH8: 4.9989378e-05 | BI8: 4.9875874e-05 | BJ8: 4.9763265e-05 | BK8: 4.9651571e-05 | BL8: 4.9540761e-05 | BM8: 4.9430839e-05 | BN8: 4.9321783e-05 | BO8: 4.9213588e-05 | BP8: 4.9106274e-05 | BQ8: 4.8999864e-05 | BR8: 4.8894421e-05 | BS8: 4.8789948e-05 | BT8: 4.8777827e-05 | BU8: 4.8766511e-05 | BV8: 4.8756011e-05 | BW8: 4.8746326e-05 | BX8: 4.8737456e-05 | BY8: 4.8729408e-05 | BZ8: 4.8722184e-05 | CA8: 4.8715793e-05 | CB8: 4.8710222e-05 | CC8: 4.8705488e-05 | CD8: 4.8701579e-05 | CE8: 4.8698493e-05 | CF8: 4.8696233e-05 | CG8: 4.8694784e-05 | CH8: 4.8694153e-05 | CI8: 4.8694331e-05 | CJ8: 4.8695312e-05 | CK8: 4.8697093e-05 | CL8: 4.8699693e-05 | CM8: 4.8703092e-05
A9: … | B9: 0 | C9: 0 | D9: 0 | E9: 0 | F9: 0 | G9: 0 | H9: 0 | I9: 0 | J9: 0 | K9: 0 | L9: 0 | M9: 0 | N9: 0 | O9: 0 | P9: 0 | Q9: 0 | R9: 0 | S9: 0 | T9: 0 | U9: 0 | V9: 0 | W9: 0 | X9: 0 | Y9: 0 | Z9: 0 | AA9: 0 | AB9: 0 | AC9: 0 | AD9: 0 | AE9: 0 | AF9: 3.7556434e-05 | AG9: 3.7502407e-05 | AH9: 3.7446368e-05 | AI9: 3.7389469e-05 | AJ9: 3.7332008e-05 | AK9: 3.7274069e-05 | AL9: 3.7215676e-05 | AM9: 3.7156978e-05 | AN9: 3.7098168e-05 | AO9: 3.7039337e-05 | AP9: 3.6980645e-05 | AQ9: 3.6922139e-05 | AR9: 3.6863855e-05 | AS9: 3.6805812e-05 | AT9: 3.6747999e-05 | AU9: 3.669047e-05 | AV9: 3.6554387e-05 | AW9: 3.641905e-05 | AX9: 3.628437e-05 | AY9: 3.6150285e-05 | AZ9: 3.6016773e-05 | BA9: 3.5883857e-05 | BB9: 3.5751585e-05 | BC9: 3.562004e-05 | BD9: 3.5489271e-05 | BE9: 3.5359289e-05 | BF9: 3.5230055e-05 | BG9: 3.5101538e-05 | BH9: 3.4973709e-05 | BI9: 3.484655e-05 | BJ9: 3.4720044e-05 | BK9: 3.4594207e-05 | BL9: 3.4469014e-05 | BM9: 3.4344472e-05 | BN9: 3.4220562e-05 | BO9: 3.4097284e-05 | BP9: 3.3974651e-05 | BQ9: 3.385268e-05 | BR9: 3.3731412e-05 | BS9: 3.3610853e-05 | BT9: 3.3602503e-05 | BU9: 3.3594708e-05 | BV9: 3.3587474e-05 | BW9: 3.3580802e-05 | BX9: 3.3574692e-05 | BY9: 3.3569148e-05 | BZ9: 3.3564171e-05 | CA9: 3.3559769e-05 | CB9: 3.3555931e-05 | CC9: 3.355267e-05 | CD9: 3.3549977e-05 | CE9: 3.3547851e-05 | CF9: 3.3546294e-05 | CG9: 3.3545296e-05 | CH9: 3.3544861e-05 | CI9: 3.3544983e-05 | CJ9: 3.3545659e-05 | CK9: 3.3546886e-05 | CL9: 3.3548677e-05 | CM9: 3.3551019e-05
A10: … | B10: 0 | C10: 0 | D10: 0 | E10: 0 | F10: 0 | G10: 0 | H10: 0 | I10: 0 | J10: 0 | K10: 0 | L10: 0 | M10: 0 | N10: 0 | O10: 0 | P10: 0 | Q10: 0 | R10: 0 | S10: 0 | T10: 0 | U10: 0 | V10: 0 | W10: 0 | X10: 0 | Y10: 0 | Z10: 0 | AA10: 0 | AB10: 0 | AC10: 0 | AD10: 0 | AE10: 0 | AF10: 3.2802455e-05 | AG10: 3.2755267e-05 | AH10: 3.2706321e-05 | AI10: 3.2656625e-05 | AJ10: 3.2606437e-05 | AK10: 3.2555832e-05 | AL10: 3.2504831e-05 | AM10: 3.2453563e-05 | AN10: 3.2402197e-05 | AO10: 3.2350813e-05 | AP10: 3.2299551e-05 | AQ10: 3.2248451e-05 | AR10: 3.2197544e-05 | AS10: 3.2146848e-05 | AT10: 3.2096354e-05 | AU10: 3.2046107e-05 | AV10: 3.2141497e-05 | AW10: 3.2237472e-05 | AX10: 3.2333953e-05 | AY10: 3.2430883e-05 | AZ10: 3.2528241e-05 | BA10: 3.2626044e-05 | BB10: 3.2724335e-05 | BC10: 3.2823187e-05 | BD10: 3.2922647e-05 | BE10: 3.3022726e-05 | BF10: 3.3123389e-05 | BG10: 3.3224607e-05 | BH10: 3.3326354e-05 | BI10: 3.3428612e-05 | BJ10: 3.3531365e-05 | BK10: 3.3634627e-05 | BL10: 3.3738375e-05 | BM10: 3.3842612e-05 | BN10: 3.394732e-05 | BO10: 3.4052497e-05 | BP10: 3.4158155e-05 | BQ10: 3.4264307e-05 | BR10: 3.4370998e-05 | BS10: 3.447823e-05 | BT10: 3.4469665e-05 | BU10: 3.4461668e-05 | BV10: 3.4454248e-05 | BW10: 3.4447403e-05 | BX10: 3.4441136e-05 | BY10: 3.4435448e-05 | BZ10: 3.4430343e-05 | CA10: 3.4425827e-05 | CB10: 3.442189e-05 | CC10: 3.4418545e-05 | CD10: 3.4415782e-05 | CE10: 3.4413602e-05 | CF10: 3.4412005e-05 | CG10: 3.4410981e-05 | CH10: 3.4410535e-05 | CI10: 3.441066e-05 | CJ10: 3.4411354e-05 | CK10: 3.4412612e-05 | CL10: 3.441445e-05 | CM10: 3.4416852e-05
A11: … | B11: 0 | C11: 0 | D11: 0 | E11: 0 | F11: 0 | G11: 0 | H11: 0 | I11: 0 | J11: 0 | K11: 0 | L11: 0 | M11: 0 | N11: 0 | O11: 0 | P11: 0 | Q11: 0 | R11: 0 | S11: 0 | T11: 0 | U11: 0 | V11: 0 | W11: 0 | X11: 0 | Y11: 0 | Z11: 0 | AA11: 0 | AB11: 0 | AC11: 0 | AD11: 0 | AE11: 0 | AF11: 9.8542367e-06 | AG11: 9.9823314e-06 | AH11: 1.0100377e-05 | AI11: 1.0217954e-05 | AJ11: 1.0335036e-05 | AK11: 1.045161e-05 | AL11: 1.0567721e-05 | AM11: 1.0683585e-05 | AN11: 1.0799445e-05 | AO11: 1.0915504e-05 | AP11: 1.1031807e-05 | AQ11: 1.114831e-05 | AR11: 1.126487e-05 | AS11: 1.1381328e-05 | AT11: 1.1497512e-05 | AU11: 1.1613397e-05 | AV11: 1.1713799e-05 | AW11: 1.181447e-05 | AX11: 1.1915346e-05 | AY11: 1.2016381e-05 | AZ11: 1.2117558e-05 | BA11: 1.2218891e-05 | BB11: 1.2320406e-05 | BC11: 1.2422163e-05 | BD11: 1.2524187e-05 | BE11: 1.2626484e-05 | BF11: 1.2729031e-05 | BG11: 1.2831825e-05 | BH11: 1.2934868e-05 | BI11: 1.3038142e-05 | BJ11: 1.3141646e-05 | BK11: 1.3245362e-05 | BL11: 1.3349273e-05 | BM11: 1.3453362e-05 | BN11: 1.3557618e-05 | BO11: 1.3662013e-05 | BP11: 1.3766548e-05 | BQ11: 1.3871201e-05 | BR11: 1.3975979e-05 | BS11: 1.4080865e-05 | BT11: 1.4176706e-05 | BU11: 1.4272898e-05 | BV11: 1.4369405e-05 | BW11: 1.4466221e-05 | BX11: 1.4563333e-05 | BY11: 1.4660743e-05 | BZ11: 1.475844e-05 | CA11: 1.4856433e-05 | CB11: 1.4954724e-05 | CC11: 1.5053311e-05 | CD11: 1.5152187e-05 | CE11: 1.5251348e-05 | CF11: 1.5350789e-05 | CG11: 1.5450503e-05 | CH11: 1.5550494e-05 | CI11: 1.5650749e-05 | CJ11: 1.5751267e-05 | CK11: 1.5852033e-05 | CL11: 1.5953047e-05 | CM11: 1.605429e-05
