Workbook

Sheet Model_Inputs
A1: Data name | B1: Global data | C1: US data | D1: ROW data | E1: Units | F1: Description | G1: Stella Variable Name | H1: Source | I1: Comments
A2: Total Cropland | B2: ='FAO-data-calculations'!C72 -> 1462810 | C2: ='FAO-data-calculations'!C78 -> 153687 | D2: ='FAO-data-calculations'!C80 -> 1309123 | E2: 1000 ha | F2: For Global data, permanent crops plus 95% of arable land. For USA, permanent crops plus 86% of arable land | G2: R1.INIT_Crop_Land | H2: FAOSTAT; | I2: http://www.fao.org/docrep/010/ag049e/AG049E03.htm
A3: Total Pastureland | B3: ='FAO-data-calculations'!C88 -> 3442212.6 | C3: ='FAO-data-calculations'!C95 -> 262380 | D3: ='FAO-data-calculations'!C97 -> 3179832.6 | E3: 1000 ha | F3: For global data, permanent pasture plus 5% of arable land. For USA, permanent pasture plus 14% of arable land | G3: R1.INIT_Pasture_Land | H3: FAOSTAT; | I3: http://www.fao.org/docrep/010/ag049e/AG049E03.htm
A4: Total Forestland | B4: ='FAO-data-calculations'!C54 -> 3608759.6 | C4: ='FAO-data-calculations'!C58 -> 279785.84 | D4: ='FAO-data-calculations'!C60 -> 3328973.7 | E4: 1000 ha | F4: Total forests from FAO minus protected forests | G4: R1.INIT_Avail_Land | H4: FAOSTAT; | I4: http://www.fao.org/forestry/fra/fra2005/en/ | J4: http://fia.fs.fed.us/library/briefings-summaries-overviews/docs/ForestFactsMetric.pdf
A6: Percent cropland naturally forest | B6: ='potential-natural-veg-calcs'!$E$39 -> 0.61935951 | C6: ='potential-natural-veg-calcs'!$G$39 -> 0.614 | D6: ='potential-natural-veg-calcs'!$I$39 -> 0.62054611 | E6: % | F6: State to which cropland will naturally revert | H6: Cha 1997 | I6: Assumed all land uses would similarly revert to these percentages; no overlaying of existing land uses with natural land types occurred in this analysis. North American data is used in place of USA-specific data | J6: http://www.springerlink.com/content/a76750xj2r28l161/fulltext.pdf
A7: Percent cropland naturally pastureland | B7: ='potential-natural-veg-calcs'!$F$39 -> 0.38064049 | C7: ='potential-natural-veg-calcs'!$H$39 -> 0.386 | D7: ='potential-natural-veg-calcs'!$J$39 -> 0.37945389 | E7: % | F7: State to which cropland will naturally revert | H7: Cha 1997 | I7: Assumed all land uses would similarly revert to these percentages; no overlaying of existing land uses with natural land types occurred in this analysis. North American data is used in place of USA-specific data | J7: http://www.springerlink.com/content/a76750xj2r28l161/fulltext.pdf
A8: Cropland naturally forest | B8: ='potential-natural-veg-calcs'!E44 -> 906005.26 | C8: ='potential-natural-veg-calcs'!E50 -> 94363.818 | D8: ='potential-natural-veg-calcs'!E53 -> 811641.45 | E8: 1000 ha
A9: Cropland naturally pastureland | B9: ='potential-natural-veg-calcs'!E45 -> 556804.7 | C9: ='potential-natural-veg-calcs'!E51 -> 59323.182 | D9: ='potential-natural-veg-calcs'!E54 -> 497481.52 | E9: 1000 ha
A11: Percent pastureland naturally forest | B11: ='potential-natural-veg-calcs'!$E$39 -> 0.61935951 | C11: ='potential-natural-veg-calcs'!$G$39 -> 0.614 | D11: ='potential-natural-veg-calcs'!$I$39 -> 0.62054611 | E11: % | F11: State to which pastureland will naturally revert | H11: Cha 1997 | I11: Assumed all land uses would similarly revert to these percentages; no overlaying of existing land uses with natural land types occurred in this analysis. North American data is used in place of USA-specific data | J11: http://www.springerlink.com/content/a76750xj2r28l161/fulltext.pdf
A12: Percent pastureland naturally pastureland | B12: ='potential-natural-veg-calcs'!$F$39 -> 0.38064049 | C12: ='potential-natural-veg-calcs'!$H$39 -> 0.386 | D12: ='potential-natural-veg-calcs'!$J$39 -> 0.37945389 | E12: % | F12: State to which pastureland will naturally revert | H12: Cha 1997 | I12: Assumed all land uses would similarly revert to these percentages; no overlaying of existing land uses with natural land types occurred in this analysis. North American data is used in place of USA-specific data | J12: http://www.springerlink.com/content/a76750xj2r28l161/fulltext.pdf
A13: Pastureland naturally forest | B13: ='potential-natural-veg-calcs'!E60 -> 2131967.1 | C13: ='potential-natural-veg-calcs'!E66 -> 161101.32 | D13: ='potential-natural-veg-calcs'!E69 -> 1970865.8 | E13: 1000 ha | F13: State to which pastureland will naturally revert
A14: Pastureland naturally pastureland | B14: ='potential-natural-veg-calcs'!E61 -> 1310245.5 | C14: ='potential-natural-veg-calcs'!E67 -> 101278.68 | D14: ='potential-natural-veg-calcs'!E70 -> 1208966.8 | E14: 1000 ha | F14: State to which pastureland will naturally revert
A20: All data in 1000 ha

Sheet FAO-data-calculations
A1: Data retrieved from: http://faostat.fao.org/site/377/default.aspx#ancor
A2: FAO Category | B2: US data available? (2002 data) | C2: US data available? (2006 data) | D2: World data available? (2006 data) | E2: ROW--Calculated: World - USA (2006 data) | F2: Units | I2: Relationships | J2: Notes
A3: Country area | B3: 963203 | C3: 963203 | D3: 13439366 | E3: =D3-C3 -> 12476163 | F3: 1000 ha | I3: Sum of arable land, permanent crops, permanent meadows and pastures, forest area, other land, and inland water
A4: Land area | B4: 916192 | C4: 916192 | D4: 13004931 | E4: =D4-C4 -> 12088739 | F4: 1000 ha | I4: Sum of arable land, permanent crops, permanent meadows and pastures, forest area, and other land
A5: Agricultural area | B5: 416067 | C5: 411030 | D5: 4905022.5 | E5: =D5-C5 -> 4493992.5 | F5: 1000 ha | I5: Sum of arable land, permanent crops, and permanent meadows and pastures
A6: Agricultural area organic, total | D6: 9788.52 | E6: =D6-C6 -> 9788.52 | F6: 1000 ha | I6: =C5/C4 -> 0.44862867 | J6: =D5/D4 -> 0.37716636
A7: Agricultural area certified organic | D7: 8985.26 | E7: =D7-C7 -> 8985.26 | F7: 1000 ha
A8: Agricultural area in conversion to organic | D8: 485.9 | E8: =D8-C8 -> 485.9 | F8: 1000 ha
A9: Agricultural area irrigated | E9: =D9-C9 -> 0 | F9: 1000 ha
A10: Arable land and Permanent crops | B10: 178710 | C10: 173230 | D10: 1532267.9 | E10: =D10-C10 -> 1359037.9 | F10: 1000 ha | I10: Sum of arable land and permanent crops
A11: Arable land | B11: 175980 | C11: 170530 | D11: 1389157.6 | E11: =D11-C11 -> 1218627.6 | F11: 1000 ha | I11: Raw number | J11: Listed as "raw" but really is the sum of temporary crops, temporary meadows and pasture, and fallow land. See definitions
A12: Arable land organic, total | D12: 449.49 | E12: =D12-C12 -> 449.49 | F12: 1000 ha
A13: Arable land area certified organic | D13: 282.5 | E13: =D13-C13 -> 282.5 | F13: 1000 ha
A14: Arable land area in conversion to organic | D14: 147.9 | E14: =D14-C14 -> 147.9 | F14: 1000 ha
A15: Temporary crops | B15: 134863 | E15: =D15-C15 -> 0 | F15: 1000 ha | J15: These data are available for only select countries and select years
A16: Temp. crops irrigated | E16: =D16-C16 -> 0 | F16: 1000 ha
A17: Temp. crops non-irrigated | E17: =D17-C17 -> 0 | F17: 1000 ha
A18: Temporary meadows and pastures | B18: 25023 | E18: =D18-C18 -> 0 | F18: 1000 ha | J18: These data are available for only select countries and select years
A19: Temp. meadows & pastures irrigated | E19: =D19-C19 -> 0 | F19: 1000 ha
A20: Temp. meadows & pastures non-irrig. | E20: =D20-C20 -> 0 | F20: 1000 ha
A21: Fallow land | B21: 16094 | E21: =D21-C21 -> 0 | F21: 1000 ha | J21: These data are available for only select countries and select years
A22: Permanent crops | B22: 2730 | C22: 2700 | D22: 143110.2 | E22: =D22-C22 -> 140410.2 | F22: 1000 ha | I22: Raw number
A23: Permanent crops organic, total | D23: 73.27 | E23: =D23-C23 -> 73.27 | F23: 1000 ha
A24: Permanent crops area certified organic | D24: 22.54 | E24: =D24-C24 -> 22.54 | F24: 1000 ha
A25: Permanent crops area in conversion to organic | D25: 49.37 | E25: =D25-C25 -> 49.37 | F25: 1000 ha
A26: Perm. crops irrigated | E26: =D26-C26 -> 0 | F26: 1000 ha
A27: Perm. crops non-irrigated | E27: =D27-C27 -> 0 | F27: 1000 ha
A28: Permanent meadows and pastures | B28: 237357 | C28: 237800 | D28: 3372754.7 | E28: =D28-C28 -> 3134954.7 | F28: 1000 ha | I28: Raw number
A29: Permanent meadows and pastures organic, total | D29: 693.31 | E29: =D29-C29 -> 693.31 | F29: 1000 ha
A30: Permanent meadows and pastures area certified organic | D30: 463.03 | E30: =D30-C30 -> 463.03 | F30: 1000 ha
A31: Permanent meadows and pastures area in conversion to organic | D31: 129.88 | E31: =D31-C31 -> 129.88 | F31: 1000 ha
A32: Perm. meadows & pastures - Cultivated | E32: =D32-C32 -> 0 | F32: 1000 ha | J32: These data are available for only select countries and select years
A33: Perm. meadows & pastures Cult. & irrig | E33: =D33-C33 -> 0 | F33: 1000 ha
A34: Perm. meadows & pastures - Nat. grown | E34: =D34-C34 -> 0 | F34: 1000 ha | J34: These data are available for only select countries and select years
A35: Perm. meadows & pastures Cult. non-irrig | E35: =D35-C35 -> 0 | F35: 1000 ha
A36: Forest area | B36: 300960.2 | C36: 302490.8 | D36: 4054786.1 | E36: =D36-C36 -> 3752295.3 | F36: 1000 ha | I36: Raw number
A37: Other land | B37: 199164.8 | C37: 202671.2 | D37: 4057645.3 | E37: =D37-C37 -> 3854974.1 | F37: 1000 ha | I37: Raw number
A38: Inland water | B38: 47011 | C38: 47011 | D38: 434435.3 | E38: =D38-C38 -> 387424.3 | F38: 1000 ha | I38: Raw number
A39: Total area equipped for irrigation | B39: 22384 | C39: 22700 | D39: 303104.5 | E39: =D39-C39 -> 280404.5 | F39: 1000 ha | I39: Raw number
A42: Protected Lands and Total Available Forests | B42: Unit | E42: Source
...

Sheet potential-natural-veg-calcs
A1: Area % | C1: North America | D1: South America | E1: Europe | F1: Africa | G1: Asia | H1: Oceania | M1: Source: Cha 1997
A2: Tropical rain forest | B2: TRF | C2: 0.8 | D2: 13.5 | F2: 0.9 | G2: 3.5 | H2: 4 | M2: http://www.springerlink.com/content/a76750xj2r28l161/fulltext.pdf
A3: Tropical seasonal forest | B3: TSF | C3: 1.7 | D3: 10.5 | F3: 3.4 | G3: 3.9 | H3: 2.6
A4: subtropical rain forest | B4: SRF | C4: 0.9 | D4: 11.1 | F4: 2.2 | G4: 3 | H4: 4.2
A5: subtropical seasonal forest | B5: SSF | C5: 2 | D5: 21.2 | F5: 11.6 | G5: 2.7 | H5: 1.1
A6: Temperate rain forest | B6: TMF | C6: 19.7 | D6: 16.5 | E6: 43.5 | F6: 1.9 | G6: 8.6 | H6: 3.1
A7: subpolar forest | B7: SPF | C7: 17.9 | D7: 2.8 | E7: 28.2 | G7: 7.4 | H7: 0.9
A8: woodlands | B8: WLD | C8: 18.4 | D8: 17 | E8: 22.2 | F8: 32.1 | G8: 25.1 | H8: 20.1
A9: steppe | B9: STP | C9: 5.5 | D9: 1.7 | E9: 1.4 | F9: 5.1 | G9: 19 | H9: 6.9
A10: thorn shrub | B10: THS | C10: 1.9 | D10: 0.4 | F10: 16.1 | G10: 2.3 | H10: 27
A11: desert | B11: DST | C11: 0.7 | D11: 0.6 | F11: 26.7 | G11: 8.8 | H11: 30.3
A12: tundra | B12: TUN | C12: 18.5 | D12: 0.9 | E12: 3.2 | F12: 0.1 | G12: 12.2
A13: ice | B13: ICE | C13: 12 | D13: 3.8 | E13: 1.4 | G13: 3.5
B15: Total Gha | C15: 2.473 | D15: 1.793 | E15: 1.057 | F15: 2.998 | G15: 4.407 | H15: 0.911 | J15: =SUM(C15:H15) -> 13.639
C17: North America | D17: South America | E17: Europe | F17: Africa | G17: Asia | H17: Oceania
A18: Tropical rain forest | B18: TRF | C18: =C2*C$15/100 -> 0.019784 | D18: =D2*D$15/100 -> 0.242055 | E18: =E2*E$15/100 -> 0 | F18: =F2*F$15/100 -> 0.026982 | G18: =G2*G$15/100 -> 0.154245 | H18: =H2*H$15/100 -> 0.03644 | J18: =SUM(C18:H18) -> 0.479506
A19: Tropical seasonal forest | B19: TSF | C19: =C3*C$15/100 -> 0.042041 | D19: =D3*D$15/100 -> 0.188265 | E19: =E3*E$15/100 -> 0 | F19: =F3*F$15/100 -> 0.101932 | G19: =G3*G$15/100 -> 0.171873 | H19: =H3*H$15/100 -> 0.023686 | J19: =SUM(C19:H19) -> 0.527797
A20: subtropical rain forest | B20: SRF | C20: =C4*C$15/100 -> 0.022257 | D20: =D4*D$15/100 -> 0.199023 | E20: =E4*E$15/100 -> 0 | F20: =F4*F$15/100 -> 0.065956 | G20: =G4*G$15/100 -> 0.13221 | H20: =H4*H$15/100 -> 0.038262 | J20: =SUM(C20:H20) -> 0.457708
A21: subtropical seasonal forest | B21: SSF | C21: =C5*C$15/100 -> 0.04946 | D21: =D5*D$15/100 -> 0.380116 | E21: =E5*E$15/100 -> 0 | F21: =F5*F$15/100 -> 0.347768 | G21: =G5*G$15/100 -> 0.118989 | H21: =H5*H$15/100 -> 0.010021 | J21: =SUM(C21:H21) -> 0.906354
A22: Temperate rain forest | B22: TMF | C22: =C6*C$15/100 -> 0.487181 | D22: =D6*D$15/100 -> 0.295845 | E22: =E6*E$15/100 -> 0.459795 | F22: =F6*F$15/100 -> 0.056962 | G22: =G6*G$15/100 -> 0.379002 | H22: =H6*H$15/100 -> 0.028241 | J22: =SUM(C22:H22) -> 1.707026
A23: subpolar forest | B23: SPF | C23: =C7*C$15/100 -> 0.442667 | D23: =D7*D$15/100 -> 0.050204 | E23: =E7*E$15/100 -> 0.298074 | F23: =F7*F$15/100 -> 0 | G23: =G7*G$15/100 -> 0.326118 | H23: =H7*H$15/100 -> 0.008199 | J23: =SUM(C23:H23) -> 1.125262
A24: woodlands | B24: WLD | C24: =C8*C$15/100 -> 0.455032 | D24: =D8*D$15/100 -> 0.30481 | E24: =E8*E$15/100 -> 0.234654 | F24: =F8*F$15/100 -> 0.962358 | G24: =G8*G$15/100 -> 1.106157 | H24: =H8*H$15/100 -> 0.183111 | J24: =SUM(C24:H24) -> 3.246122
A25: steppe | B25: STP | C25: =C9*C$15/100 -> 0.136015 | D25: =D9*D$15/100 -> 0.030481 | E25: =E9*E$15/100 -> 0.014798 | F25: =F9*F$15/100 -> 0.152898 | G25: =G9*G$15/100 -> 0.83733 | H25: =H9*H$15/100 -> 0.062859 | J25: =SUM(C25:H25) -> 1.234381
A26: thorn shrub | B26: THS | C26: =C10*C$15/100 -> 0.046987 | D26: =D10*D$15/100 -> 0.007172 | E26: =E10*E$15/100 -> 0 | F26: =F10*F$15/100 -> 0.482678 | G26: =G10*G$15/100 -> 0.101361 | H26: =H10*H$15/100 -> 0.24597 | J26: =SUM(C26:H26) -> 0.884168
A27: desert | B27: DST | C27: =C11*C$15/100 -> 0.017311 | D27: =D11*D$15/100 -> 0.010758 | E27: =E11*E$15/100 -> 0 | F27: =F11*F$15/100 -> 0.800466 | G27: =G11*G$15/100 -> 0.387816 | H27: =H11*H$15/100 -> 0.276033 | J27: =SUM(C27:H27) -> 1.492384
A28: tundra | B28: TUN | C28: =C12*C$15/100 -> 0.457505 | D28: =D12*D$15/100 -> 0.016137 | E28: =E12*E$15/100 -> 0.033824 | F28: =F12*F$15/100 -> 0.002998 | G28: =G12*G$15/100 -> 0.537654 | H28: =H12*H$15/100 -> 0 | J28: =SUM(C28:H28) -> 1.048118
A29: ice | B29: ICE | C29: =C13*C$15/100 -> 0.29676 | D29: =D13*D$15/100 -> 0.068134 | E29: =E13*E$15/100 -> 0.014798 | F29: =F13*F$15/100 -> 0 | G29: =G13*G$15/100 -> 0.154245 | H29: =H13*H$15/100 -> 0 | J29: =SUM(C29:H29) -> 0.533937
A32: World total area | C32: =SUM(J18:J29) -> 13.642763 | D32: Gha
A33: NA total area | C33: =SUM(C18:C29) -> 2.473 | D33: Gha
A34: World-NA total area | C34: =C32-C33 -> 11.169763 | D34: Gha
E37: World Forest | F37: World Grassland | G37: NA Forest | H37: NA Grassland | I37: World-NA Forest | J37: World-NA Grassland
A38: If woodland counts as forest: | D38: Gha | E38: =SUM(J18:J24) -> 8.449775 | F38: =SUM(J25:J29) -> 5.192988 | G38: =SUM(C18:C24) -> 1.518422 | H38: =SUM(C25:C29) -> 0.954578 | I38: =E38-G38 -> 6.931353 | J38: =F38-H38 -> 4.23841
D39: % | E39: =E38/C32 -> 0.61935951 | F39: =F38/C32 -> 0.38064049 | G39: =G38/C33 -> 0.614 | H39: =H38/C33 -> 0.386 | I39: =I38/C34 -> 0.62054611 | J39: =J38/C34 -> 0.37945389
A41: global cropland | E41: ='FAO-data-calculations'!C72 -> 1462810 | F41: 1000 ha
A42: percent cropland naturally forest | E42: =E39 -> 0.61935951
A43: percent cropland naturally pastureland | E43: =F39 -> 0.38064049
A44: global cropland naturally forest | E44: =E42*E41 -> 906005.26 | F44: 1000 ha
A45: global cropland naturally pastureland | E45: =E43*E41 -> 556804.7 | F45: 1000 ha
A47: usa cropland | E47: ='FAO-data-calculations'!C78 -> 153687 | F47: 1000 ha
A48: percent cropland naturally forest | E48: =G39 -> 0.614
...

Sheet FAO-definitions
A1: Defintions from: http://faostat.fao.org/site/379/default.aspx
A2: Arable land | B2: Arable land is the land under temporary agricultural crops (multiple-cropped areas are counted only once), temporary meadows for mowing or pasture, land under market and kitchen gardens and land temporarily fallow (less than five years). The abandoned land resulting from shifting cultivation is not included in this category. Data for “Arable land” are not meant to indicate the amount of land that is potentially cultivable. Data are expressed in 1000 hectares.
A3: Permanent crops | B3: Permanent crops is the land cultivated with long-term crops which do not have to be replanted for several years (such as cocoa and coffee); land under trees and shrubs producing flowers, such as roses and jasmine; and nurseries (except those for forest trees, which should be classified under "forest"). Permanent meadows and pastures are excluded from land under permanent crops. Data are expressed in 1000 hectares.
A4: Permanent meadows and pastures | B4: Permanent meadows and pastures is the land used permanently (five years or more) to grow herbaceous forage crops, either cultivated or growing wild (wild prairie or grazing land). Data are expressed in 1000 hectares.
A5: Forest area | B5: Forest area is the land spanning more than 0.5 hectares with trees higher than 5 metres and a canopy cover of more than 10 percent, or trees able to reach these thresholds in situ. It does not include land that is predominantly under agricultural or urban land use. Forest is determined both by the presence of trees and the absence of other predominant land uses. The trees should be able to reach a minimum height of 5 metres (m) in situ. Areas under reforestation that have not yet reached but are expected to reach a canopy cover of 10 percent and a tree height of 5 m are included, as are temporarily unstocked areas, resulting from human intervention or natural causes, which are expected to regenerate. Includes: areas with bamboo and palms provided that height and canopy cover criteria are met; forest roads, firebreaks and other small open areas; forest in national parks, nature reserves and other protected areas such as those of specific scientific, historical, cultural or spiritual interest; windbreaks, shelterbelts and corridors of trees with an area of more than 0.5 ha and width of more than 20 m; plantations primarily used for forestry or protective purposes, such as: rubber-wood plantations and cork, oak stands. Excludes: tree stands in agricultural production systems, for example in fruit plantations and agroforestry systems. The term also excludes trees in urban parks and gardens. Data are expressed in 1000 hectares.
A6: Other land | B6: Other land is the land not classified as Agricultural land and Forest area. It includes built-up and related land, barren land, other wooded land, etc. Data are expressed in 1000 hectares.

Sheet crosswalk
A1: Model Categories List | B1: Potential candidates from FAO data
A2: R1.INIT_Avail_Land | B2: Sum of Forest Area (fraction) + Other Land (fraction)
A3: R1.INIT_Crop_Land | B3: Sum of Permanent Crops + Arable Land (fraction)
A4: R1.INIT_Pasture_Land | B4: Sum of Permanent Meadows and Pasture + Arable Land (fraction)
A5: R1.INIT_Abandoned_Land | B5: Other Land (fraction)
